Workbook

Sheet Competitors
A1: Name | B1: URL | C1: Type (local / pan-EU / marketplace) | D1: B2B / B2C focus | E1: Prices shown incl./excl. VAT | F1: Shipping to Czechia | G1: Shipping to Austria (business address) | H1: Shipping VAT treatment | I1: Free-shipping threshold | J1: Minimum order value | K1: Shipping / terms source URL(s) | L1: Distinct basket items with price (any match) | M1: of which EXACT/CLOSE | N1: Counted (yes/no) | O1: Notes
A2: TOMGAST | B2: https://www.tomgast.cz/ | C2: local | D2: B2B + B2C (HORECA specialist; sells to consumers and businesses) | E2: Both shown: incl. 21% VAT as main price, "bez DPH" (excl. VAT) shown alongside | F2: GLS 149 CZK or PPL to address 149 CZK; personal pick-up Karviná free; cash on delivery +39 CZK | G2: Not offered: checkout country list contains only Czech Republic and Slovakia (checked in cart 2026-09-30). No Austrian shipping rate published. | H2: Shipping incl. 21% VAT (checkout: 1,440 CZK item + 149 CZK shipping = 1,589 CZK total, 1,313.22 CZK excl. VAT) | I2: Over 6,000 CZK (shipping page says "nad 6 000 Kč"; site header says "Objednávky nad 6 000 Kč bez DPH doručíme zdarma" i.e. 6,000 CZK excl. VAT) | J2: Not stated | K2: https://www.tomgast.cz/doprava-a-platba/ ; https://www.tomgast.cz/obchodni-podminky/ ; checkout https://www.tomgast.cz/objednavka/krok-1/ | L2: =COUNTIFS(Prices!$C$2:$C$600,A2,Prices!$G$2:$G$600,"<>") | M2: =COUNTIFS(Prices!$C$2:$C$600,A2,Prices!$G$2:$G$600,"<>",Prices!$N$2:$N$600,"EXACT")+COUNTIFS(Prices!$C$2:$C$600,A2,Prices!$G$2:$G$600,"<>",Prices!$N$2:$N$600,"CLOSE") | N2: =IF(L2>=6,"yes","no") | O2: Karviná-based HORECA wholesaler (TOMGAST Czech Republic s.r.o.), large Cambro range. Prices public without login. Stock status shown per item; some chosen items are "Očekáváme naskladnění" (awaiting stock).
A3: Gastro Novotný | B3: https://eshop.gastronovotny.cz/ | C3: local | D3: B2B-oriented wholesale ("Velkoobchod s gastro vybavením"), also sells to consumers (consumer withdrawal rights in T&C) | E3: Main price excl. VAT; "včetně DPH" (incl. 21% VAT) shown alongside | F3: Checkout options: PPL up to 20 kg 275 CZK; TopTrans (large/atypical items) 990 CZK; personal pick-up Brno free; cash on delivery +45 CZK | G3: Not offered: checkout step 2 offers only "Česká republika" as billing/delivery country (checked 2026-09-30). No Austrian rate published. | H3: Shipping prices shown excl. VAT (PPL 275 CZK = 332.75 CZK incl. VAT in checkout) | I3: No general free-shipping threshold published; some individual products (e.g. Liebherr appliances) flagged "Doprava ZDARMA" | J3: 500 CZK excl. VAT (cart: "Minimální cena objednávky je 500 Kč bez DPH") | K3: https://eshop.gastronovotny.cz/obchodni-podminky/ ; checkout https://eshop.gastronovotny.cz/objednavka/krok-1/ | L3: =COUNTIFS(Prices!$C$2:$C$600,A3,Prices!$G$2:$G$600,"<>") | M3: =COUNTIFS(Prices!$C$2:$C$600,A3,Prices!$G$2:$G$600,"<>",Prices!$N$2:$N$600,"EXACT")+COUNTIFS(Prices!$C$2:$C$600,A3,Prices!$G$2:$G$600,"<>",Prices!$N$2:$N$600,"CLOSE") | N3: =IF(L3>=6,"yes","no") | O3: GASTRO NOVOTNÝ, družstvo, Brno. Prices public without login. Many items show availability "Na dotaz" (availability on request) while the price is displayed - recorded as listed prices; noted per item. No squeeze bottle near 1,000 ml, no triple-tip bottle, no pump dispenser, no 300 x 200 board, no dough-box lid, no thermo tray found.
A4: Gastrozone | B4: https://www.gastrozone.cz/ | C4: local | D4: B2C + B2B (gastro and household range; published T&C are written for consumers and state they do not apply to business buyers) | E4: Main price incl. 21% VAT; "bez DPH" (excl. VAT) shown below on product pages | F4: Address delivery (DPD/GLS/PPL, carrier chosen by shop) 95 CZK; pick-up points 49-79 CZK (GLS ParcelShop 49, Balíkovna 59, Zásilkovna 65, PPL Smart 69, DPD Pickup 79); cash on delivery +35 CZK approx.; pick-up Tábor warehouse free. Bulky goods: special transport agreed individually. | G4: No published rate: "Doprava do zahraničí" - price set individually from carriers' tariffs and quoted on request before order confirmation; invoiced under destination-country VAT rules. Quote required. | H4: Shipping prices shown incl. VAT ("s DPH") | I4: All CZ delivery and pick-up options free for orders over 3,000 CZK incl. VAT (CZ only) | J4: Not stated | K4: https://www.gastrozone.cz/informace/doprava-a-platba/ ; https://www.gastrozone.cz/informace/obchodni-podminky/ | L4: =COUNTIFS(Prices!$C$2:$C$600,A4,Prices!$G$2:$G$600,"<>") | M4: =COUNTIFS(Prices!$C$2:$C$600,A4,Prices!$G$2:$G$600,"<>",Prices!$N$2:$N$600,"EXACT")+COUNTIFS(Prices!$C$2:$C$600,A4,Prices!$G$2:$G$600,"<>",Prices!$N$2:$N$600,"CLOSE") | N4: =IF(L4>=6,"yes","no") | O4: GASTROZONE, spol. s r.o., Tábor. Broad multi-brand range (Araven, APS, Pujadas, Cambro, Hendi, Schneider, Contacto). Prices public without login. Several chosen items are "Na objednávku (3-5 týdnů)" (to order); noted per item.
A5: Gastromania | B5: https://www.gastromania.cz/ | C5: local | D5: B2B + B2C (HORECA equipment "velkoobchod"; consumer T&C; separate B2B reseller programme) | E5: Both shown: "bez DPH" (excl.) and "s DPH" (incl. 21% VAT); prices injected by JavaScript (read with a rendering browser) | F5: PPL: 109 CZK with bank transfer/online payment, 169 CZK cash on delivery (parcels up to 31.5 kg, max 60x60x120 cm); oversize, >31.5 kg or pallet shipments priced individually at order confirmation | G5: Not published: T&C state that published delivery costs apply only to delivery within the Czech Republic; no Austrian rate or foreign-delivery terms found (quote would be needed). | H5: Shipping VAT treatment not stated explicitly for the 109/169 CZK fees (free-shipping threshold is stated incl. VAT) | I5: Over 7,000 CZK incl. VAT ("Při nákupu nad 7000 Kč s DPH je doprava zdarma") | J5: Not stated (20% deposit required for orders over 10,000 CZK incl. VAT and made-to-order goods) | K5: https://www.gastromania.cz/zpusoby-dopravy.html ; https://www.gastromania.cz/obchodni-podminky.html | L5: =COUNTIFS(Prices!$C$2:$C$600,A5,Prices!$G$2:$G$600,"<>") | M5: =COUNTIFS(Prices!$C$2:$C$600,A5,Prices!$G$2:$G$600,"<>",Prices!$N$2:$N$600,"EXACT")+COUNTIFS(Prices!$C$2:$C$600,A5,Prices!$G$2:$G$600,"<>",Prices!$N$2:$N$600,"CLOSE") | N5: =IF(L5>=6,"yes","no") | O5: Ostrava-area HORECA shop with CZ/SK storefronts. Multi-brand (Hendi, Contacto, Stalgast, APS, Redfox, Cambro, Yato) and also lists TOMGAST-branded items at identical prices to tomgast.cz. Many items show a crossed-out base price with a current discounted price; the current price for 1 pc is recorded and discounts noted. Where several variants match equally, the lowest current price was taken.
A6: GGM Gastro (CZ storefront) | B6: https://www.ggmgastro.com/cs-cz-czk/ | C6: pan-EU | D6: B2B only (site footer: offers aimed exclusively at commercial customers per §14 BGB, not consumers) | E6: Excl. VAT (net CZK) shown as main price; gross shown "vč. 19% DPH" - the CZ storefront applies German 19% VAT, not Czech 21% | F6: Product pages show "Doprava zdarma**" and footnote "Všechny ceny plus DPH 19 %, včetně dodávky" (prices include delivery); site banner "Doprava zdarma po celé Evropě na všechny objednávky". ** = mainland only; island surcharge. | G6: No specific Austrian rate on the CZ storefront; site banner claims free delivery across Europe on all orders, but the shipping-cost page (English text) says its listed rates (free from 30 EUR net; insured 9.90 EUR, lifting platform 19.90/29.90 EUR, express from 49.90 EUR) apply to the German mainland only and other European countries must request a quote. Austrian customers are normally served via the de-at-eur storefront. | H6: Shipping stated as included in prices (net); where charged, rates on shipping-cost page are in EUR net | I6: Free shipping claimed on all orders (Europe-wide banner); shipping-cost page: free from 30 EUR net purchase value (German mainland) | J6: Not stated (free-shipping reference value 30 EUR net) | K6: https://www.ggmgastro.com/cs-cz-czk/shipping-cost ; https://www.ggmgastro.com/cs-cz-czk/terms | L6: =COUNTIFS(Prices!$C$2:$C$600,A6,Prices!$G$2:$G$600,"<>") | M6: =COUNTIFS(Prices!$C$2:$C$600,A6,Prices!$G$2:$G$600,"<>",Prices!$N$2:$N$600,"EXACT")+COUNTIFS(Prices!$C$2:$C$600,A6,Prices!$G$2:$G$600,"<>",Prices!$N$2:$N$600,"CLOSE") | N6: =IF(L6>=6,"yes","no") | O6: GGM Gastro International GmbH (Germany), Czech-language CZK storefront. Site search and pages are JavaScript-rendered and block headless browsers; products were located via the public product sitemap and read in a full (non-headless) browser. Many products are sold in multi-packs (price per pack; per-piece net computed). Some pages show odd bulk banners (e.g. "30 929,19 Kč Sleva-10%") not used. No 300 x 200 board, no triple-tip bottle (only a 3-hole membrane accessory FFO-055), no separate 600x400 dough-box lid and no thermo tray found.
A7: MAKRO Czechia | B7: https://www.makro.cz/ | C7: local | D7: B2B (cash & carry wholesaler; makro customer card / registration) | E7: Hidden: product listings on sortiment.makro.cz show "Pro zobrazení cen se prosím přihlaste" (log in to see prices) | F7: "makro distribuce" delivery service (m-objednávka) for registered customers; only requirement stated is a minimum order value (amount not published publicly). Otherwise in-store purchase ("Nakoupíte v obchodě"). | G7: Not offered / not published | H7: Not published | I7: Not published | J7: Minimum order value required for makro distribuce - amount not shown publicly | K7: https://www.makro.cz/makro-distribuce ; https://sortiment.makro.cz/shop/search?q=gastron%C3%A1doba%20polykarbon%C3%A1t | L7: =COUNTIFS(Prices!$C$2:$C$600,A7,Prices!$G$2:$G$600,"<>") | M7: =COUNTIFS(Prices!$C$2:$C$600,A7,Prices!$G$2:$G$600,"<>",Prices!$N$2:$N$600,"EXACT")+COUNTIFS(Prices!$C$2:$C$600,A7,Prices!$G$2:$G$600,"<>",Prices!$N$2:$N$600,"CLOSE") | N7: no | O7: Login-only prices - NOT COUNTED. Relevant items exist in the catalogue (e.g. METRO PROFESSIONAL polycarbonate GN 1/1 and 1/2 150 mm containers, APS and Hendi GN containers) but no price is publicly readable. www.makro.cz returns HTTP 403 to plain scripts; readable in a browser.
A8: A GASTRO | B8: https://agastro.cz/ | C8: local | D8: Unknown (HORECA equipment shop per search-engine snippets) | E8: Not readable - site blocked (Cloudflare security check / HTTP 403) | F8: Not readable | G8: Not readable | H8: Not readable | I8: Not readable | J8: Not readable | K8: https://agastro.cz/ | L8: =COUNTIFS(Prices!$C$2:$C$600,A8,Prices!$G$2:$G$600,"<>") | M8: =COUNTIFS(Prices!$C$2:$C$600,A8,Prices!$G$2:$G$600,"<>",Prices!$N$2:$N$600,"EXACT")+COUNTIFS(Prices!$C$2:$C$600,A8,Prices!$G$2:$G$600,"<>",Prices!$N$2:$N$600,"CLOSE") | N8: no | O8: NOT COUNTED - access error. Every URL tried (home, robots.txt, sitemap.xml, www/eshop subdomains, category pages) returns HTTP 403 or a Cloudflare "Provádění bezpečnostního ověření" challenge, both to scripts and to a full browser; the web-fetch tool also gets 403. Search-engine results show category pages such as /gastronadoby-vacbox/, /gastronadoby-zmrlinove/ and /detail/21689/, but no price could be verified, so none recorded. Needs a manual check in a normal browser.

Sheet Prices
A1: Basket item no. | B1: Basket item | C1: Competitor | D1: Product name | E1: Brand | F1: Product URL | G1: Listed price | H1: Currency | I1: Incl./excl. VAT | J1: VAT rate used | K1: Pack size (pcs) | L1: Price basis (per pack / per piece) | M1: Net price per piece CZK | N1: Match quality | O1: Notes | P1: Date checked | Q1: Competitor counted? | R1: Used in Summary?
A2: 1 | B2: GN 1/1 polycarbonate container, 65 mm deep | C2: GGM Gastro (CZ storefront) | D2: (6 ks) Gastronádoba GN GN 1/1 - polykarbonát - čirá - Výška: 65 mm | E2: GGM | F2: https://www.ggmgastro.com/cs-cz-czk/6-ks-gastronadoba-gn-gn-1-1-polykarbonat-cira-vyska-65-mm-gpcp1165 | G2: 1143.69 | H2: CZK | I2: excl. | J2: 0.19 | K2: 6 | L2: per pack | M2: =IF(OR(G2="",J2="",K2=""),"",ROUND(IF(I2="incl.",G2/(1+J2),G2)/IF(L2="per pack",K2,1),2)) | N2: EXACT | O2: Net CZK price as displayed; page footnote: "* čistá cena | hrubá cena vč. 19% DPH" (German VAT 19% used on the CZ storefront). SKU GPCP1165, pack of 6; gross 1,360.99 CZK; delivery 5-6 weeks. | P2: 2026-09-30 | Q2: =IFERROR(INDEX(Competitors!$N$2:$N$50,MATCH(C2,Competitors!$A$2:$A$50,0)),"no") | R2: =IF(AND(Q2="yes",OR(N2="EXACT",N2="CLOSE"),ISNUMBER(M2)),"yes","no")
A3: 1 | B3: GN 1/1 polycarbonate container, 65 mm deep | C3: Gastro Novotný | D3: Gastronádoba PC 1/1 100 | F3: https://eshop.gastronovotny.cz/gastronadoba-pc-1-1-100--0835126/ | G3: 289 | H3: CZK | I3: excl. | J3: 0.21 | K3: 1 | L3: per piece | M3: =IF(OR(G3="",J3="",K3=""),"",ROUND(IF(I3="incl.",G3/(1+J3),G3)/IF(L3="per pack",K3,1),2)) | N3: APPROX | O3: Polycarbonate GN 1/1 but 100 mm deep (no 65 mm PC listed; PC range 1/1 = 100 and 200 mm only). 349.69 CZK incl. VAT. Availability "Na dotaz". | P3: 2026-09-30 | Q3: =IFERROR(INDEX(Competitors!$N$2:$N$50,MATCH(C3,Competitors!$A$2:$A$50,0)),"no") | R3: =IF(AND(Q3="yes",OR(N3="EXACT",N3="CLOSE"),ISNUMBER(M3)),"yes","no")
A4: 1 | B4: GN 1/1 polycarbonate container, 65 mm deep | C4: Gastromania | D4: Gastronádoba z polykarbonátu GN 1/1 65 mm | HENDI, Profi Line | E4: Hendi | F4: https://www.gastromania.cz/gastronadoby-polykarbonatove/gastronadoba-z-polykarbonatu-gn-1-1-65-mm-hendi-profi-line | G4: 262 | H4: CZK | I4: excl. | J4: 0.21 | K4: 1 | L4: per piece | M4: =IF(OR(G4="",J4="",K4=""),"",ROUND(IF(I4="incl.",G4/(1+J4),G4)/IF(L4="per pack",K4,1),2)) | N4: EXACT | O4: PC, 9 l. Current price 262 CZK excl. / 317 incl. is an "Outlet" discount from 368 excl. / 445 incl. (30-day low shown 445). Regular-priced alternative: Stalgast Bufet PC GN 1/1 65 mm 286 excl. / 346 incl. | P4: 2026-09-30 | Q4: =IFERROR(INDEX(Competitors!$N$2:$N$50,MATCH(C4,Competitors!$A$2:$A$50,0)),"no") | R4: =IF(AND(Q4="yes",OR(N4="EXACT",N4="CLOSE"),ISNUMBER(M4)),"yes","no")
A5: 1 | B5: GN 1/1 polycarbonate container, 65 mm deep | C5: Gastrozone | D5: ARAVEN Gastronádoba GN 1/1, polykarbonát, hloubka: 65 mm, objem: 8,6 L | E5: Araven | F5: https://www.gastrozone.cz/araven-gn-box-1-1-polykarbonat-hloubka-65-mm-objem-8-6-l.html | G5: 502 | H5: CZK | I5: incl. | J5: 0.21 | K5: 1 | L5: per piece | M5: =IF(OR(G5="",J5="",K5=""),"",ROUND(IF(I5="incl.",G5/(1+J5),G5)/IF(L5="per pack",K5,1),2)) | N5: EXACT | O5: 414.88 CZK bez DPH; availability "Na objednávku (3-5 týdnů)". In-stock alternative: ARAVEN PC GN 1/1 65 mm with integrated label 601 CZK. | P5: 2026-09-30 | Q5: =IFERROR(INDEX(Competitors!$N$2:$N$50,MATCH(C5,Competitors!$A$2:$A$50,0)),"no") | R5: =IF(AND(Q5="yes",OR(N5="EXACT",N5="CLOSE"),ISNUMBER(M5)),"yes","no")
A6: 1 | B6: GN 1/1 polycarbonate container, 65 mm deep | C6: TOMGAST | D6: Gastronádoba polykarbonátová GN 1/1 65 mm | E6: Cambro | F6: https://www.tomgast.cz/gastronadoba-polykarbonatova-gn-1-1-65-mm/ | G6: 401 | H6: CZK | I6: incl. | J6: 0.21 | K6: 1 | L6: per piece | M6: =IF(OR(G6="",J6="",K6=""),"",ROUND(IF(I6="incl.",G6/(1+J6),G6)/IF(L6="per pack",K6,1),2)) | N6: EXACT | O6: Code R-M211065; site shows 331 CZK bez DPH; in stock | P6: 2026-09-30 | Q6: =IFERROR(INDEX(Competitors!$N$2:$N$50,MATCH(C6,Competitors!$A$2:$A$50,0)),"no") | R6: =IF(AND(Q6="yes",OR(N6="EXACT",N6="CLOSE"),ISNUMBER(M6)),"yes","no")
A7: 2 | B7: GN 1/2 polycarbonate container, 150 mm deep | C7: GGM Gastro (CZ storefront) | D7: (6 ks) CAMBRO Camview – kopolymerové nádoby GN 1/2 – průhledné – výška: 150 mm – bez BPA | E7: Cambro | F7: https://www.ggmgastro.com/cs-cz-czk/6-ks-cambro-camview-r-kopolymerove-nadoby-gn-1-2-pruhledne-vyska-150-mm-bez-bpa-26cv135 | G7: 1460.1 | H7: CZK | I7: excl. | J7: 0.19 | K7: 6 | L7: per pack | M7: =IF(OR(G7="",J7="",K7=""),"",ROUND(IF(I7="incl.",G7/(1+J7),G7)/IF(L7="per pack",K7,1),2)) | N7: CLOSE | O7: Net CZK price as displayed; page footnote: "* čistá cena | hrubá cena vč. 19% DPH" (German VAT 19% used on the CZ storefront). SKU 26CV135, pack of 6; copolymer (Camview), not polycarbonate - no clear PC GN 1/2 150 mm listed. Gross 1,737.52 CZK; in stock 3-5 days. | P7: 2026-09-30 | Q7: =IFERROR(INDEX(Competitors!$N$2:$N$50,MATCH(C7,Competitors!$A$2:$A$50,0)),"no") | R7: =IF(AND(Q7="yes",OR(N7="EXACT",N7="CLOSE"),ISNUMBER(M7)),"yes","no")
A8: 2 | B8: GN 1/2 polycarbonate container, 150 mm deep | C8: Gastro Novotný | D8: Gastronádoba PC 1/2 150 | F8: https://eshop.gastronovotny.cz/gastronadoba-pc-1-2-150--0835123/ | G8: 270 | H8: CZK | I8: excl. | J8: 0.21 | K8: 1 | L8: per piece | M8: =IF(OR(G8="",J8="",K8=""),"",ROUND(IF(I8="incl.",G8/(1+J8),G8)/IF(L8="per pack",K8,1),2)) | N8: EXACT | O8: Code 0835123; 326.70 CZK incl. VAT; availability "Na dotaz" | P8: 2026-09-30 | Q8: =IFERROR(INDEX(Competitors!$N$2:$N$50,MATCH(C8,Competitors!$A$2:$A$50,0)),"no") | R8: =IF(AND(Q8="yes",OR(N8="EXACT",N8="CLOSE"),ISNUMBER(M8)),"yes","no")
A9: 2 | B9: GN 1/2 polycarbonate container, 150 mm deep | C9: Gastromania | D9: Gastronádoba GN 1/2 polykarbonátová 150 mm | REDFOX, GNP-1/2-150 | E9: Redfox | F9: https://www.gastromania.cz/kuchynsky-inventar/gastronadoba-gn-1-2-polykarbonatova-150-mm-redfox-gnp-1-2-150 | G9: 239 | H9: CZK | I9: excl. | J9: 0.21 | K9: 1 | L9: per piece | M9: =IF(OR(G9="",J9="",K9=""),"",ROUND(IF(I9="incl.",G9/(1+J9),G9)/IF(L9="per pack",K9,1),2)) | N9: EXACT | O9: PC, 9.2 l; 289 CZK incl.; availability 5 days. (APS 82116 at 132 excl. is named polycarbonate but its parameters say polypropylene - conflicting, not used.) | P9: 2026-09-30 | Q9: =IFERROR(INDEX(Competitors!$N$2:$N$50,MATCH(C9,Competitors!$A$2:$A$50,0)),"no") | R9: =IF(AND(Q9="yes",OR(N9="EXACT",N9="CLOSE"),ISNUMBER(M9)),"yes","no")
A10: 2 | B10: GN 1/2 polycarbonate container, 150 mm deep | C10: Gastrozone | D10: ARAVEN Gastronádoba GN 1/2, polykarbonát, Hloubka: 150 mm, Objem: 8 L | E10: Araven | F10: https://www.gastrozone.cz/araven-gn-nadoba-1-2-polykarbonat-hloubka-150-mm-objem-8-l.html | G10: 464 | H10: CZK | I10: incl. | J10: 0.21 | K10: 1 | L10: per piece | M10: =IF(OR(G10="",J10="",K10=""),"",ROUND(IF(I10="incl.",G10/(1+J10),G10)/IF(L10="per pack",K10,1),2)) | N10: EXACT | O10: 383.47 CZK bez DPH; to order 3-5 weeks. In-stock alternative: Pujadas GN 1/2 PC 150 mm 630 CZK. | P10: 2026-09-30 | Q10: =IFERROR(INDEX(Competitors!$N$2:$N$50,MATCH(C10,Competitors!$A$2:$A$50,0)),"no") | R10: =IF(AND(Q10="yes",OR(N10="EXACT",N10="CLOSE"),ISNUMBER(M10)),"yes","no")
A11: 2 | B11: GN 1/2 polycarbonate container, 150 mm deep | C11: TOMGAST | D11: Gastronádoba polykarbonátová GN 1/2 150 mm | E11: Cambro | F11: https://www.tomgast.cz/gastronadoba-polykarbonatova-gn-1-2-150-mm-2/ | G11: 356 | H11: CZK | I11: incl. | J11: 0.21 | K11: 1 | L11: per piece | M11: =IF(OR(G11="",J11="",K11=""),"",ROUND(IF(I11="incl.",G11/(1+J11),G11)/IF(L11="per pack",K11,1),2)) | N11: EXACT | O11: Code R-M212150; 294 CZK bez DPH; in stock | P11: 2026-09-30 | Q11: =IFERROR(INDEX(Competitors!$N$2:$N$50,MATCH(C11,Competitors!$A$2:$A$50,0)),"no") | R11: =IF(AND(Q11="yes",OR(N11="EXACT",N11="CLOSE"),ISNUMBER(M11)),"yes","no")
A12: 3 | B12: GN 1/3 polypropylene container, 100 mm deep | C12: GGM Gastro (CZ storefront) | D12: (12 ks) Gastronádoba polypropylen GN 1/3 - Mléčná - Výška: 100 mm | E12: GGM | F12: https://www.ggmgastro.com/cs-cz-czk/12-ks-gastronadoba-polypropylen-gn-1-3-mlecna-vyska-100-mm-gpp13100 | G12: 973.32 | H12: CZK | I12: excl. | J12: 0.19 | K12: 12 | L12: per pack | M12: =IF(OR(G12="",J12="",K12=""),"",ROUND(IF(I12="incl.",G12/(1+J12),G12)/IF(L12="per pack",K12,1),2)) | N12: EXACT | O12: Net CZK price as displayed; page footnote: "* čistá cena | hrubá cena vč. 19% DPH" (German VAT 19% used on the CZ storefront). SKU GPP13100, pack of 12 (3.6 l); gross 1,158.25 CZK. A 6-pack SKU GPP13100#6 is listed at 4,040.03 CZK net (anomalous, ~8x the per-piece price) - not used. | P12: 2026-09-30 | Q12: =IFERROR(INDEX(Competitors!$N$2:$N$50,MATCH(C12,Competitors!$A$2:$A$50,0)),"no") | R12: =IF(AND(Q12="yes",OR(N12="EXACT",N12="CLOSE"),ISNUMBER(M12)),"yes","no")
A13: 3 | B13: GN 1/3 polypropylene container, 100 mm deep | C13: Gastro Novotný | D13: Gastronádoba 1/3 100 polypropylen | F13: https://eshop.gastronovotny.cz/gastronadoba-1-3-100-polypropylen-/ | G13: 100 | H13: CZK | I13: excl. | J13: 0.21 | K13: 1 | L13: per piece | M13: =IF(OR(G13="",J13="",K13=""),"",ROUND(IF(I13="incl.",G13/(1+J13),G13)/IF(L13="per pack",K13,1),2)) | N13: EXACT | O13: Code 1814707-10; 325x180x100 mm, 3.6 l; 121 CZK incl. VAT; in stock | P13: 2026-09-30 | Q13: =IFERROR(INDEX(Competitors!$N$2:$N$50,MATCH(C13,Competitors!$A$2:$A$50,0)),"no") | R13: =IF(AND(Q13="yes",OR(N13="EXACT",N13="CLOSE"),ISNUMBER(M13)),"yes","no")
A14: 3 | B14: GN 1/3 polypropylene container, 100 mm deep | C14: Gastromania | D14: Gastronádoba GN 1/3 - 100 polypropylenová | REDFOX, GNPP 1/3-100 | E14: Redfox | F14: https://www.gastromania.cz/gastronadoby-polypropylenove/gastronadoba-gn-1-3-100-polypropylenova-redfox-gnpp-1-3-100 | G14: 99 | H14: CZK | I14: excl. | J14: 0.21 | K14: 1 | L14: per piece | M14: =IF(OR(G14="",J14="",K14=""),"",ROUND(IF(I14="incl.",G14/(1+J14),G14)/IF(L14="per pack",K14,1),2)) | N14: EXACT | O14: PP, 4 l; 120 CZK incl.; availability 5 days; new item. | P14: 2026-09-30 | Q14: =IFERROR(INDEX(Competitors!$N$2:$N$50,MATCH(C14,Competitors!$A$2:$A$50,0)),"no") | R14: =IF(AND(Q14="yes",OR(N14="EXACT",N14="CLOSE"),ISNUMBER(M14)),"yes","no")
A15: 3 | B15: GN 1/3 polypropylene container, 100 mm deep | C15: Gastrozone | D15: APS GN-nádoba polypropylen, GN 1/3, objem: 3,60 litru, hloubka: 100 mm | E15: APS | F15: https://www.gastrozone.cz/aps-gn-nadoba-z-polypropylenu-gn-1-3-objem-3-60-litru-hloubka-100-mm.html | G15: 180 | H15: CZK | I15: incl. | J15: 0.21 | K15: 1 | L15: per piece | M15: =IF(OR(G15="",J15="",K15=""),"",ROUND(IF(I15="incl.",G15/(1+J15),G15)/IF(L15="per pack",K15,1),2)) | N15: EXACT | O15: 148.76 CZK bez DPH; to order 3-5 weeks. In-stock alternative: Pujadas GN 1/3 PP 100 mm 196 CZK. | P15: 2026-09-30 | Q15: =IFERROR(INDEX(Competitors!$N$2:$N$50,MATCH(C15,Competitors!$A$2:$A$50,0)),"no") | R15: =IF(AND(Q15="yes",OR(N15="EXACT",N15="CLOSE"),ISNUMBER(M15)),"yes","no")
A16: 3 | B16: GN 1/3 polypropylene container, 100 mm deep | C16: TOMGAST | D16: Gastronádoba polypropylenová GN 1/3 100 mm | E16: Cambro | F16: https://www.tomgast.cz/gastronadoba-polypropylenova-gn-1-3-100-mm-2/ | G16: 143 | H16: CZK | I16: incl. | J16: 0.21 | K16: 1 | L16: per piece | M16: =IF(OR(G16="",J16="",K16=""),"",ROUND(IF(I16="incl.",G16/(1+J16),G16)/IF(L16="per pack",K16,1),2)) | N16: EXACT | O16: Code R-MP13100; 118 CZK bez DPH; in stock | P16: 2026-09-30 | Q16: =IFERROR(INDEX(Competitors!$N$2:$N$50,MATCH(C16,Competitors!$A$2:$A$50,0)),"no") | R16: =IF(AND(Q16="yes",OR(N16="EXACT",N16="CLOSE"),ISNUMBER(M16)),"yes","no")
A17: 4 | B17: GN 1/1 polypropylene lid | C17: GGM Gastro (CZ storefront) | D17: (6 kusů) CAMBRO SafeTrak - Polypropylenové víko GN 1/1 - červené | E17: Cambro | F17: https://www.ggmgastro.com/cs-cz-czk/6-kusu-cambro-safetrak-polypropylenove-viko-gn-1-1-cervene-10ppcwsc544 | G17: 802.94 | H17: CZK | I17: excl. | J17: 0.19 | K17: 6 | L17: per pack | M17: =IF(OR(G17="",J17="",K17=""),"",ROUND(IF(I17="incl.",G17/(1+J17),G17)/IF(L17="per pack",K17,1),2)) | N17: EXACT | O17: Net CZK price as displayed; page footnote: "* čistá cena | hrubá cena vč. 19% DPH" (German VAT 19% used on the CZ storefront). SKU 10PPCWSC544, PP, pack of 6; gross 955.50 CZK; in stock. GGM own-brand PP lid GPPL11-12 (717.76 CZK) has conflicting pack size (title 12 pcs, specs 6 pcs) and is available only from 19.10.2026 - not used. | P17: 2026-09-30 | Q17: =IFERROR(INDEX(Competitors!$N$2:$N$50,MATCH(C17,Competitors!$A$2:$A$50,0)),"no") | R17: =IF(AND(Q17="yes",OR(N17="EXACT",N17="CLOSE"),ISNUMBER(M17)),"yes","no")
A18: 4 | B18: GN 1/1 polypropylene lid | C18: Gastro Novotný | D18: Víko 1/1 polypropylen barevné | F18: https://eshop.gastronovotny.cz/viko-1-1-polypropylen-barevne--1814722-11/ | G18: 105 | H18: CZK | I18: excl. | J18: 0.21 | K18: 1 | L18: per piece | M18: =IF(OR(G18="",J18="",K18=""),"",ROUND(IF(I18="incl.",G18/(1+J18),G18)/IF(L18="per pack",K18,1),2)) | N18: EXACT | O18: Code 1814722-11; PP lid 530x325 mm, coloured; 127.05 CZK incl. VAT. Alternative: Víko 1/1 polypropylen PIAZZA 119.01 CZK excl. | P18: 2026-09-30 | Q18: =IFERROR(INDEX(Competitors!$N$2:$N$50,MATCH(C18,Competitors!$A$2:$A$50,0)),"no") | R18: =IF(AND(Q18="yes",OR(N18="EXACT",N18="CLOSE"),ISNUMBER(M18)),"yes","no")
A19: 4 | B19: GN 1/1 polypropylene lid | C19: Gastromania | D19: Víko na nádobu GN 1/1 | APS, 82101 | E19: APS | F19: https://www.gastromania.cz/vika-gn-polypropylenove/viko-na-nadobu-gn-1-1-aps-82101 | G19: 97 | H19: CZK | I19: excl. | J19: 0.21 | K19: 1 | L19: per piece | M19: =IF(OR(G19="",J19="",K19=""),"",ROUND(IF(I19="incl.",G19/(1+J19),G19)/IF(L19="per pack",K19,1),2)) | N19: EXACT | O19: PP lid 530x325; 117 CZK incl. Discounted from 190 excl. / 230 incl. (30-day low 207); availability 21 days. Regular-priced alternative: Redfox VPP 1/1 99 excl. / 120 incl. | P19: 2026-09-30 | Q19: =IFERROR(INDEX(Competitors!$N$2:$N$50,MATCH(C19,Competitors!$A$2:$A$50,0)),"no") | R19: =IF(AND(Q19="yes",OR(N19="EXACT",N19="CLOSE"),ISNUMBER(M19)),"yes","no")
A20: 4 | B20: GN 1/1 polypropylene lid | C20: Gastrozone | D20: víko na gastronádobu GN 1/1 polypropylen Pujadas | E20: Vollrath Pujadas | F20: https://www.gastrozone.cz/viko-na-gastronadobu-gn-1-1-polypropylen-pujadas.html | G20: 350 | H20: CZK | I20: incl. | J20: 0.21 | K20: 1 | L20: per piece | M20: =IF(OR(G20="",J20="",K20=""),"",ROUND(IF(I20="incl.",G20/(1+J20),G20)/IF(L20="per pack",K20,1),2)) | N20: EXACT | O20: 289.26 CZK bez DPH; in stock | P20: 2026-09-30 | Q20: =IFERROR(INDEX(Competitors!$N$2:$N$50,MATCH(C20,Competitors!$A$2:$A$50,0)),"no") | R20: =IF(AND(Q20="yes",OR(N20="EXACT",N20="CLOSE"),ISNUMBER(M20)),"yes","no")
A21: 4 | B21: GN 1/1 polypropylene lid | C21: TOMGAST | D21: Těsnící víko pro gastronádobu GN 1/1 | E21: Cambro | F21: https://www.tomgast.cz/tesnici-viko-pro-gastronadobu-gn-1-1/ | G21: 204 | H21: CZK | I21: incl. | J21: 0.21 | K21: 1 | L21: per piece | M21: =IF(OR(G21="",J21="",K21=""),"",ROUND(IF(I21="incl.",G21/(1+J21),G21)/IF(L21="per pack",K21,1),2)) | N21: CLOSE | O21: Code R-MP11001 (seal cover for PC and PP containers). Product page states material "polykarbonát", not polypropylene - material differs/unclear. Page text "Cena uvedena za 1 kus/6 ks v balení": price read as per piece. 169 CZK bez DPH. No PP GN 1/1 lid found. | P21: 2026-09-30 | Q21: =IFERROR(INDEX(Competitors!$N$2:$N$50,MATCH(C21,Competitors!$A$2:$A$50,0)),"no") | R21: =IF(AND(Q21="yes",OR(N21="EXACT",N21="CLOSE"),ISNUMBER(M21)),"yes","no")
A22: 5 | B22: Squeeze bottle 500 ml, polypropylene, single tip | C22: GGM Gastro (CZ storefront) | D22: (12 ks) Stlačovací lahev na omáčky se středovou membránou - 473 ml | E22: GGM | F22: https://www.ggmgastro.com/cs-cz-czk/12-ks-stlacovaci-lahev-na-omacky-se-stredovou-membranou-473-ml-ffo-002 | G22: 1241.05 | H22: CZK | I22: excl. | J22: 0.19 | K22: 12 | L22: per pack | M22: =IF(OR(G22="",J22="",K22=""),"",ROUND(IF(I22="incl.",G22/(1+J22),G22)/IF(L22="per pack",K22,1),2)) | N22: CLOSE | O22: Net CZK price as displayed; page footnote: "* čistá cena | hrubá cena vč. 19% DPH" (German VAT 19% used on the CZ storefront). SKU FFO-002, 473 ml, pack of 12, valve (membrane) nozzle; material NOT stated (flagged). Gross 1,476.85 CZK. 3-pack version with screw cap FFO-007: 486.54 CZK. | P22: 2026-09-30 | Q22: =IFERROR(INDEX(Competitors!$N$2:$N$50,MATCH(C22,Competitors!$A$2:$A$50,0)),"no") | R22: =IF(AND(Q22="yes",OR(N22="EXACT",N22="CLOSE"),ISNUMBER(M22)),"yes","no")
A23: 5 | B23: Squeeze bottle 500 ml, polypropylene, single tip | C23: Gastro Novotný | D23: Láhev plastová dávkovací čirá 354ml | F23: https://eshop.gastronovotny.cz/lahev-plastova-davkovaci-cira-354ml--255046026/ | G23: 29 | H23: CZK | I23: excl. | J23: 0.21 | K23: 1 | L23: per piece | M23: =IF(OR(G23="",J23="",K23=""),"",ROUND(IF(I23="incl.",G23/(1+J23),G23)/IF(L23="per pack",K23,1),2)) | N23: APPROX | O23: 354 ml instead of 500 ml; plastic type not stated. 35.09 CZK incl. VAT. Red variant same price. Largest squeeze bottle is a 708 ml "zdobící" (decorating) bottle, 39 CZK excl. | P23: 2026-09-30 | Q23: =IFERROR(INDEX(Competitors!$N$2:$N$50,MATCH(C23,Competitors!$A$2:$A$50,0)),"no") | R23: =IF(AND(Q23="yes",OR(N23="EXACT",N23="CLOSE"),ISNUMBER(M23)),"yes","no")
A24: 5 | B24: Squeeze bottle 500 ml, polypropylene, single tip | C24: Gastromania | D24: Láhev na omáčky, 0,475 ml | NEUMARKER, FIFO | E24: Neumarker | F24: https://www.gastromania.cz/davkovace-omacek/lahev-na-omacky-0-475-ml-neumarker-fifo | G24: 352 | H24: CZK | I24: excl. | J24: 0.21 | K24: 1 | L24: per piece | M24: =IF(OR(G24="",J24="",K24=""),"",ROUND(IF(I24="incl.",G24/(1+J24),G24)/IF(L24="per pack",K24,1),2)) | N24: CLOSE | O24: 475 ml FIFO squeeze bottle (refilled from the bottom); material NOT stated (flagged). 425 CZK incl.; discounted from 370 excl.; availability 40 days. Standard PE bottles only in 350/400/700 ml (e.g. Tomgast 400 ml PE 48 excl.). | P24: 2026-09-30 | Q24: =IFERROR(INDEX(Competitors!$N$2:$N$50,MATCH(C24,Competitors!$A$2:$A$50,0)),"no") | R24: =IF(AND(Q24="yes",OR(N24="EXACT",N24="CLOSE"),ISNUMBER(M24)),"yes","no")
A25: 5 | B25: Squeeze bottle 500 ml, polypropylene, single tip | C25: Gastrozone | D25: Dávkovací mačkací láhev Schneider 500 ml | E25: Schneider | F25: https://www.gastrozone.cz/lahev-mackaci-s-uzaviranim-0-5-l-odolna-od-40c-do-95c-transparentni-pro-styk-s-potravinama-schneider-10134.html | G25: 313 | H25: CZK | I25: incl. | J25: 0.21 | K25: 1 | L25: per piece | M25: =IF(OR(G25="",J25="",K25=""),"",ROUND(IF(I25="incl.",G25/(1+J25),G25)/IF(L25="per pack",K25,1),2)) | N25: CLOSE | O25: 500 ml, single nozzle with closure; material polyethylene (not PP). 259 CZK bez DPH. Cheaper non-500 ml options exist (Hendi 0.35/0.7 l from 67 CZK). | P25: 2026-09-30 | Q25: =IFERROR(INDEX(Competitors!$N$2:$N$50,MATCH(C25,Competitors!$A$2:$A$50,0)),"no") | R25: =IF(AND(Q25="yes",OR(N25="EXACT",N25="CLOSE"),ISNUMBER(M25)),"yes","no")
A26: 5 | B26: Squeeze bottle 500 ml, polypropylene, single tip | C26: TOMGAST | D26: Dávkovač na omáčky 400 ml | E26: Laco | F26: https://www.tomgast.cz/davkovac-na-omacky-400-ml/ | G26: 58 | H26: CZK | I26: incl. | J26: 0.21 | K26: 1 | L26: per piece | M26: =IF(OR(G26="",J26="",K26=""),"",ROUND(IF(I26="incl.",G26/(1+J26),G26)/IF(L26="per pack",K26,1),2)) | N26: APPROX | O26: 400 ml instead of 500 ml AND polyethylene instead of PP. 48 CZK bez DPH. No 500 ml bottle listed (sizes 250/360/400/700/720/1025 ml). | P26: 2026-09-30 | Q26: =IFERROR(INDEX(Competitors!$N$2:$N$50,MATCH(C26,Competitors!$A$2:$A$50,0)),"no") | R26: =IF(AND(Q26="yes",OR(N26="EXACT",N26="CLOSE"),ISNUMBER(M26)),"yes","no")
A27: 6 | B27: Squeeze bottle 1000 ml, polypropylene, single tip | C27: GGM Gastro (CZ storefront) | D27: (6 ks) Stlačovací lahev na omáčky se středovou membránou - 946 ml - se šroubovacím uzávěrem a uzavírací čepičkou | E27: GGM | F27: https://www.ggmgastro.com/cs-cz-czk/6-ks-stlacovaci-lahev-na-omacky-se-stredovou-membranou-946-ml-se-sroubovacim-uzaverem-a-uzaviraci-cepickou-ffo-005 | G27: 851.62 | H27: CZK | I27: excl. | J27: 0.19 | K27: 6 | L27: per pack | M27: =IF(OR(G27="",J27="",K27=""),"",ROUND(IF(I27="incl.",G27/(1+J27),G27)/IF(L27="per pack",K27,1),2)) | N27: CLOSE | O27: Net CZK price as displayed; page footnote: "* čistá cena | hrubá cena vč. 19% DPH" (German VAT 19% used on the CZ storefront). SKU FFO-005, 946 ml, pack of 6; material NOT stated (flagged). Gross 1,013.43 CZK. (APS 1,020 ml PE 6-pack 93259#6 shown as not available for the selected delivery country.) | P27: 2026-09-30 | Q27: =IFERROR(INDEX(Competitors!$N$2:$N$50,MATCH(C27,Competitors!$A$2:$A$50,0)),"no") | R27: =IF(AND(Q27="yes",OR(N27="EXACT",N27="CLOSE"),ISNUMBER(M27)),"yes","no")
A28: 6 | B28: Squeeze bottle 1000 ml, polypropylene, single tip | C28: Gastromania | D28: Zásobník na omáčku 1,025 l, bílý | APS, 93259 | E28: APS | F28: https://www.gastromania.cz/davkovace-omacek/zasobnik-na-omacku-1-025-l-bily-aps-93259 | G28: 73 | H28: CZK | I28: excl. | J28: 0.21 | K28: 1 | L28: per piece | M28: =IF(OR(G28="",J28="",K28=""),"",ROUND(IF(I28="incl.",G28/(1+J28),G28)/IF(L28="per pack",K28,1),2)) | N28: CLOSE | O28: 1.025 l squeeze bottle with screw cap; polyethylene, not PP. 88 CZK incl.; discounted from 77 excl.; in stock. | P28: 2026-09-30 | Q28: =IFERROR(INDEX(Competitors!$N$2:$N$50,MATCH(C28,Competitors!$A$2:$A$50,0)),"no") | R28: =IF(AND(Q28="yes",OR(N28="EXACT",N28="CLOSE"),ISNUMBER(M28)),"yes","no")
A29: 6 | B29: Squeeze bottle 1000 ml, polypropylene, single tip | C29: Gastrozone | D29: Dávkovací mačkací láhev Schneider 1000 ml, transparentní | E29: Schneider | F29: https://www.gastrozone.cz/schneider-davkovaci-mackaci-lahev-1000-ml-transparentni.html | G29: 446 | H29: CZK | I29: incl. | J29: 0.21 | K29: 1 | L29: per piece | M29: =IF(OR(G29="",J29="",K29=""),"",ROUND(IF(I29="incl.",G29/(1+J29),G29)/IF(L29="per pack",K29,1),2)) | N29: CLOSE | O29: 1000 ml; material polyethylene (not PP). 369 CZK bez DPH. | P29: 2026-09-30 | Q29: =IFERROR(INDEX(Competitors!$N$2:$N$50,MATCH(C29,Competitors!$A$2:$A$50,0)),"no") | R29: =IF(AND(Q29="yes",OR(N29="EXACT",N29="CLOSE"),ISNUMBER(M29)),"yes","no")
A30: 6 | B30: Squeeze bottle 1000 ml, polypropylene, single tip | C30: TOMGAST | D30: Dávkovač na omáčky 1025 ml, žlutý | E30: TOMGAST | F30: https://www.tomgast.cz/davkovac-na-omacky-1025-ml--zluty/ | G30: 48 | H30: CZK | I30: incl. | J30: 0.21 | K30: 1 | L30: per piece | M30: =IF(OR(G30="",J30="",K30=""),"",ROUND(IF(I30="incl.",G30/(1+J30),G30)/IF(L30="per pack",K30,1),2)) | N30: CLOSE | O30: 1025 ml; material only "plast" (plastic type not stated - flagged); single thin nozzle. 40 CZK bez DPH. Transparent/red variants same price but awaiting stock. | P30: 2026-09-30 | Q30: =IFERROR(INDEX(Competitors!$N$2:$N$50,MATCH(C30,Competitors!$A$2:$A$50,0)),"no") | R30: =IF(AND(Q30="yes",OR(N30="EXACT",N30="CLOSE"),ISNUMBER(M30)),"yes","no")
A31: 7 | B31: Squeeze bottle 500 ml with triple tip | C31: Gastrozone | D31: ARAVEN Mačkací láhev, LDPE, průměr: 80 mm, výška: 253 mm, objem: 0,75 L, 3 trysky | E31: Araven | F31: https://www.gastrozone.cz/araven-lahvicka-na-stlaceni-ldpe-o-80-mm-vyska-253-mm-objem-0-75-l-3-trysky.html | G31: 156 | H31: CZK | I31: incl. | J31: 0.21 | K31: 1 | L31: per piece | M31: =IF(OR(G31="",J31="",K31=""),"",ROUND(IF(I31="incl.",G31/(1+J31),G31)/IF(L31="per pack",K31,1),2)) | N31: APPROX | O31: Triple-tip squeeze bottle but 750 ml (not 500 ml); LDPE. 129 CZK bez DPH. | P31: 2026-09-30 | Q31: =IFERROR(INDEX(Competitors!$N$2:$N$50,MATCH(C31,Competitors!$A$2:$A$50,0)),"no") | R31: =IF(AND(Q31="yes",OR(N31="EXACT",N31="CLOSE"),ISNUMBER(M31)),"yes","no")
A32: 8 | B32: Ketchup/sauce pump dispenser with stand | C32: GGM Gastro (CZ storefront) | D32: Dávkovač omáčky - 2 L - Vč. nerezového podstavce | E32: GGM | F32: https://www.ggmgastro.com/cs-cz-czk/davkovac-omacky-2-l-vc-nerezoveho-podstavce-ssh12 | G32: 997.66 | H32: CZK | I32: excl. | J32: 0.19 | K32: 1 | L32: per piece | M32: =IF(OR(G32="",J32="",K32=""),"",ROUND(IF(I32="incl.",G32/(1+J32),G32)/IF(L32="per pack",K32,1),2)) | N32: EXACT | O32: Net CZK price as displayed; page footnote: "* čistá cena | hrubá cena vč. 19% DPH" (German VAT 19% used on the CZ storefront). SKU SSH12: PP container with portion pump (30 ml adjustable) on stainless-steel stand. Gross 1,187.22 CZK. Stand-less pump dispenser KSP2 2 l: 681.25 CZK. | P32: 2026-09-30 | Q32: =IFERROR(INDEX(Competitors!$N$2:$N$50,MATCH(C32,Competitors!$A$2:$A$50,0)),"no") | R32: =IF(AND(Q32="yes",OR(N32="EXACT",N32="CLOSE"),ISNUMBER(M32)),"yes","no")
A33: 8 | B33: Ketchup/sauce pump dispenser with stand | C33: Gastromania | D33: Dávkovač na omáčky s pumpičkou 2,5 l, červený | HENDI, 203521 | E33: Hendi | F33: https://www.gastromania.cz/davkovace-omacek/davkovac-na-omacky-s-pumpickou-2-5-l-cerveny-hendi-203521 | G33: 636 | H33: CZK | I33: excl. | J33: 0.21 | K33: 1 | L33: per piece | M33: =IF(OR(G33="",J33="",K33=""),"",ROUND(IF(I33="incl.",G33/(1+J33),G33)/IF(L33="per pack",K33,1),2)) | N33: CLOSE | O33: Free-standing pump dispenser: ABS housing, PP inner container and removable pump, 2.5 l, 20 ml dose; separate stand not mentioned. 770 CZK incl.; in stock. | P33: 2026-09-30 | Q33: =IFERROR(INDEX(Competitors!$N$2:$N$50,MATCH(C33,Competitors!$A$2:$A$50,0)),"no") | R33: =IF(AND(Q33="yes",OR(N33="EXACT",N33="CLOSE"),ISNUMBER(M33)),"yes","no")
A34: 8 | B34: Ketchup/sauce pump dispenser with stand | C34: Gastrozone | D34: Dávkovač omáčky Contacto 3 l | E34: Contacto | F34: https://www.gastrozone.cz/contacto-davkovac-omacky-3-l.html | G34: 1446 | H34: CZK | I34: incl. | J34: 0.21 | K34: 1 | L34: per piece | M34: =IF(OR(G34="",J34="",K34=""),"",ROUND(IF(I34="incl.",G34/(1+J34),G34)/IF(L34="per pack",K34,1),2)) | N34: CLOSE | O34: Countertop pump dispenser for ketchup/mustard, white PE, ~30 ml portion, sliding cover, removable pump; free-standing unit - separate stand not mentioned. 1,195 CZK bez DPH. | P34: 2026-09-30 | Q34: =IFERROR(INDEX(Competitors!$N$2:$N$50,MATCH(C34,Competitors!$A$2:$A$50,0)),"no") | R34: =IF(AND(Q34="yes",OR(N34="EXACT",N34="CLOSE"),ISNUMBER(M34)),"yes","no")
A35: 8 | B35: Ketchup/sauce pump dispenser with stand | C35: TOMGAST | D35: Dávkovač 1,5 l | E35: TOMGAST | F35: https://www.tomgast.cz/davkovac-1-5-l/ | G35: 877 | H35: CZK | I35: incl. | J35: 0.21 | K35: 1 | L35: per piece | M35: =IF(OR(G35="",J35="",K35=""),"",ROUND(IF(I35="incl.",G35/(1+J35),G35)/IF(L35="per pack",K35,1),2)) | N35: APPROX | O35: Push-button portion dispenser (30 ml dose), polyethylene, 1.5 l; no stand/base mentioned - not a pump-on-stand unit. 725 CZK bez DPH. | P35: 2026-09-30 | Q35: =IFERROR(INDEX(Competitors!$N$2:$N$50,MATCH(C35,Competitors!$A$2:$A$50,0)),"no") | R35: =IF(AND(Q35="yes",OR(N35="EXACT",N35="CLOSE"),ISNUMBER(M35)),"yes","no")
A36: 9 | B36: HACCP PE cutting board 530 x 325 x 20 mm (GN 1/1) | C36: GGM Gastro (CZ storefront) | D36: Krájecí deska - 325x530 mm - Dle HACCP - Bílá | E36: GGM | F36: https://www.ggmgastro.com/cs-cz-czk/krajeci-deska-325x530-mm-dle-haccp-bila-sbp53w | G36: 632.57 | H36: CZK | I36: excl. | J36: 0.19 | K36: 1 | L36: per piece | M36: =IF(OR(G36="",J36="",K36=""),"",ROUND(IF(I36="incl.",G36/(1+J36),G36)/IF(L36="per pack",K36,1),2)) | N36: EXACT | O36: Net CZK price as displayed; page footnote: "* čistá cena | hrubá cena vč. 19% DPH" (German VAT 19% used on the CZ storefront). SKU SBP53W, PE, 325 x 530 x 20 mm, HACCP colours (same price red etc.). Gross 752.76 CZK. | P36: 2026-09-30 | Q36: =IFERROR(INDEX(Competitors!$N$2:$N$50,MATCH(C36,Competitors!$A$2:$A$50,0)),"no") | R36: =IF(AND(Q36="yes",OR(N36="EXACT",N36="CLOSE"),ISNUMBER(M36)),"yes","no")
A37: 9 | B37: HACCP PE cutting board 530 x 325 x 20 mm (GN 1/1) | C37: Gastro Novotný | D37: Deska polyethylen GN 1/1 53x32,5x2cm nožičky, PE-HD červená | F37: https://eshop.gastronovotny.cz/deska-polyethylen-gn-1-1--53x32-5x2cm--nozicky-pe-hd--cervena/ | G37: 1090 | H37: CZK | I37: excl. | J37: 0.21 | K37: 1 | L37: per piece | M37: =IF(OR(G37="",J37="",K37=""),"",ROUND(IF(I37="incl.",G37/(1+J37),G37)/IF(L37="per pack",K37,1),2)) | N37: EXACT | O37: HDPE, feet, colours white/yellow/red/blue/green/brown/black; 1,318.90 CZK incl. VAT; availability "Na dotaz" (some colours 3-6 weeks) | P37: 2026-09-30 | Q37: =IFERROR(INDEX(Competitors!$N$2:$N$50,MATCH(C37,Competitors!$A$2:$A$50,0)),"no") | R37: =IF(AND(Q37="yes",OR(N37="EXACT",N37="CLOSE"),ISNUMBER(M37)),"yes","no")
A38: 9 | B38: HACCP PE cutting board 530 x 325 x 20 mm (GN 1/1) | C38: Gastromania | D38: Deska na krájení HACCP 530x325x25 mm, červená | CONTACTO, 1524/539 | E38: Contacto | F38: https://www.gastromania.cz/plastove-krajeci-desky-haccp/deska-na-krajeni-haccp-530x325x25-mm-cervena-contacto-1524-539 | G38: 1172 | H38: CZK | I38: excl. | J38: 0.21 | K38: 1 | L38: per piece | M38: =IF(OR(G38="",J38="",K38=""),"",ROUND(IF(I38="incl.",G38/(1+J38),G38)/IF(L38="per pack",K38,1),2)) | N38: CLOSE | O38: PE, HACCP colours, anti-slip feet; 25 mm thick (no 20 mm PE GN 1/1 board found). 1,418 CZK incl.; availability 30 days. Thinner options: Hendi 530x325x15 (PE/PP conflicting) 523 excl.; Hendi 10 mm 297 excl. | P38: 2026-09-30 | Q38: =IFERROR(INDEX(Competitors!$N$2:$N$50,MATCH(C38,Competitors!$A$2:$A$50,0)),"no") | R38: =IF(AND(Q38="yes",OR(N38="EXACT",N38="CLOSE"),ISNUMBER(M38)),"yes","no")
A39: 9 | B39: HACCP PE cutting board 530 x 325 x 20 mm (GN 1/1) | C39: Gastrozone | D39: Prkénko krájecí plastové 53x32,5x2 cm GN 1/1, s drážkou, červené | E39: Gastro | F39: https://www.gastrozone.cz/gastro-prkenko-krajeci-plastove-53x32-5x2-cm-gn-1-1-s-drazkou-cervene.html | G39: 1531 | H39: CZK | I39: incl. | J39: 0.21 | K39: 1 | L39: per piece | M39: =IF(OR(G39="",J39="",K39=""),"",ROUND(IF(I39="incl.",G39/(1+J39),G39)/IF(L39="per pack",K39,1),2)) | N39: CLOSE | O39: 530 x 325 x 20 mm, HACCP colours; material only "plast" (plastic type not stated - flagged); has juice groove and rubber feet. 1,265 CZK bez DPH. | P39: 2026-09-30 | Q39: =IFERROR(INDEX(Competitors!$N$2:$N$50,MATCH(C39,Competitors!$A$2:$A$50,0)),"no") | R39: =IF(AND(Q39="yes",OR(N39="EXACT",N39="CLOSE"),ISNUMBER(M39)),"yes","no")
A40: 9 | B40: HACCP PE cutting board 530 x 325 x 20 mm (GN 1/1) | C40: TOMGAST | D40: Deska 500 × 325 × 20 mm, červená | E40: TOMGAST | F40: https://www.tomgast.cz/deska-500--325--20-mm--cervena/ | G40: 1016 | H40: CZK | I40: incl. | J40: 0.21 | K40: 1 | L40: per piece | M40: =IF(OR(G40="",J40="",K40=""),"",ROUND(IF(I40="incl.",G40/(1+J40),G40)/IF(L40="per pack",K40,1),2)) | N40: APPROX | O40: PE, colour range (white/red/blue/green/yellow/brown), anti-slip feet; 500 mm long, not GN 1/1 530 mm. 840 CZK bez DPH. No 530 x 325 PE board listed. | P40: 2026-09-30 | Q40: =IFERROR(INDEX(Competitors!$N$2:$N$50,MATCH(C40,Competitors!$A$2:$A$50,0)),"no") | R40: =IF(AND(Q40="yes",OR(N40="EXACT",N40="CLOSE"),ISNUMBER(M40)),"yes","no")
...

Sheet Summary
A1: Basket item no. | B1: Item description | C1: Qualifying prices (EXACT+CLOSE, counted competitors) | D1: Min net/pc CZK | E1: Median net/pc CZK | F1: Max net/pc CZK | G1: Competitors in statistics | H1: APPROX observations (not in stats) | I1: All observations (any competitor)
A2: 1 | B2: GN 1/1 polycarbonate container, 65 mm deep | C2: =COUNTIFS(Prices!$A$2:$A$600,A2,Prices!$R$2:$R$600,"yes") | D2: {=IF(C2=0,"",MIN(IF((Prices!$A$2:$A$600=A2)*(Prices!$R$2:$R$600="yes"),Prices!$M$2:$M$600)))} | E2: {=IF(C2=0,"",MEDIAN(IF((Prices!$A$2:$A$600=A2)*(Prices!$R$2:$R$600="yes"),Prices!$M$2:$M$600)))} | F2: {=IF(C2=0,"",MAX(IF((Prices!$A$2:$A$600=A2)*(Prices!$R$2:$R$600="yes"),Prices!$M$2:$M$600)))} | G2: {=IF(C2=0,"",_xlfn.TEXTJOIN(", ",TRUE,IF((Prices!$A$2:$A$600=A2)*(Prices!$R$2:$R$600="yes"),Prices!$C$2:$C$600,"")))} | H2: =COUNTIFS(Prices!$A$2:$A$600,A2,Prices!$N$2:$N$600,"APPROX") | I2: =COUNTIFS(Prices!$A$2:$A$600,A2)
A3: 2 | B3: GN 1/2 polycarbonate container, 150 mm deep | C3: =COUNTIFS(Prices!$A$2:$A$600,A3,Prices!$R$2:$R$600,"yes") | D3: {=IF(C3=0,"",MIN(IF((Prices!$A$2:$A$600=A3)*(Prices!$R$2:$R$600="yes"),Prices!$M$2:$M$600)))} | E3: {=IF(C3=0,"",MEDIAN(IF((Prices!$A$2:$A$600=A3)*(Prices!$R$2:$R$600="yes"),Prices!$M$2:$M$600)))} | F3: {=IF(C3=0,"",MAX(IF((Prices!$A$2:$A$600=A3)*(Prices!$R$2:$R$600="yes"),Prices!$M$2:$M$600)))} | G3: {=IF(C3=0,"",_xlfn.TEXTJOIN(", ",TRUE,IF((Prices!$A$2:$A$600=A3)*(Prices!$R$2:$R$600="yes"),Prices!$C$2:$C$600,"")))} | H3: =COUNTIFS(Prices!$A$2:$A$600,A3,Prices!$N$2:$N$600,"APPROX") | I3: =COUNTIFS(Prices!$A$2:$A$600,A3)
A4: 3 | B4: GN 1/3 polypropylene container, 100 mm deep | C4: =COUNTIFS(Prices!$A$2:$A$600,A4,Prices!$R$2:$R$600,"yes") | D4: {=IF(C4=0,"",MIN(IF((Prices!$A$2:$A$600=A4)*(Prices!$R$2:$R$600="yes"),Prices!$M$2:$M$600)))} | E4: {=IF(C4=0,"",MEDIAN(IF((Prices!$A$2:$A$600=A4)*(Prices!$R$2:$R$600="yes"),Prices!$M$2:$M$600)))} | F4: {=IF(C4=0,"",MAX(IF((Prices!$A$2:$A$600=A4)*(Prices!$R$2:$R$600="yes"),Prices!$M$2:$M$600)))} | G4: {=IF(C4=0,"",_xlfn.TEXTJOIN(", ",TRUE,IF((Prices!$A$2:$A$600=A4)*(Prices!$R$2:$R$600="yes"),Prices!$C$2:$C$600,"")))} | H4: =COUNTIFS(Prices!$A$2:$A$600,A4,Prices!$N$2:$N$600,"APPROX") | I4: =COUNTIFS(Prices!$A$2:$A$600,A4)
A5: 4 | B5: GN 1/1 polypropylene lid | C5: =COUNTIFS(Prices!$A$2:$A$600,A5,Prices!$R$2:$R$600,"yes") | D5: {=IF(C5=0,"",MIN(IF((Prices!$A$2:$A$600=A5)*(Prices!$R$2:$R$600="yes"),Prices!$M$2:$M$600)))} | E5: {=IF(C5=0,"",MEDIAN(IF((Prices!$A$2:$A$600=A5)*(Prices!$R$2:$R$600="yes"),Prices!$M$2:$M$600)))} | F5: {=IF(C5=0,"",MAX(IF((Prices!$A$2:$A$600=A5)*(Prices!$R$2:$R$600="yes"),Prices!$M$2:$M$600)))} | G5: {=IF(C5=0,"",_xlfn.TEXTJOIN(", ",TRUE,IF((Prices!$A$2:$A$600=A5)*(Prices!$R$2:$R$600="yes"),Prices!$C$2:$C$600,"")))} | H5: =COUNTIFS(Prices!$A$2:$A$600,A5,Prices!$N$2:$N$600,"APPROX") | I5: =COUNTIFS(Prices!$A$2:$A$600,A5)
A6: 5 | B6: Squeeze bottle 500 ml, polypropylene, single tip | C6: =COUNTIFS(Prices!$A$2:$A$600,A6,Prices!$R$2:$R$600,"yes") | D6: {=IF(C6=0,"",MIN(IF((Prices!$A$2:$A$600=A6)*(Prices!$R$2:$R$600="yes"),Prices!$M$2:$M$600)))} | E6: {=IF(C6=0,"",MEDIAN(IF((Prices!$A$2:$A$600=A6)*(Prices!$R$2:$R$600="yes"),Prices!$M$2:$M$600)))} | F6: {=IF(C6=0,"",MAX(IF((Prices!$A$2:$A$600=A6)*(Prices!$R$2:$R$600="yes"),Prices!$M$2:$M$600)))} | G6: {=IF(C6=0,"",_xlfn.TEXTJOIN(", ",TRUE,IF((Prices!$A$2:$A$600=A6)*(Prices!$R$2:$R$600="yes"),Prices!$C$2:$C$600,"")))} | H6: =COUNTIFS(Prices!$A$2:$A$600,A6,Prices!$N$2:$N$600,"APPROX") | I6: =COUNTIFS(Prices!$A$2:$A$600,A6)
A7: 6 | B7: Squeeze bottle 1000 ml, polypropylene, single tip | C7: =COUNTIFS(Prices!$A$2:$A$600,A7,Prices!$R$2:$R$600,"yes") | D7: {=IF(C7=0,"",MIN(IF((Prices!$A$2:$A$600=A7)*(Prices!$R$2:$R$600="yes"),Prices!$M$2:$M$600)))} | E7: {=IF(C7=0,"",MEDIAN(IF((Prices!$A$2:$A$600=A7)*(Prices!$R$2:$R$600="yes"),Prices!$M$2:$M$600)))} | F7: {=IF(C7=0,"",MAX(IF((Prices!$A$2:$A$600=A7)*(Prices!$R$2:$R$600="yes"),Prices!$M$2:$M$600)))} | G7: {=IF(C7=0,"",_xlfn.TEXTJOIN(", ",TRUE,IF((Prices!$A$2:$A$600=A7)*(Prices!$R$2:$R$600="yes"),Prices!$C$2:$C$600,"")))} | H7: =COUNTIFS(Prices!$A$2:$A$600,A7,Prices!$N$2:$N$600,"APPROX") | I7: =COUNTIFS(Prices!$A$2:$A$600,A7)
A8: 7 | B8: Squeeze bottle 500 ml with triple tip | C8: =COUNTIFS(Prices!$A$2:$A$600,A8,Prices!$R$2:$R$600,"yes") | D8: {=IF(C8=0,"",MIN(IF((Prices!$A$2:$A$600=A8)*(Prices!$R$2:$R$600="yes"),Prices!$M$2:$M$600)))} | E8: {=IF(C8=0,"",MEDIAN(IF((Prices!$A$2:$A$600=A8)*(Prices!$R$2:$R$600="yes"),Prices!$M$2:$M$600)))} | F8: {=IF(C8=0,"",MAX(IF((Prices!$A$2:$A$600=A8)*(Prices!$R$2:$R$600="yes"),Prices!$M$2:$M$600)))} | G8: {=IF(C8=0,"",_xlfn.TEXTJOIN(", ",TRUE,IF((Prices!$A$2:$A$600=A8)*(Prices!$R$2:$R$600="yes"),Prices!$C$2:$C$600,"")))} | H8: =COUNTIFS(Prices!$A$2:$A$600,A8,Prices!$N$2:$N$600,"APPROX") | I8: =COUNTIFS(Prices!$A$2:$A$600,A8)
A9: 8 | B9: Ketchup/sauce pump dispenser with stand | C9: =COUNTIFS(Prices!$A$2:$A$600,A9,Prices!$R$2:$R$600,"yes") | D9: {=IF(C9=0,"",MIN(IF((Prices!$A$2:$A$600=A9)*(Prices!$R$2:$R$600="yes"),Prices!$M$2:$M$600)))} | E9: {=IF(C9=0,"",MEDIAN(IF((Prices!$A$2:$A$600=A9)*(Prices!$R$2:$R$600="yes"),Prices!$M$2:$M$600)))} | F9: {=IF(C9=0,"",MAX(IF((Prices!$A$2:$A$600=A9)*(Prices!$R$2:$R$600="yes"),Prices!$M$2:$M$600)))} | G9: {=IF(C9=0,"",_xlfn.TEXTJOIN(", ",TRUE,IF((Prices!$A$2:$A$600=A9)*(Prices!$R$2:$R$600="yes"),Prices!$C$2:$C$600,"")))} | H9: =COUNTIFS(Prices!$A$2:$A$600,A9,Prices!$N$2:$N$600,"APPROX") | I9: =COUNTIFS(Prices!$A$2:$A$600,A9)
A10: 9 | B10: HACCP PE cutting board 530 x 325 x 20 mm (GN 1/1) | C10: =COUNTIFS(Prices!$A$2:$A$600,A10,Prices!$R$2:$R$600,"yes") | D10: {=IF(C10=0,"",MIN(IF((Prices!$A$2:$A$600=A10)*(Prices!$R$2:$R$600="yes"),Prices!$M$2:$M$600)))} | E10: {=IF(C10=0,"",MEDIAN(IF((Prices!$A$2:$A$600=A10)*(Prices!$R$2:$R$600="yes"),Prices!$M$2:$M$600)))} | F10: {=IF(C10=0,"",MAX(IF((Prices!$A$2:$A$600=A10)*(Prices!$R$2:$R$600="yes"),Prices!$M$2:$M$600)))} | G10: {=IF(C10=0,"",_xlfn.TEXTJOIN(", ",TRUE,IF((Prices!$A$2:$A$600=A10)*(Prices!$R$2:$R$600="yes"),Prices!$C$2:$C$600,"")))} | H10: =COUNTIFS(Prices!$A$2:$A$600,A10,Prices!$N$2:$N$600,"APPROX") | I10: =COUNTIFS(Prices!$A$2:$A$600,A10)
A11: 10 | B11: HACCP PE cutting board 600 x 400 x 20 mm | C11: =COUNTIFS(Prices!$A$2:$A$600,A11,Prices!$R$2:$R$600,"yes") | D11: {=IF(C11=0,"",MIN(IF((Prices!$A$2:$A$600=A11)*(Prices!$R$2:$R$600="yes"),Prices!$M$2:$M$600)))} | E11: {=IF(C11=0,"",MEDIAN(IF((Prices!$A$2:$A$600=A11)*(Prices!$R$2:$R$600="yes"),Prices!$M$2:$M$600)))} | F11: {=IF(C11=0,"",MAX(IF((Prices!$A$2:$A$600=A11)*(Prices!$R$2:$R$600="yes"),Prices!$M$2:$M$600)))} | G11: {=IF(C11=0,"",_xlfn.TEXTJOIN(", ",TRUE,IF((Prices!$A$2:$A$600=A11)*(Prices!$R$2:$R$600="yes"),Prices!$C$2:$C$600,"")))} | H11: =COUNTIFS(Prices!$A$2:$A$600,A11,Prices!$N$2:$N$600,"APPROX") | I11: =COUNTIFS(Prices!$A$2:$A$600,A11)
A12: 11 | B12: HACCP PE cutting board 300 x 200 x 10 mm | C12: =COUNTIFS(Prices!$A$2:$A$600,A12,Prices!$R$2:$R$600,"yes") | D12: {=IF(C12=0,"",MIN(IF((Prices!$A$2:$A$600=A12)*(Prices!$R$2:$R$600="yes"),Prices!$M$2:$M$600)))} | E12: {=IF(C12=0,"",MEDIAN(IF((Prices!$A$2:$A$600=A12)*(Prices!$R$2:$R$600="yes"),Prices!$M$2:$M$600)))} | F12: {=IF(C12=0,"",MAX(IF((Prices!$A$2:$A$600=A12)*(Prices!$R$2:$R$600="yes"),Prices!$M$2:$M$600)))} | G12: {=IF(C12=0,"",_xlfn.TEXTJOIN(", ",TRUE,IF((Prices!$A$2:$A$600=A12)*(Prices!$R$2:$R$600="yes"),Prices!$C$2:$C$600,"")))} | H12: =COUNTIFS(Prices!$A$2:$A$600,A12,Prices!$N$2:$N$600,"APPROX") | I12: =COUNTIFS(Prices!$A$2:$A$600,A12)
A13: 12 | B13: Pizza dough proofing box 600 x 400 x 100 mm, polypropylene | C13: =COUNTIFS(Prices!$A$2:$A$600,A13,Prices!$R$2:$R$600,"yes") | D13: {=IF(C13=0,"",MIN(IF((Prices!$A$2:$A$600=A13)*(Prices!$R$2:$R$600="yes"),Prices!$M$2:$M$600)))} | E13: {=IF(C13=0,"",MEDIAN(IF((Prices!$A$2:$A$600=A13)*(Prices!$R$2:$R$600="yes"),Prices!$M$2:$M$600)))} | F13: {=IF(C13=0,"",MAX(IF((Prices!$A$2:$A$600=A13)*(Prices!$R$2:$R$600="yes"),Prices!$M$2:$M$600)))} | G13: {=IF(C13=0,"",_xlfn.TEXTJOIN(", ",TRUE,IF((Prices!$A$2:$A$600=A13)*(Prices!$R$2:$R$600="yes"),Prices!$C$2:$C$600,"")))} | H13: =COUNTIFS(Prices!$A$2:$A$600,A13,Prices!$N$2:$N$600,"APPROX") | I13: =COUNTIFS(Prices!$A$2:$A$600,A13)
... A35: 34 | B35: Dough box 400x300x100 mm, PP, without lid | C35: =COUNTIFS(Prices!$A$2:$A$600,A35,Prices!$R$2:$R$600,"yes") | D35: {=IF(C35=0,"",MIN(IF((Prices!$A$2:$A$600=A35)*(Prices!$R$2:$R$600="yes"),Prices!$M$2:$M$600)))} | E35: {=IF(C35=0,"",MEDIAN(IF((Prices!$A$2:$A$600=A35)*(Prices!$R$2:$R$600="yes"),Prices!$M$2:$M$600)))} | F35: {=IF(C35=0,"",MAX(IF((Prices!$A$2:$A$600=A35)*(Prices!$R$2:$R$600="yes"),Prices!$M$2:$M$600)))} | G35: {=IF(C35=0,"",_xlfn.TEXTJOIN(", ",TRUE,IF((Prices!$A$2:$A$600=A35)*(Prices!$R$2:$R$600="yes"),Prices!$C$2:$C$600,"")))} | H35: =COUNTIFS(Prices!$A$2:$A$600,A35,Prices!$N$2:$N$600,"APPROX") | I35: =COUNTIFS(Prices!$A$2:$A$600,A35)
A37: Notes:
A38: Statistics use only primary observations with match quality EXACT or CLOSE from competitors marked Counted = yes on the Competitors sheet (max one observation per competitor per item).
A39: Net price per piece = listed price / (1 + VAT rate) when the listed price includes VAT, divided by pack size when the price is per pack. Czech VAT 21%.
A40: Blank statistics = no qualifying observation. APPROX matches are listed on the Prices sheet but excluded from statistics.
A41: Where several products matched equally well, the lowest current 1-unit price was taken as primary; alternatives, promotions and pack sizes are in the Prices notes.
A42: GGM Gastro prices are shown net on its CZ storefront (gross uses German 19% VAT, recorded in the VAT-rate column); net per piece is taken directly from the displayed net price. All other shops use Czech 21% VAT.
A43: Prices checked 2026-09-30. All prices in CZK from Czech storefronts. MAKRO (login-only prices) and A GASTRO (site blocked) are not counted - see Not accessible.
A44: Items 18-34 (additional variants) added 2026-09-30 for the same competitors; same rules (EXACT/CLOSE only in statistics, net = gross/1.21 for Czech VAT, GGM uses its own net CZK).

Sheet Not accessible
A1: Competitor | B1: URL | C1: Reason | D1: Date checked | E1: Notes
A2: MAKRO Czechia | B2: https://sortiment.makro.cz/shop/search?q=gastron%C3%A1doba%20polykarbon%C3%A1t | C2: Login required: every product tile shows "Pro zobrazení cen se prosím přihlaste" (please log in to view prices). Checked GN containers (METRO PROFESSIONAL, APS, Hendi). | D2: 2026-09-30 | E2: Competitor not counted. Homepage www.makro.cz returns HTTP 403 to non-browser clients.
A3: MAKRO Czechia | B3: https://www.makro.cz/metro/services/idamstream/login?returnUrl=/ | C3: Price display link on homepage product teasers ("Přihlaste se pro zobrazení ceny") leads to login. | D3: 2026-09-30
A4: A GASTRO | B4: https://agastro.cz/ | C4: Access error: Cloudflare bot challenge / HTTP 403 on all pages (home, robots.txt, sitemap.xml, category pages), in scripts, a full browser and the web-fetch tool. | D4: 2026-09-30 | E4: Competitor not counted. Search snippets only (e.g. https://agastro.cz/gastronadoby-vacbox/, https://agastro.cz/detail/21689/) - not used as price evidence.
A5: A GASTRO | B5: https://agastro.cz/gastronadoby-vacbox/ | C5: HTTP 403 (Cloudflare) - category page found via search engine could not be opened. | D5: 2026-09-30
A6: GGM Gastro (CZ storefront) | B6: https://www.ggmgastro.com/cs-cz-czk/search?q=polykarbon%C3%A1t | C6: Search results are JavaScript-loaded and the site returns "403 FORBIDDEN - This request was blocked" to headless browsers. | D6: 2026-09-30 | E6: Worked around: products located via the public product sitemap and read in a full (non-headless) browser; prices recorded from product pages.
A7: GGM Gastro (CZ storefront) | B7: https://www.ggmgastro.com/cs-cz-czk/6-ks-stlacovaci-lahev-na-omacky-1-020-ml-o-80-mm-se-sroubovacim-uzaverem-a-uzaviraci-cepickou-transparentni-93259-6 | C7: Product shows "Není k dispozici pro vybranou zemi dodání" (not available for the selected delivery country). | D7: 2026-09-30 | E7: Not used as primary observation for item 6.
A8: Gastromania | B8: https://www.gastromania.cz/products/search/language:cze?q=polykarbon%C3%A1t+GN+1%2F1 | C8: Prices are injected by JavaScript (empty in raw HTML). | D8: 2026-09-30 | E8: Worked around: read with a rendering browser; all recorded prices verified on rendered product pages/listings.
