Workbook

Sheet Compare
B2: YES Gastro market comparison
B3: Original benchmark basket plus Austria and Czechia additions; Austria/Germany expansion and corrections of 2 Oct 2026; GN container and lid expansion of 2 Oct 2026 (45 further GN variants, AT/DE/CZ/SK/RO; see Change log). Net prices per piece.
B5: Statistic | C5: Median | D5: View | E5: Net per piece EUR | G5: Match | H5: EXACT + CLOSE | J5: Product detail
J6: GN 1/1 PC container, 65 mm
B7: =IF(E5="Local prices","Local net prices per piece. Currency differs by country.","EUR net prices per piece. Erste Bank mid-rates published 30 Sep 2026 at 18:00 CEST.") -> EUR net prices per piece. Erste Bank mid-rates published 30 Sep 2026 at 18:00 CEST.
B8: A dash means no qualifying price. Green marks the lowest available EUR price for each product.
J9: Net price per piece in EUR
B10: Product | C10: Hungary | D10: Romania | E10: Austria | F10: Germany | G10: Czech | H10: Slovakia
C11: =IF($E$5="Local prices","HUF net/pc","EUR net/pc") -> EUR net/pc | D11: =IF($E$5="Local prices","RON net/pc","EUR net/pc") -> EUR net/pc | E11: =IF($E$5="Local prices","EUR net/pc","EUR net/pc") -> EUR net/pc | F11: =IF($E$5="Local prices","EUR net/pc","EUR net/pc") -> EUR net/pc | G11: =IF($E$5="Local prices","CZK net/pc","EUR net/pc") -> EUR net/pc | H11: =IF($E$5="Local prices","EUR net/pc","EUR net/pc") -> EUR net/pc | J11: Market | K11: Minimum | L11: Median | M11: Maximum
B12: GN 1/1 PC container, 65 mm | C12: =IF(IF($E$5="Local prices",COUNTIFS(Offers!$B$7:$B$3000,$B12,Offers!$C$7:$C$3000,C$10,Offers!$AH$7:$AH$3000,"yes"),COUNTIFS(Offers!$B$7:$B$3000,$B12,Offers!$C$7:$C$3000,C$10,Offers!$AI$7:$AI$3000,"yes"))=0,"—",SUMIFS(Review!$O$7:$O$600,Review!$B$7:$B$600,$B12,Review!$C$7:$C$600,C$10)) -> 10.912021 | D12: =IF(IF($E$5="Local prices",COUNTIFS(Offers!$B$7:$B$3000,$B12,Offers!$C$7:$C$3000,D$10,Offers!$AH$7:$AH$3000,"yes"),COUNTIFS(Offers!$B$7:$B$3000,$B12,Offers!$C$7:$C$3000,D$10,Offers!$AI$7:$AI$3000,"yes"))=0,"—",SUMIFS(Review!$O$7:$O$600,Review!$B$7:$B$600,$B12,Review!$C$7:$C$600,D$10)) -> 10.029101 | E12: =IF(IF($E$5="Local prices",COUNTIFS(Offers!$B$7:$B$3000,$B12,Offers!$C$7:$C$3000,E$10,Offers!$AH$7:$AH$3000,"yes"),COUNTIFS(Offers!$B$7:$B$3000,$B12,Offers!$C$7:$C$3000,E$10,Offers!$AI$7:$AI$3000,"yes"))=0,"—",SUMIFS(Review!$O$7:$O$600,Review!$B$7:$B$600,$B12,Review!$C$7:$C$600,E$10)) -> 14.07 | F12: =IF(IF($E$5="Local prices",COUNTIFS(Offers!$B$7:$B$3000,$B12,Offers!$C$7:$C$3000,F$10,Offers!$AH$7:$AH$3000,"yes"),COUNTIFS(Offers!$B$7:$B$3000,$B12,Offers!$C$7:$C$3000,F$10,Offers!$AI$7:$AI$3000,"yes"))=0,"—",SUMIFS(Review!$O$7:$O$600,Review!$B$7:$B$600,$B12,Review!$C$7:$C$600,F$10)) -> 13.11 | G12: =IF(IF($E$5="Local prices",COUNTIFS(Offers!$B$7:$B$3000,$B12,Offers!$C$7:$C$3000,G$10,Offers!$AH$7:$AH$3000,"yes"),COUNTIFS(Offers!$B$7:$B$3000,$B12,Offers!$C$7:$C$3000,G$10,Offers!$AI$7:$AI$3000,"yes"))=0,"—",SUMIFS(Review!$O$7:$O$600,Review!$B$7:$B$600,$B12,Review!$C$7:$C$600,G$10)) -> 12.148079 | H12: =IF(IF($E$5="Local prices",COUNTIFS(Offers!$B$7:$B$3000,$B12,Offers!$C$7:$C$3000,H$10,Offers!$AH$7:$AH$3000,"yes"),COUNTIFS(Offers!$B$7:$B$3000,$B12,Offers!$C$7:$C$3000,H$10,Offers!$AI$7:$AI$3000,"yes"))=0,"—",SUMIFS(Review!$O$7:$O$600,Review!$B$7:$B$600,$B12,Review!$C$7:$C$600,H$10)) -> 18.467643 | J12: Hungary | K12: =IF(COUNTIFS(Offers!$B$7:$B$3000,$J$6,Offers!$C$7:$C$3000,$J12,Offers!$AI$7:$AI$3000,"yes")=0,"—",SUMIFS(Review!$I$7:$I$600,Review!$B$7:$B$600,$J$6,Review!$C$7:$C$600,$J12)) -> 6.883177 | L12: =IF(COUNTIFS(Offers!$B$7:$B$3000,$J$6,Offers!$C$7:$C$3000,$J12,Offers!$AI$7:$AI$3000,"yes")=0,"—",SUMIFS(Review!$J$7:$J$600,Review!$B$7:$B$600,$J$6,Review!$C$7:$C$600,$J12)) -> 10.912021 | M12: =IF(COUNTIFS(Offers!$B$7:$B$3000,$J$6,Offers!$C$7:$C$3000,$J12,Offers!$AI$7:$AI$3000,"yes")=0,"—",SUMIFS(Review!$K$7:$K$600,Review!$B$7:$B$600,$J$6,Review!$C$7:$C$600,$J12)) -> 19.764552
B13: GN 1/2 PC container, 150 mm | C13: =IF(IF($E$5="Local prices",COUNTIFS(Offers!$B$7:$B$3000,$B13,Offers!$C$7:$C$3000,C$10,Offers!$AH$7:$AH$3000,"yes"),COUNTIFS(Offers!$B$7:$B$3000,$B13,Offers!$C$7:$C$3000,C$10,Offers!$AI$7:$AI$3000,"yes"))=0,"—",SUMIFS(Review!$O$7:$O$600,Review!$B$7:$B$600,$B13,Review!$C$7:$C$600,C$10)) -> 9.607768 | D13: =IF(IF($E$5="Local prices",COUNTIFS(Offers!$B$7:$B$3000,$B13,Offers!$C$7:$C$3000,D$10,Offers!$AH$7:$AH$3000,"yes"),COUNTIFS(Offers!$B$7:$B$3000,$B13,Offers!$C$7:$C$3000,D$10,Offers!$AI$7:$AI$3000,"yes"))=0,"—",SUMIFS(Review!$O$7:$O$600,Review!$B$7:$B$600,$B13,Review!$C$7:$C$600,D$10)) -> 10.87228 | E13: =IF(IF($E$5="Local prices",COUNTIFS(Offers!$B$7:$B$3000,$B13,Offers!$C$7:$C$3000,E$10,Offers!$AH$7:$AH$3000,"yes"),COUNTIFS(Offers!$B$7:$B$3000,$B13,Offers!$C$7:$C$3000,E$10,Offers!$AI$7:$AI$3000,"yes"))=0,"—",SUMIFS(Review!$O$7:$O$600,Review!$B$7:$B$600,$B13,Review!$C$7:$C$600,E$10)) -> 10.9 | F13: =IF(IF($E$5="Local prices",COUNTIFS(Offers!$B$7:$B$3000,$B13,Offers!$C$7:$C$3000,F$10,Offers!$AH$7:$AH$3000,"yes"),COUNTIFS(Offers!$B$7:$B$3000,$B13,Offers!$C$7:$C$3000,F$10,Offers!$AI$7:$AI$3000,"yes"))=0,"—",SUMIFS(Review!$O$7:$O$600,Review!$B$7:$B$600,$B13,Review!$C$7:$C$600,F$10)) -> 9.35 | G13: =IF(IF($E$5="Local prices",COUNTIFS(Offers!$B$7:$B$3000,$B13,Offers!$C$7:$C$3000,G$10,Offers!$AH$7:$AH$3000,"yes"),COUNTIFS(Offers!$B$7:$B$3000,$B13,Offers!$C$7:$C$3000,G$10,Offers!$AI$7:$AI$3000,"yes"))=0,"—",SUMIFS(Review!$O$7:$O$600,Review!$B$7:$B$600,$B13,Review!$C$7:$C$600,G$10)) -> 10.509296 | H13: =IF(IF($E$5="Local prices",COUNTIFS(Offers!$B$7:$B$3000,$B13,Offers!$C$7:$C$3000,H$10,Offers!$AH$7:$AH$3000,"yes"),COUNTIFS(Offers!$B$7:$B$3000,$B13,Offers!$C$7:$C$3000,H$10,Offers!$AI$7:$AI$3000,"yes"))=0,"—",SUMIFS(Review!$O$7:$O$600,Review!$B$7:$B$600,$B13,Review!$C$7:$C$600,H$10)) -> 15.688821 | J13: Romania | K13: =IF(COUNTIFS(Offers!$B$7:$B$3000,$J$6,Offers!$C$7:$C$3000,$J13,Offers!$AI$7:$AI$3000,"yes")=0,"—",SUMIFS(Review!$I$7:$I$600,Review!$B$7:$B$600,$J$6,Review!$C$7:$C$600,$J13)) -> 8 | L13: =IF(COUNTIFS(Offers!$B$7:$B$3000,$J$6,Offers!$C$7:$C$3000,$J13,Offers!$AI$7:$AI$3000,"yes")=0,"—",SUMIFS(Review!$J$7:$J$600,Review!$B$7:$B$600,$J$6,Review!$C$7:$C$600,$J13)) -> 10.029101 | M13: =IF(COUNTIFS(Offers!$B$7:$B$3000,$J$6,Offers!$C$7:$C$3000,$J13,Offers!$AI$7:$AI$3000,"yes")=0,"—",SUMIFS(Review!$K$7:$K$600,Review!$B$7:$B$600,$J$6,Review!$C$7:$C$600,$J13)) -> 17.413081
B14: GN 1/3 PP container, 100 mm | C14: =IF(IF($E$5="Local prices",COUNTIFS(Offers!$B$7:$B$3000,$B14,Offers!$C$7:$C$3000,C$10,Offers!$AH$7:$AH$3000,"yes"),COUNTIFS(Offers!$B$7:$B$3000,$B14,Offers!$C$7:$C$3000,C$10,Offers!$AI$7:$AI$3000,"yes"))=0,"—",SUMIFS(Review!$O$7:$O$600,Review!$B$7:$B$600,$B14,Review!$C$7:$C$600,C$10)) -> 4.247357 | D14: =IF(IF($E$5="Local prices",COUNTIFS(Offers!$B$7:$B$3000,$B14,Offers!$C$7:$C$3000,D$10,Offers!$AH$7:$AH$3000,"yes"),COUNTIFS(Offers!$B$7:$B$3000,$B14,Offers!$C$7:$C$3000,D$10,Offers!$AI$7:$AI$3000,"yes"))=0,"—",SUMIFS(Review!$O$7:$O$600,Review!$B$7:$B$600,$B14,Review!$C$7:$C$600,D$10)) -> 6.404376 | E14: =IF(IF($E$5="Local prices",COUNTIFS(Offers!$B$7:$B$3000,$B14,Offers!$C$7:$C$3000,E$10,Offers!$AH$7:$AH$3000,"yes"),COUNTIFS(Offers!$B$7:$B$3000,$B14,Offers!$C$7:$C$3000,E$10,Offers!$AI$7:$AI$3000,"yes"))=0,"—",SUMIFS(Review!$O$7:$O$600,Review!$B$7:$B$600,$B14,Review!$C$7:$C$600,E$10)) -> 5.305 | F14: =IF(IF($E$5="Local prices",COUNTIFS(Offers!$B$7:$B$3000,$B14,Offers!$C$7:$C$3000,F$10,Offers!$AH$7:$AH$3000,"yes"),COUNTIFS(Offers!$B$7:$B$3000,$B14,Offers!$C$7:$C$3000,F$10,Offers!$AI$7:$AI$3000,"yes"))=0,"—",SUMIFS(Review!$O$7:$O$600,Review!$B$7:$B$600,$B14,Review!$C$7:$C$600,F$10)) -> 6.93 | G14: =IF(IF($E$5="Local prices",COUNTIFS(Offers!$B$7:$B$3000,$B14,Offers!$C$7:$C$3000,G$10,Offers!$AH$7:$AH$3000,"yes"),COUNTIFS(Offers!$B$7:$B$3000,$B14,Offers!$C$7:$C$3000,G$10,Offers!$AI$7:$AI$3000,"yes"))=0,"—",SUMIFS(Review!$O$7:$O$600,Review!$B$7:$B$600,$B14,Review!$C$7:$C$600,G$10)) -> 4.15868 | H14: =IF(IF($E$5="Local prices",COUNTIFS(Offers!$B$7:$B$3000,$B14,Offers!$C$7:$C$3000,H$10,Offers!$AH$7:$AH$3000,"yes"),COUNTIFS(Offers!$B$7:$B$3000,$B14,Offers!$C$7:$C$3000,H$10,Offers!$AI$7:$AI$3000,"yes"))=0,"—",SUMIFS(Review!$O$7:$O$600,Review!$B$7:$B$600,$B14,Review!$C$7:$C$600,H$10)) -> 11.991992 | J14: Austria | K14: =IF(COUNTIFS(Offers!$B$7:$B$3000,$J$6,Offers!$C$7:$C$3000,$J14,Offers!$AI$7:$AI$3000,"yes")=0,"—",SUMIFS(Review!$I$7:$I$600,Review!$B$7:$B$600,$J$6,Review!$C$7:$C$600,$J14)) -> 7.83 | L14: =IF(COUNTIFS(Offers!$B$7:$B$3000,$J$6,Offers!$C$7:$C$3000,$J14,Offers!$AI$7:$AI$3000,"yes")=0,"—",SUMIFS(Review!$J$7:$J$600,Review!$B$7:$B$600,$J$6,Review!$C$7:$C$600,$J14)) -> 14.07 | M14: =IF(COUNTIFS(Offers!$B$7:$B$3000,$J$6,Offers!$C$7:$C$3000,$J14,Offers!$AI$7:$AI$3000,"yes")=0,"—",SUMIFS(Review!$K$7:$K$600,Review!$B$7:$B$600,$J$6,Review!$C$7:$C$600,$J14)) -> 23
B15: GN 1/1 PP lid | C15: =IF(IF($E$5="Local prices",COUNTIFS(Offers!$B$7:$B$3000,$B15,Offers!$C$7:$C$3000,C$10,Offers!$AH$7:$AH$3000,"yes"),COUNTIFS(Offers!$B$7:$B$3000,$B15,Offers!$C$7:$C$3000,C$10,Offers!$AI$7:$AI$3000,"yes"))=0,"—",SUMIFS(Review!$O$7:$O$600,Review!$B$7:$B$600,$B15,Review!$C$7:$C$600,C$10)) -> — | D15: =IF(IF($E$5="Local prices",COUNTIFS(Offers!$B$7:$B$3000,$B15,Offers!$C$7:$C$3000,D$10,Offers!$AH$7:$AH$3000,"yes"),COUNTIFS(Offers!$B$7:$B$3000,$B15,Offers!$C$7:$C$3000,D$10,Offers!$AI$7:$AI$3000,"yes"))=0,"—",SUMIFS(Review!$O$7:$O$600,Review!$B$7:$B$600,$B15,Review!$C$7:$C$600,D$10)) -> 4.50959 | E15: =IF(IF($E$5="Local prices",COUNTIFS(Offers!$B$7:$B$3000,$B15,Offers!$C$7:$C$3000,E$10,Offers!$AH$7:$AH$3000,"yes"),COUNTIFS(Offers!$B$7:$B$3000,$B15,Offers!$C$7:$C$3000,E$10,Offers!$AI$7:$AI$3000,"yes"))=0,"—",SUMIFS(Review!$O$7:$O$600,Review!$B$7:$B$600,$B15,Review!$C$7:$C$600,E$10)) -> 6.525 | F15: =IF(IF($E$5="Local prices",COUNTIFS(Offers!$B$7:$B$3000,$B15,Offers!$C$7:$C$3000,F$10,Offers!$AH$7:$AH$3000,"yes"),COUNTIFS(Offers!$B$7:$B$3000,$B15,Offers!$C$7:$C$3000,F$10,Offers!$AI$7:$AI$3000,"yes"))=0,"—",SUMIFS(Review!$O$7:$O$600,Review!$B$7:$B$600,$B15,Review!$C$7:$C$600,F$10)) -> 7.5 | G15: =IF(IF($E$5="Local prices",COUNTIFS(Offers!$B$7:$B$3000,$B15,Offers!$C$7:$C$3000,G$10,Offers!$AH$7:$AH$3000,"yes"),COUNTIFS(Offers!$B$7:$B$3000,$B15,Offers!$C$7:$C$3000,G$10,Offers!$AI$7:$AI$3000,"yes"))=0,"—",SUMIFS(Review!$O$7:$O$600,Review!$B$7:$B$600,$B15,Review!$C$7:$C$600,G$10)) -> 5.040613 | H15: =IF(IF($E$5="Local prices",COUNTIFS(Offers!$B$7:$B$3000,$B15,Offers!$C$7:$C$3000,H$10,Offers!$AH$7:$AH$3000,"yes"),COUNTIFS(Offers!$B$7:$B$3000,$B15,Offers!$C$7:$C$3000,H$10,Offers!$AI$7:$AI$3000,"yes"))=0,"—",SUMIFS(Review!$O$7:$O$600,Review!$B$7:$B$600,$B15,Review!$C$7:$C$600,H$10)) -> 9.945447 | J15: Germany | K15: =IF(COUNTIFS(Offers!$B$7:$B$3000,$J$6,Offers!$C$7:$C$3000,$J15,Offers!$AI$7:$AI$3000,"yes")=0,"—",SUMIFS(Review!$I$7:$I$600,Review!$B$7:$B$600,$J$6,Review!$C$7:$C$600,$J15)) -> 7.26 | L15: =IF(COUNTIFS(Offers!$B$7:$B$3000,$J$6,Offers!$C$7:$C$3000,$J15,Offers!$AI$7:$AI$3000,"yes")=0,"—",SUMIFS(Review!$J$7:$J$600,Review!$B$7:$B$600,$J$6,Review!$C$7:$C$600,$J15)) -> 13.11 | M15: =IF(COUNTIFS(Offers!$B$7:$B$3000,$J$6,Offers!$C$7:$C$3000,$J15,Offers!$AI$7:$AI$3000,"yes")=0,"—",SUMIFS(Review!$K$7:$K$600,Review!$B$7:$B$600,$J$6,Review!$C$7:$C$600,$J15)) -> 22.43
B16: Squeeze bottle 500 ml, PP, single tip | C16: =IF(IF($E$5="Local prices",COUNTIFS(Offers!$B$7:$B$3000,$B16,Offers!$C$7:$C$3000,C$10,Offers!$AH$7:$AH$3000,"yes"),COUNTIFS(Offers!$B$7:$B$3000,$B16,Offers!$C$7:$C$3000,C$10,Offers!$AI$7:$AI$3000,"yes"))=0,"—",SUMIFS(Review!$O$7:$O$600,Review!$B$7:$B$600,$B16,Review!$C$7:$C$600,C$10)) -> — | D16: =IF(IF($E$5="Local prices",COUNTIFS(Offers!$B$7:$B$3000,$B16,Offers!$C$7:$C$3000,D$10,Offers!$AH$7:$AH$3000,"yes"),COUNTIFS(Offers!$B$7:$B$3000,$B16,Offers!$C$7:$C$3000,D$10,Offers!$AI$7:$AI$3000,"yes"))=0,"—",SUMIFS(Review!$O$7:$O$600,Review!$B$7:$B$600,$B16,Review!$C$7:$C$600,D$10)) -> — | E16: =IF(IF($E$5="Local prices",COUNTIFS(Offers!$B$7:$B$3000,$B16,Offers!$C$7:$C$3000,E$10,Offers!$AH$7:$AH$3000,"yes"),COUNTIFS(Offers!$B$7:$B$3000,$B16,Offers!$C$7:$C$3000,E$10,Offers!$AI$7:$AI$3000,"yes"))=0,"—",SUMIFS(Review!$O$7:$O$600,Review!$B$7:$B$600,$B16,Review!$C$7:$C$600,E$10)) -> 2.32 | F16: =IF(IF($E$5="Local prices",COUNTIFS(Offers!$B$7:$B$3000,$B16,Offers!$C$7:$C$3000,F$10,Offers!$AH$7:$AH$3000,"yes"),COUNTIFS(Offers!$B$7:$B$3000,$B16,Offers!$C$7:$C$3000,F$10,Offers!$AI$7:$AI$3000,"yes"))=0,"—",SUMIFS(Review!$O$7:$O$600,Review!$B$7:$B$600,$B16,Review!$C$7:$C$600,F$10)) -> 2.055 | G16: =IF(IF($E$5="Local prices",COUNTIFS(Offers!$B$7:$B$3000,$B16,Offers!$C$7:$C$3000,G$10,Offers!$AH$7:$AH$3000,"yes"),COUNTIFS(Offers!$B$7:$B$3000,$B16,Offers!$C$7:$C$3000,G$10,Offers!$AI$7:$AI$3000,"yes"))=0,"—",SUMIFS(Review!$O$7:$O$600,Review!$B$7:$B$600,$B16,Review!$C$7:$C$600,G$10)) -> 4.708558 | H16: =IF(IF($E$5="Local prices",COUNTIFS(Offers!$B$7:$B$3000,$B16,Offers!$C$7:$C$3000,H$10,Offers!$AH$7:$AH$3000,"yes"),COUNTIFS(Offers!$B$7:$B$3000,$B16,Offers!$C$7:$C$3000,H$10,Offers!$AI$7:$AI$3000,"yes"))=0,"—",SUMIFS(Review!$O$7:$O$600,Review!$B$7:$B$600,$B16,Review!$C$7:$C$600,H$10)) -> — | J16: Czech | K16: =IF(COUNTIFS(Offers!$B$7:$B$3000,$J$6,Offers!$C$7:$C$3000,$J16,Offers!$AI$7:$AI$3000,"yes")=0,"—",SUMIFS(Review!$I$7:$I$600,Review!$B$7:$B$600,$J$6,Review!$C$7:$C$600,$J16)) -> 7.804741 | L16: =IF(COUNTIFS(Offers!$B$7:$B$3000,$J$6,Offers!$C$7:$C$3000,$J16,Offers!$AI$7:$AI$3000,"yes")=0,"—",SUMIFS(Review!$J$7:$J$600,Review!$B$7:$B$600,$J$6,Review!$C$7:$C$600,$J16)) -> 12.148079 | M16: =IF(COUNTIFS(Offers!$B$7:$B$3000,$J$6,Offers!$C$7:$C$3000,$J16,Offers!$AI$7:$AI$3000,"yes")=0,"—",SUMIFS(Review!$K$7:$K$600,Review!$B$7:$B$600,$J$6,Review!$C$7:$C$600,$J16)) -> 16.986838
B17: Squeeze bottle 1,000 ml, PP, single tip | C17: =IF(IF($E$5="Local prices",COUNTIFS(Offers!$B$7:$B$3000,$B17,Offers!$C$7:$C$3000,C$10,Offers!$AH$7:$AH$3000,"yes"),COUNTIFS(Offers!$B$7:$B$3000,$B17,Offers!$C$7:$C$3000,C$10,Offers!$AI$7:$AI$3000,"yes"))=0,"—",SUMIFS(Review!$O$7:$O$600,Review!$B$7:$B$600,$B17,Review!$C$7:$C$600,C$10)) -> — | D17: =IF(IF($E$5="Local prices",COUNTIFS(Offers!$B$7:$B$3000,$B17,Offers!$C$7:$C$3000,D$10,Offers!$AH$7:$AH$3000,"yes"),COUNTIFS(Offers!$B$7:$B$3000,$B17,Offers!$C$7:$C$3000,D$10,Offers!$AI$7:$AI$3000,"yes"))=0,"—",SUMIFS(Review!$O$7:$O$600,Review!$B$7:$B$600,$B17,Review!$C$7:$C$600,D$10)) -> — | E17: =IF(IF($E$5="Local prices",COUNTIFS(Offers!$B$7:$B$3000,$B17,Offers!$C$7:$C$3000,E$10,Offers!$AH$7:$AH$3000,"yes"),COUNTIFS(Offers!$B$7:$B$3000,$B17,Offers!$C$7:$C$3000,E$10,Offers!$AI$7:$AI$3000,"yes"))=0,"—",SUMIFS(Review!$O$7:$O$600,Review!$B$7:$B$600,$B17,Review!$C$7:$C$600,E$10)) -> 2.96 | F17: =IF(IF($E$5="Local prices",COUNTIFS(Offers!$B$7:$B$3000,$B17,Offers!$C$7:$C$3000,F$10,Offers!$AH$7:$AH$3000,"yes"),COUNTIFS(Offers!$B$7:$B$3000,$B17,Offers!$C$7:$C$3000,F$10,Offers!$AI$7:$AI$3000,"yes"))=0,"—",SUMIFS(Review!$O$7:$O$600,Review!$B$7:$B$600,$B17,Review!$C$7:$C$600,F$10)) -> 1.97 | G17: =IF(IF($E$5="Local prices",COUNTIFS(Offers!$B$7:$B$3000,$B17,Offers!$C$7:$C$3000,G$10,Offers!$AH$7:$AH$3000,"yes"),COUNTIFS(Offers!$B$7:$B$3000,$B17,Offers!$C$7:$C$3000,G$10,Offers!$AI$7:$AI$3000,"yes"))=0,"—",SUMIFS(Review!$O$7:$O$600,Review!$B$7:$B$600,$B17,Review!$C$7:$C$600,G$10)) -> 3.80779 | H17: =IF(IF($E$5="Local prices",COUNTIFS(Offers!$B$7:$B$3000,$B17,Offers!$C$7:$C$3000,H$10,Offers!$AH$7:$AH$3000,"yes"),COUNTIFS(Offers!$B$7:$B$3000,$B17,Offers!$C$7:$C$3000,H$10,Offers!$AI$7:$AI$3000,"yes"))=0,"—",SUMIFS(Review!$O$7:$O$600,Review!$B$7:$B$600,$B17,Review!$C$7:$C$600,H$10)) -> 1.28 | J17: Slovakia | K17: =IF(COUNTIFS(Offers!$B$7:$B$3000,$J$6,Offers!$C$7:$C$3000,$J17,Offers!$AI$7:$AI$3000,"yes")=0,"—",SUMIFS(Review!$I$7:$I$600,Review!$B$7:$B$600,$J$6,Review!$C$7:$C$600,$J17)) -> 16.455285 | L17: =IF(COUNTIFS(Offers!$B$7:$B$3000,$J$6,Offers!$C$7:$C$3000,$J17,Offers!$AI$7:$AI$3000,"yes")=0,"—",SUMIFS(Review!$J$7:$J$600,Review!$B$7:$B$600,$J$6,Review!$C$7:$C$600,$J17)) -> 18.467643 | M17: =IF(COUNTIFS(Offers!$B$7:$B$3000,$J$6,Offers!$C$7:$C$3000,$J17,Offers!$AI$7:$AI$3000,"yes")=0,"—",SUMIFS(Review!$K$7:$K$600,Review!$B$7:$B$600,$J$6,Review!$C$7:$C$600,$J17)) -> 20.48
B18: Squeeze bottle 500 ml, triple tip | C18: =IF(IF($E$5="Local prices",COUNTIFS(Offers!$B$7:$B$3000,$B18,Offers!$C$7:$C$3000,C$10,Offers!$AH$7:$AH$3000,"yes"),COUNTIFS(Offers!$B$7:$B$3000,$B18,Offers!$C$7:$C$3000,C$10,Offers!$AI$7:$AI$3000,"yes"))=0,"—",SUMIFS(Review!$O$7:$O$600,Review!$B$7:$B$600,$B18,Review!$C$7:$C$600,C$10)) -> — | D18: =IF(IF($E$5="Local prices",COUNTIFS(Offers!$B$7:$B$3000,$B18,Offers!$C$7:$C$3000,D$10,Offers!$AH$7:$AH$3000,"yes"),COUNTIFS(Offers!$B$7:$B$3000,$B18,Offers!$C$7:$C$3000,D$10,Offers!$AI$7:$AI$3000,"yes"))=0,"—",SUMIFS(Review!$O$7:$O$600,Review!$B$7:$B$600,$B18,Review!$C$7:$C$600,D$10)) -> — | E18: =IF(IF($E$5="Local prices",COUNTIFS(Offers!$B$7:$B$3000,$B18,Offers!$C$7:$C$3000,E$10,Offers!$AH$7:$AH$3000,"yes"),COUNTIFS(Offers!$B$7:$B$3000,$B18,Offers!$C$7:$C$3000,E$10,Offers!$AI$7:$AI$3000,"yes"))=0,"—",SUMIFS(Review!$O$7:$O$600,Review!$B$7:$B$600,$B18,Review!$C$7:$C$600,E$10)) -> — | F18: =IF(IF($E$5="Local prices",COUNTIFS(Offers!$B$7:$B$3000,$B18,Offers!$C$7:$C$3000,F$10,Offers!$AH$7:$AH$3000,"yes"),COUNTIFS(Offers!$B$7:$B$3000,$B18,Offers!$C$7:$C$3000,F$10,Offers!$AI$7:$AI$3000,"yes"))=0,"—",SUMIFS(Review!$O$7:$O$600,Review!$B$7:$B$600,$B18,Review!$C$7:$C$600,F$10)) -> — | G18: =IF(IF($E$5="Local prices",COUNTIFS(Offers!$B$7:$B$3000,$B18,Offers!$C$7:$C$3000,G$10,Offers!$AH$7:$AH$3000,"yes"),COUNTIFS(Offers!$B$7:$B$3000,$B18,Offers!$C$7:$C$3000,G$10,Offers!$AI$7:$AI$3000,"yes"))=0,"—",SUMIFS(Review!$O$7:$O$600,Review!$B$7:$B$600,$B18,Review!$C$7:$C$600,G$10)) -> — | H18: =IF(IF($E$5="Local prices",COUNTIFS(Offers!$B$7:$B$3000,$B18,Offers!$C$7:$C$3000,H$10,Offers!$AH$7:$AH$3000,"yes"),COUNTIFS(Offers!$B$7:$B$3000,$B18,Offers!$C$7:$C$3000,H$10,Offers!$AI$7:$AI$3000,"yes"))=0,"—",SUMIFS(Review!$O$7:$O$600,Review!$B$7:$B$600,$B18,Review!$C$7:$C$600,H$10)) -> —
B19: Sauce pump dispenser with stand | C19: =IF(IF($E$5="Local prices",COUNTIFS(Offers!$B$7:$B$3000,$B19,Offers!$C$7:$C$3000,C$10,Offers!$AH$7:$AH$3000,"yes"),COUNTIFS(Offers!$B$7:$B$3000,$B19,Offers!$C$7:$C$3000,C$10,Offers!$AI$7:$AI$3000,"yes"))=0,"—",SUMIFS(Review!$O$7:$O$600,Review!$B$7:$B$600,$B19,Review!$C$7:$C$600,C$10)) -> — | D19: =IF(IF($E$5="Local prices",COUNTIFS(Offers!$B$7:$B$3000,$B19,Offers!$C$7:$C$3000,D$10,Offers!$AH$7:$AH$3000,"yes"),COUNTIFS(Offers!$B$7:$B$3000,$B19,Offers!$C$7:$C$3000,D$10,Offers!$AI$7:$AI$3000,"yes"))=0,"—",SUMIFS(Review!$O$7:$O$600,Review!$B$7:$B$600,$B19,Review!$C$7:$C$600,D$10)) -> 16.641903 | E19: =IF(IF($E$5="Local prices",COUNTIFS(Offers!$B$7:$B$3000,$B19,Offers!$C$7:$C$3000,E$10,Offers!$AH$7:$AH$3000,"yes"),COUNTIFS(Offers!$B$7:$B$3000,$B19,Offers!$C$7:$C$3000,E$10,Offers!$AI$7:$AI$3000,"yes"))=0,"—",SUMIFS(Review!$O$7:$O$600,Review!$B$7:$B$600,$B19,Review!$C$7:$C$600,E$10)) -> 30.5 | F19: =IF(IF($E$5="Local prices",COUNTIFS(Offers!$B$7:$B$3000,$B19,Offers!$C$7:$C$3000,F$10,Offers!$AH$7:$AH$3000,"yes"),COUNTIFS(Offers!$B$7:$B$3000,$B19,Offers!$C$7:$C$3000,F$10,Offers!$AI$7:$AI$3000,"yes"))=0,"—",SUMIFS(Review!$O$7:$O$600,Review!$B$7:$B$600,$B19,Review!$C$7:$C$600,F$10)) -> 27.49 | G19: =IF(IF($E$5="Local prices",COUNTIFS(Offers!$B$7:$B$3000,$B19,Offers!$C$7:$C$3000,G$10,Offers!$AH$7:$AH$3000,"yes"),COUNTIFS(Offers!$B$7:$B$3000,$B19,Offers!$C$7:$C$3000,G$10,Offers!$AI$7:$AI$3000,"yes"))=0,"—",SUMIFS(Review!$O$7:$O$600,Review!$B$7:$B$600,$B19,Review!$C$7:$C$600,G$10)) -> 40.84817 | H19: =IF(IF($E$5="Local prices",COUNTIFS(Offers!$B$7:$B$3000,$B19,Offers!$C$7:$C$3000,H$10,Offers!$AH$7:$AH$3000,"yes"),COUNTIFS(Offers!$B$7:$B$3000,$B19,Offers!$C$7:$C$3000,H$10,Offers!$AI$7:$AI$3000,"yes"))=0,"—",SUMIFS(Review!$O$7:$O$600,Review!$B$7:$B$600,$B19,Review!$C$7:$C$600,H$10)) -> —
B20: PE cutting board 530 × 325 × 20 mm | C20: =IF(IF($E$5="Local prices",COUNTIFS(Offers!$B$7:$B$3000,$B20,Offers!$C$7:$C$3000,C$10,Offers!$AH$7:$AH$3000,"yes"),COUNTIFS(Offers!$B$7:$B$3000,$B20,Offers!$C$7:$C$3000,C$10,Offers!$AI$7:$AI$3000,"yes"))=0,"—",SUMIFS(Review!$O$7:$O$600,Review!$B$7:$B$600,$B20,Review!$C$7:$C$600,C$10)) -> — | D20: =IF(IF($E$5="Local prices",COUNTIFS(Offers!$B$7:$B$3000,$B20,Offers!$C$7:$C$3000,D$10,Offers!$AH$7:$AH$3000,"yes"),COUNTIFS(Offers!$B$7:$B$3000,$B20,Offers!$C$7:$C$3000,D$10,Offers!$AI$7:$AI$3000,"yes"))=0,"—",SUMIFS(Review!$O$7:$O$600,Review!$B$7:$B$600,$B20,Review!$C$7:$C$600,D$10)) -> — | E20: =IF(IF($E$5="Local prices",COUNTIFS(Offers!$B$7:$B$3000,$B20,Offers!$C$7:$C$3000,E$10,Offers!$AH$7:$AH$3000,"yes"),COUNTIFS(Offers!$B$7:$B$3000,$B20,Offers!$C$7:$C$3000,E$10,Offers!$AI$7:$AI$3000,"yes"))=0,"—",SUMIFS(Review!$O$7:$O$600,Review!$B$7:$B$600,$B20,Review!$C$7:$C$600,E$10)) -> 24.57 | F20: =IF(IF($E$5="Local prices",COUNTIFS(Offers!$B$7:$B$3000,$B20,Offers!$C$7:$C$3000,F$10,Offers!$AH$7:$AH$3000,"yes"),COUNTIFS(Offers!$B$7:$B$3000,$B20,Offers!$C$7:$C$3000,F$10,Offers!$AI$7:$AI$3000,"yes"))=0,"—",SUMIFS(Review!$O$7:$O$600,Review!$B$7:$B$600,$B20,Review!$C$7:$C$600,F$10)) -> 22.79 | G20: =IF(IF($E$5="Local prices",COUNTIFS(Offers!$B$7:$B$3000,$B20,Offers!$C$7:$C$3000,G$10,Offers!$AH$7:$AH$3000,"yes"),COUNTIFS(Offers!$B$7:$B$3000,$B20,Offers!$C$7:$C$3000,G$10,Offers!$AI$7:$AI$3000,"yes"))=0,"—",SUMIFS(Review!$O$7:$O$600,Review!$B$7:$B$600,$B20,Review!$C$7:$C$600,G$10)) -> 44.628937 | H20: =IF(IF($E$5="Local prices",COUNTIFS(Offers!$B$7:$B$3000,$B20,Offers!$C$7:$C$3000,H$10,Offers!$AH$7:$AH$3000,"yes"),COUNTIFS(Offers!$B$7:$B$3000,$B20,Offers!$C$7:$C$3000,H$10,Offers!$AI$7:$AI$3000,"yes"))=0,"—",SUMIFS(Review!$O$7:$O$600,Review!$B$7:$B$600,$B20,Review!$C$7:$C$600,H$10)) -> 36.154675 | J20: Price basis
B21: PE cutting board 600 × 400 × 20 mm | C21: =IF(IF($E$5="Local prices",COUNTIFS(Offers!$B$7:$B$3000,$B21,Offers!$C$7:$C$3000,C$10,Offers!$AH$7:$AH$3000,"yes"),COUNTIFS(Offers!$B$7:$B$3000,$B21,Offers!$C$7:$C$3000,C$10,Offers!$AI$7:$AI$3000,"yes"))=0,"—",SUMIFS(Review!$O$7:$O$600,Review!$B$7:$B$600,$B21,Review!$C$7:$C$600,C$10)) -> — | D21: =IF(IF($E$5="Local prices",COUNTIFS(Offers!$B$7:$B$3000,$B21,Offers!$C$7:$C$3000,D$10,Offers!$AH$7:$AH$3000,"yes"),COUNTIFS(Offers!$B$7:$B$3000,$B21,Offers!$C$7:$C$3000,D$10,Offers!$AI$7:$AI$3000,"yes"))=0,"—",SUMIFS(Review!$O$7:$O$600,Review!$B$7:$B$600,$B21,Review!$C$7:$C$600,D$10)) -> — | E21: =IF(IF($E$5="Local prices",COUNTIFS(Offers!$B$7:$B$3000,$B21,Offers!$C$7:$C$3000,E$10,Offers!$AH$7:$AH$3000,"yes"),COUNTIFS(Offers!$B$7:$B$3000,$B21,Offers!$C$7:$C$3000,E$10,Offers!$AI$7:$AI$3000,"yes"))=0,"—",SUMIFS(Review!$O$7:$O$600,Review!$B$7:$B$600,$B21,Review!$C$7:$C$600,E$10)) -> 33.5 | F21: =IF(IF($E$5="Local prices",COUNTIFS(Offers!$B$7:$B$3000,$B21,Offers!$C$7:$C$3000,F$10,Offers!$AH$7:$AH$3000,"yes"),COUNTIFS(Offers!$B$7:$B$3000,$B21,Offers!$C$7:$C$3000,F$10,Offers!$AI$7:$AI$3000,"yes"))=0,"—",SUMIFS(Review!$O$7:$O$600,Review!$B$7:$B$600,$B21,Review!$C$7:$C$600,F$10)) -> 34.275 | G21: =IF(IF($E$5="Local prices",COUNTIFS(Offers!$B$7:$B$3000,$B21,Offers!$C$7:$C$3000,G$10,Offers!$AH$7:$AH$3000,"yes"),COUNTIFS(Offers!$B$7:$B$3000,$B21,Offers!$C$7:$C$3000,G$10,Offers!$AI$7:$AI$3000,"yes"))=0,"—",SUMIFS(Review!$O$7:$O$600,Review!$B$7:$B$600,$B21,Review!$C$7:$C$600,G$10)) -> 40.597592 | H21: =IF(IF($E$5="Local prices",COUNTIFS(Offers!$B$7:$B$3000,$B21,Offers!$C$7:$C$3000,H$10,Offers!$AH$7:$AH$3000,"yes"),COUNTIFS(Offers!$B$7:$B$3000,$B21,Offers!$C$7:$C$3000,H$10,Offers!$AI$7:$AI$3000,"yes"))=0,"—",SUMIFS(Review!$O$7:$O$600,Review!$B$7:$B$600,$B21,Review!$C$7:$C$600,H$10)) -> 32.85 | J21: Hungary and Romania prices are net per piece, as confirmed by you.
B22: PE cutting board 300 × 200 × 10 mm | C22: =IF(IF($E$5="Local prices",COUNTIFS(Offers!$B$7:$B$3000,$B22,Offers!$C$7:$C$3000,C$10,Offers!$AH$7:$AH$3000,"yes"),COUNTIFS(Offers!$B$7:$B$3000,$B22,Offers!$C$7:$C$3000,C$10,Offers!$AI$7:$AI$3000,"yes"))=0,"—",SUMIFS(Review!$O$7:$O$600,Review!$B$7:$B$600,$B22,Review!$C$7:$C$600,C$10)) -> — | D22: =IF(IF($E$5="Local prices",COUNTIFS(Offers!$B$7:$B$3000,$B22,Offers!$C$7:$C$3000,D$10,Offers!$AH$7:$AH$3000,"yes"),COUNTIFS(Offers!$B$7:$B$3000,$B22,Offers!$C$7:$C$3000,D$10,Offers!$AI$7:$AI$3000,"yes"))=0,"—",SUMIFS(Review!$O$7:$O$600,Review!$B$7:$B$600,$B22,Review!$C$7:$C$600,D$10)) -> — | E22: =IF(IF($E$5="Local prices",COUNTIFS(Offers!$B$7:$B$3000,$B22,Offers!$C$7:$C$3000,E$10,Offers!$AH$7:$AH$3000,"yes"),COUNTIFS(Offers!$B$7:$B$3000,$B22,Offers!$C$7:$C$3000,E$10,Offers!$AI$7:$AI$3000,"yes"))=0,"—",SUMIFS(Review!$O$7:$O$600,Review!$B$7:$B$600,$B22,Review!$C$7:$C$600,E$10)) -> 8.12 | F22: =IF(IF($E$5="Local prices",COUNTIFS(Offers!$B$7:$B$3000,$B22,Offers!$C$7:$C$3000,F$10,Offers!$AH$7:$AH$3000,"yes"),COUNTIFS(Offers!$B$7:$B$3000,$B22,Offers!$C$7:$C$3000,F$10,Offers!$AI$7:$AI$3000,"yes"))=0,"—",SUMIFS(Review!$O$7:$O$600,Review!$B$7:$B$600,$B22,Review!$C$7:$C$600,F$10)) -> 7.96 | G22: =IF(IF($E$5="Local prices",COUNTIFS(Offers!$B$7:$B$3000,$B22,Offers!$C$7:$C$3000,G$10,Offers!$AH$7:$AH$3000,"yes"),COUNTIFS(Offers!$B$7:$B$3000,$B22,Offers!$C$7:$C$3000,G$10,Offers!$AI$7:$AI$3000,"yes"))=0,"—",SUMIFS(Review!$O$7:$O$600,Review!$B$7:$B$600,$B22,Review!$C$7:$C$600,G$10)) -> 6.35123 | H22: =IF(IF($E$5="Local prices",COUNTIFS(Offers!$B$7:$B$3000,$B22,Offers!$C$7:$C$3000,H$10,Offers!$AH$7:$AH$3000,"yes"),COUNTIFS(Offers!$B$7:$B$3000,$B22,Offers!$C$7:$C$3000,H$10,Offers!$AI$7:$AI$3000,"yes"))=0,"—",SUMIFS(Review!$O$7:$O$600,Review!$B$7:$B$600,$B22,Review!$C$7:$C$600,H$10)) -> 6.59
B23: PP dough box 600 × 400 × 100 mm | C23: =IF(IF($E$5="Local prices",COUNTIFS(Offers!$B$7:$B$3000,$B23,Offers!$C$7:$C$3000,C$10,Offers!$AH$7:$AH$3000,"yes"),COUNTIFS(Offers!$B$7:$B$3000,$B23,Offers!$C$7:$C$3000,C$10,Offers!$AI$7:$AI$3000,"yes"))=0,"—",SUMIFS(Review!$O$7:$O$600,Review!$B$7:$B$600,$B23,Review!$C$7:$C$600,C$10)) -> 10.898364 | D23: =IF(IF($E$5="Local prices",COUNTIFS(Offers!$B$7:$B$3000,$B23,Offers!$C$7:$C$3000,D$10,Offers!$AH$7:$AH$3000,"yes"),COUNTIFS(Offers!$B$7:$B$3000,$B23,Offers!$C$7:$C$3000,D$10,Offers!$AI$7:$AI$3000,"yes"))=0,"—",SUMIFS(Review!$O$7:$O$600,Review!$B$7:$B$600,$B23,Review!$C$7:$C$600,D$10)) -> 11.482401 | E23: =IF(IF($E$5="Local prices",COUNTIFS(Offers!$B$7:$B$3000,$B23,Offers!$C$7:$C$3000,E$10,Offers!$AH$7:$AH$3000,"yes"),COUNTIFS(Offers!$B$7:$B$3000,$B23,Offers!$C$7:$C$3000,E$10,Offers!$AI$7:$AI$3000,"yes"))=0,"—",SUMIFS(Review!$O$7:$O$600,Review!$B$7:$B$600,$B23,Review!$C$7:$C$600,E$10)) -> 21.28 | F23: =IF(IF($E$5="Local prices",COUNTIFS(Offers!$B$7:$B$3000,$B23,Offers!$C$7:$C$3000,F$10,Offers!$AH$7:$AH$3000,"yes"),COUNTIFS(Offers!$B$7:$B$3000,$B23,Offers!$C$7:$C$3000,F$10,Offers!$AI$7:$AI$3000,"yes"))=0,"—",SUMIFS(Review!$O$7:$O$600,Review!$B$7:$B$600,$B23,Review!$C$7:$C$600,F$10)) -> 21.18 | G23: =IF(IF($E$5="Local prices",COUNTIFS(Offers!$B$7:$B$3000,$B23,Offers!$C$7:$C$3000,G$10,Offers!$AH$7:$AH$3000,"yes"),COUNTIFS(Offers!$B$7:$B$3000,$B23,Offers!$C$7:$C$3000,G$10,Offers!$AI$7:$AI$3000,"yes"))=0,"—",SUMIFS(Review!$O$7:$O$600,Review!$B$7:$B$600,$B23,Review!$C$7:$C$600,G$10)) -> 17.221857 | H23: =IF(IF($E$5="Local prices",COUNTIFS(Offers!$B$7:$B$3000,$B23,Offers!$C$7:$C$3000,H$10,Offers!$AH$7:$AH$3000,"yes"),COUNTIFS(Offers!$B$7:$B$3000,$B23,Offers!$C$7:$C$3000,H$10,Offers!$AI$7:$AI$3000,"yes"))=0,"—",SUMIFS(Review!$O$7:$O$600,Review!$B$7:$B$600,$B23,Review!$C$7:$C$600,H$10)) -> 15.658333
B24: Lid for 600 × 400 mm dough box | C24: =IF(IF($E$5="Local prices",COUNTIFS(Offers!$B$7:$B$3000,$B24,Offers!$C$7:$C$3000,C$10,Offers!$AH$7:$AH$3000,"yes"),COUNTIFS(Offers!$B$7:$B$3000,$B24,Offers!$C$7:$C$3000,C$10,Offers!$AI$7:$AI$3000,"yes"))=0,"—",SUMIFS(Review!$O$7:$O$600,Review!$B$7:$B$600,$B24,Review!$C$7:$C$600,C$10)) -> 7.322936 | D24: =IF(IF($E$5="Local prices",COUNTIFS(Offers!$B$7:$B$3000,$B24,Offers!$C$7:$C$3000,D$10,Offers!$AH$7:$AH$3000,"yes"),COUNTIFS(Offers!$B$7:$B$3000,$B24,Offers!$C$7:$C$3000,D$10,Offers!$AI$7:$AI$3000,"yes"))=0,"—",SUMIFS(Review!$O$7:$O$600,Review!$B$7:$B$600,$B24,Review!$C$7:$C$600,D$10)) -> 7.989364 | E24: =IF(IF($E$5="Local prices",COUNTIFS(Offers!$B$7:$B$3000,$B24,Offers!$C$7:$C$3000,E$10,Offers!$AH$7:$AH$3000,"yes"),COUNTIFS(Offers!$B$7:$B$3000,$B24,Offers!$C$7:$C$3000,E$10,Offers!$AI$7:$AI$3000,"yes"))=0,"—",SUMIFS(Review!$O$7:$O$600,Review!$B$7:$B$600,$B24,Review!$C$7:$C$600,E$10)) -> 10.49 | F24: =IF(IF($E$5="Local prices",COUNTIFS(Offers!$B$7:$B$3000,$B24,Offers!$C$7:$C$3000,F$10,Offers!$AH$7:$AH$3000,"yes"),COUNTIFS(Offers!$B$7:$B$3000,$B24,Offers!$C$7:$C$3000,F$10,Offers!$AI$7:$AI$3000,"yes"))=0,"—",SUMIFS(Review!$O$7:$O$600,Review!$B$7:$B$600,$B24,Review!$C$7:$C$600,F$10)) -> 8.69 | G24: =IF(IF($E$5="Local prices",COUNTIFS(Offers!$B$7:$B$3000,$B24,Offers!$C$7:$C$3000,G$10,Offers!$AH$7:$AH$3000,"yes"),COUNTIFS(Offers!$B$7:$B$3000,$B24,Offers!$C$7:$C$3000,G$10,Offers!$AI$7:$AI$3000,"yes"))=0,"—",SUMIFS(Review!$O$7:$O$600,Review!$B$7:$B$600,$B24,Review!$C$7:$C$600,G$10)) -> 7.984895 | H24: =IF(IF($E$5="Local prices",COUNTIFS(Offers!$B$7:$B$3000,$B24,Offers!$C$7:$C$3000,H$10,Offers!$AH$7:$AH$3000,"yes"),COUNTIFS(Offers!$B$7:$B$3000,$B24,Offers!$C$7:$C$3000,H$10,Offers!$AI$7:$AI$3000,"yes"))=0,"—",SUMIFS(Review!$O$7:$O$600,Review!$B$7:$B$600,$B24,Review!$C$7:$C$600,H$10)) -> 11.382521 | J24: Current FX
B25: PE dough box 600 × 400 × 75 mm | C25: =IF(IF($E$5="Local prices",COUNTIFS(Offers!$B$7:$B$3000,$B25,Offers!$C$7:$C$3000,C$10,Offers!$AH$7:$AH$3000,"yes"),COUNTIFS(Offers!$B$7:$B$3000,$B25,Offers!$C$7:$C$3000,C$10,Offers!$AI$7:$AI$3000,"yes"))=0,"—",SUMIFS(Review!$O$7:$O$600,Review!$B$7:$B$600,$B25,Review!$C$7:$C$600,C$10)) -> 10.925678 | D25: =IF(IF($E$5="Local prices",COUNTIFS(Offers!$B$7:$B$3000,$B25,Offers!$C$7:$C$3000,D$10,Offers!$AH$7:$AH$3000,"yes"),COUNTIFS(Offers!$B$7:$B$3000,$B25,Offers!$C$7:$C$3000,D$10,Offers!$AI$7:$AI$3000,"yes"))=0,"—",SUMIFS(Review!$O$7:$O$600,Review!$B$7:$B$600,$B25,Review!$C$7:$C$600,D$10)) -> — | E25: =IF(IF($E$5="Local prices",COUNTIFS(Offers!$B$7:$B$3000,$B25,Offers!$C$7:$C$3000,E$10,Offers!$AH$7:$AH$3000,"yes"),COUNTIFS(Offers!$B$7:$B$3000,$B25,Offers!$C$7:$C$3000,E$10,Offers!$AI$7:$AI$3000,"yes"))=0,"—",SUMIFS(Review!$O$7:$O$600,Review!$B$7:$B$600,$B25,Review!$C$7:$C$600,E$10)) -> 12.8 | F25: =IF(IF($E$5="Local prices",COUNTIFS(Offers!$B$7:$B$3000,$B25,Offers!$C$7:$C$3000,F$10,Offers!$AH$7:$AH$3000,"yes"),COUNTIFS(Offers!$B$7:$B$3000,$B25,Offers!$C$7:$C$3000,F$10,Offers!$AI$7:$AI$3000,"yes"))=0,"—",SUMIFS(Review!$O$7:$O$600,Review!$B$7:$B$600,$B25,Review!$C$7:$C$600,F$10)) -> 11.395 | G25: =IF(IF($E$5="Local prices",COUNTIFS(Offers!$B$7:$B$3000,$B25,Offers!$C$7:$C$3000,G$10,Offers!$AH$7:$AH$3000,"yes"),COUNTIFS(Offers!$B$7:$B$3000,$B25,Offers!$C$7:$C$3000,G$10,Offers!$AI$7:$AI$3000,"yes"))=0,"—",SUMIFS(Review!$O$7:$O$600,Review!$B$7:$B$600,$B25,Review!$C$7:$C$600,G$10)) -> 10.557609 | H25: =IF(IF($E$5="Local prices",COUNTIFS(Offers!$B$7:$B$3000,$B25,Offers!$C$7:$C$3000,H$10,Offers!$AH$7:$AH$3000,"yes"),COUNTIFS(Offers!$B$7:$B$3000,$B25,Offers!$C$7:$C$3000,H$10,Offers!$AI$7:$AI$3000,"yes"))=0,"—",SUMIFS(Review!$O$7:$O$600,Review!$B$7:$B$600,$B25,Review!$C$7:$C$600,H$10)) -> 15.21 | J25: Erste rates are applied to analytical conversions. Historical prices and research dates remain unchanged.
B26: Front-load GN 1/1 thermobox, 80–90 L | C26: =IF(IF($E$5="Local prices",COUNTIFS(Offers!$B$7:$B$3000,$B26,Offers!$C$7:$C$3000,C$10,Offers!$AH$7:$AH$3000,"yes"),COUNTIFS(Offers!$B$7:$B$3000,$B26,Offers!$C$7:$C$3000,C$10,Offers!$AI$7:$AI$3000,"yes"))=0,"—",SUMIFS(Review!$O$7:$O$600,Review!$B$7:$B$600,$B26,Review!$C$7:$C$600,C$10)) -> — | D26: =IF(IF($E$5="Local prices",COUNTIFS(Offers!$B$7:$B$3000,$B26,Offers!$C$7:$C$3000,D$10,Offers!$AH$7:$AH$3000,"yes"),COUNTIFS(Offers!$B$7:$B$3000,$B26,Offers!$C$7:$C$3000,D$10,Offers!$AI$7:$AI$3000,"yes"))=0,"—",SUMIFS(Review!$O$7:$O$600,Review!$B$7:$B$600,$B26,Review!$C$7:$C$600,D$10)) -> — | E26: =IF(IF($E$5="Local prices",COUNTIFS(Offers!$B$7:$B$3000,$B26,Offers!$C$7:$C$3000,E$10,Offers!$AH$7:$AH$3000,"yes"),COUNTIFS(Offers!$B$7:$B$3000,$B26,Offers!$C$7:$C$3000,E$10,Offers!$AI$7:$AI$3000,"yes"))=0,"—",SUMIFS(Review!$O$7:$O$600,Review!$B$7:$B$600,$B26,Review!$C$7:$C$600,E$10)) -> 260.435 | F26: =IF(IF($E$5="Local prices",COUNTIFS(Offers!$B$7:$B$3000,$B26,Offers!$C$7:$C$3000,F$10,Offers!$AH$7:$AH$3000,"yes"),COUNTIFS(Offers!$B$7:$B$3000,$B26,Offers!$C$7:$C$3000,F$10,Offers!$AI$7:$AI$3000,"yes"))=0,"—",SUMIFS(Review!$O$7:$O$600,Review!$B$7:$B$600,$B26,Review!$C$7:$C$600,F$10)) -> 252.97 | G26: =IF(IF($E$5="Local prices",COUNTIFS(Offers!$B$7:$B$3000,$B26,Offers!$C$7:$C$3000,G$10,Offers!$AH$7:$AH$3000,"yes"),COUNTIFS(Offers!$B$7:$B$3000,$B26,Offers!$C$7:$C$3000,G$10,Offers!$AI$7:$AI$3000,"yes"))=0,"—",SUMIFS(Review!$O$7:$O$600,Review!$B$7:$B$600,$B26,Review!$C$7:$C$600,G$10)) -> 225.51513 | H26: =IF(IF($E$5="Local prices",COUNTIFS(Offers!$B$7:$B$3000,$B26,Offers!$C$7:$C$3000,H$10,Offers!$AH$7:$AH$3000,"yes"),COUNTIFS(Offers!$B$7:$B$3000,$B26,Offers!$C$7:$C$3000,H$10,Offers!$AI$7:$AI$3000,"yes"))=0,"—",SUMIFS(Review!$O$7:$O$600,Review!$B$7:$B$600,$B26,Review!$C$7:$C$600,H$10)) -> 207.12
B27: Service tray approx. 370 × 530 mm | C27: =IF(IF($E$5="Local prices",COUNTIFS(Offers!$B$7:$B$3000,$B27,Offers!$C$7:$C$3000,C$10,Offers!$AH$7:$AH$3000,"yes"),COUNTIFS(Offers!$B$7:$B$3000,$B27,Offers!$C$7:$C$3000,C$10,Offers!$AI$7:$AI$3000,"yes"))=0,"—",SUMIFS(Review!$O$7:$O$600,Review!$B$7:$B$600,$B27,Review!$C$7:$C$600,C$10)) -> — | D27: =IF(IF($E$5="Local prices",COUNTIFS(Offers!$B$7:$B$3000,$B27,Offers!$C$7:$C$3000,D$10,Offers!$AH$7:$AH$3000,"yes"),COUNTIFS(Offers!$B$7:$B$3000,$B27,Offers!$C$7:$C$3000,D$10,Offers!$AI$7:$AI$3000,"yes"))=0,"—",SUMIFS(Review!$O$7:$O$600,Review!$B$7:$B$600,$B27,Review!$C$7:$C$600,D$10)) -> — | E27: =IF(IF($E$5="Local prices",COUNTIFS(Offers!$B$7:$B$3000,$B27,Offers!$C$7:$C$3000,E$10,Offers!$AH$7:$AH$3000,"yes"),COUNTIFS(Offers!$B$7:$B$3000,$B27,Offers!$C$7:$C$3000,E$10,Offers!$AI$7:$AI$3000,"yes"))=0,"—",SUMIFS(Review!$O$7:$O$600,Review!$B$7:$B$600,$B27,Review!$C$7:$C$600,E$10)) -> 11.365 | F27: =IF(IF($E$5="Local prices",COUNTIFS(Offers!$B$7:$B$3000,$B27,Offers!$C$7:$C$3000,F$10,Offers!$AH$7:$AH$3000,"yes"),COUNTIFS(Offers!$B$7:$B$3000,$B27,Offers!$C$7:$C$3000,F$10,Offers!$AI$7:$AI$3000,"yes"))=0,"—",SUMIFS(Review!$O$7:$O$600,Review!$B$7:$B$600,$B27,Review!$C$7:$C$600,F$10)) -> 7.47 | G27: =IF(IF($E$5="Local prices",COUNTIFS(Offers!$B$7:$B$3000,$B27,Offers!$C$7:$C$3000,G$10,Offers!$AH$7:$AH$3000,"yes"),COUNTIFS(Offers!$B$7:$B$3000,$B27,Offers!$C$7:$C$3000,G$10,Offers!$AI$7:$AI$3000,"yes"))=0,"—",SUMIFS(Review!$O$7:$O$600,Review!$B$7:$B$600,$B27,Review!$C$7:$C$600,G$10)) -> 8.195142 | H27: =IF(IF($E$5="Local prices",COUNTIFS(Offers!$B$7:$B$3000,$B27,Offers!$C$7:$C$3000,H$10,Offers!$AH$7:$AH$3000,"yes"),COUNTIFS(Offers!$B$7:$B$3000,$B27,Offers!$C$7:$C$3000,H$10,Offers!$AI$7:$AI$3000,"yes"))=0,"—",SUMIFS(Review!$O$7:$O$600,Review!$B$7:$B$600,$B27,Review!$C$7:$C$600,H$10)) -> —
B28: Thermo tray + lid, 5–6 compartments | C28: =IF(IF($E$5="Local prices",COUNTIFS(Offers!$B$7:$B$3000,$B28,Offers!$C$7:$C$3000,C$10,Offers!$AH$7:$AH$3000,"yes"),COUNTIFS(Offers!$B$7:$B$3000,$B28,Offers!$C$7:$C$3000,C$10,Offers!$AI$7:$AI$3000,"yes"))=0,"—",SUMIFS(Review!$O$7:$O$600,Review!$B$7:$B$600,$B28,Review!$C$7:$C$600,C$10)) -> — | D28: =IF(IF($E$5="Local prices",COUNTIFS(Offers!$B$7:$B$3000,$B28,Offers!$C$7:$C$3000,D$10,Offers!$AH$7:$AH$3000,"yes"),COUNTIFS(Offers!$B$7:$B$3000,$B28,Offers!$C$7:$C$3000,D$10,Offers!$AI$7:$AI$3000,"yes"))=0,"—",SUMIFS(Review!$O$7:$O$600,Review!$B$7:$B$600,$B28,Review!$C$7:$C$600,D$10)) -> — | E28: =IF(IF($E$5="Local prices",COUNTIFS(Offers!$B$7:$B$3000,$B28,Offers!$C$7:$C$3000,E$10,Offers!$AH$7:$AH$3000,"yes"),COUNTIFS(Offers!$B$7:$B$3000,$B28,Offers!$C$7:$C$3000,E$10,Offers!$AI$7:$AI$3000,"yes"))=0,"—",SUMIFS(Review!$O$7:$O$600,Review!$B$7:$B$600,$B28,Review!$C$7:$C$600,E$10)) -> 26.19 | F28: =IF(IF($E$5="Local prices",COUNTIFS(Offers!$B$7:$B$3000,$B28,Offers!$C$7:$C$3000,F$10,Offers!$AH$7:$AH$3000,"yes"),COUNTIFS(Offers!$B$7:$B$3000,$B28,Offers!$C$7:$C$3000,F$10,Offers!$AI$7:$AI$3000,"yes"))=0,"—",SUMIFS(Review!$O$7:$O$600,Review!$B$7:$B$600,$B28,Review!$C$7:$C$600,F$10)) -> 29.74 | G28: =IF(IF($E$5="Local prices",COUNTIFS(Offers!$B$7:$B$3000,$B28,Offers!$C$7:$C$3000,G$10,Offers!$AH$7:$AH$3000,"yes"),COUNTIFS(Offers!$B$7:$B$3000,$B28,Offers!$C$7:$C$3000,G$10,Offers!$AI$7:$AI$3000,"yes"))=0,"—",SUMIFS(Review!$O$7:$O$600,Review!$B$7:$B$600,$B28,Review!$C$7:$C$600,G$10)) -> 99.00991 | H28: =IF(IF($E$5="Local prices",COUNTIFS(Offers!$B$7:$B$3000,$B28,Offers!$C$7:$C$3000,H$10,Offers!$AH$7:$AH$3000,"yes"),COUNTIFS(Offers!$B$7:$B$3000,$B28,Offers!$C$7:$C$3000,H$10,Offers!$AI$7:$AI$3000,"yes"))=0,"—",SUMIFS(Review!$O$7:$O$600,Review!$B$7:$B$600,$B28,Review!$C$7:$C$600,H$10)) -> — | J28: Your review
B29: GN 1/1 PP container, 65 mm | C29: =IF(IF($E$5="Local prices",COUNTIFS(Offers!$B$7:$B$3000,$B29,Offers!$C$7:$C$3000,C$10,Offers!$AH$7:$AH$3000,"yes"),COUNTIFS(Offers!$B$7:$B$3000,$B29,Offers!$C$7:$C$3000,C$10,Offers!$AI$7:$AI$3000,"yes"))=0,"—",SUMIFS(Review!$O$7:$O$600,Review!$B$7:$B$600,$B29,Review!$C$7:$C$600,C$10)) -> — | D29: =IF(IF($E$5="Local prices",COUNTIFS(Offers!$B$7:$B$3000,$B29,Offers!$C$7:$C$3000,D$10,Offers!$AH$7:$AH$3000,"yes"),COUNTIFS(Offers!$B$7:$B$3000,$B29,Offers!$C$7:$C$3000,D$10,Offers!$AI$7:$AI$3000,"yes"))=0,"—",SUMIFS(Review!$O$7:$O$600,Review!$B$7:$B$600,$B29,Review!$C$7:$C$600,D$10)) -> — | E29: =IF(IF($E$5="Local prices",COUNTIFS(Offers!$B$7:$B$3000,$B29,Offers!$C$7:$C$3000,E$10,Offers!$AH$7:$AH$3000,"yes"),COUNTIFS(Offers!$B$7:$B$3000,$B29,Offers!$C$7:$C$3000,E$10,Offers!$AI$7:$AI$3000,"yes"))=0,"—",SUMIFS(Review!$O$7:$O$600,Review!$B$7:$B$600,$B29,Review!$C$7:$C$600,E$10)) -> 12.23 | F29: =IF(IF($E$5="Local prices",COUNTIFS(Offers!$B$7:$B$3000,$B29,Offers!$C$7:$C$3000,F$10,Offers!$AH$7:$AH$3000,"yes"),COUNTIFS(Offers!$B$7:$B$3000,$B29,Offers!$C$7:$C$3000,F$10,Offers!$AI$7:$AI$3000,"yes"))=0,"—",SUMIFS(Review!$O$7:$O$600,Review!$B$7:$B$600,$B29,Review!$C$7:$C$600,F$10)) -> 8.505 | G29: =IF(IF($E$5="Local prices",COUNTIFS(Offers!$B$7:$B$3000,$B29,Offers!$C$7:$C$3000,G$10,Offers!$AH$7:$AH$3000,"yes"),COUNTIFS(Offers!$B$7:$B$3000,$B29,Offers!$C$7:$C$3000,G$10,Offers!$AI$7:$AI$3000,"yes"))=0,"—",SUMIFS(Review!$O$7:$O$600,Review!$B$7:$B$600,$B29,Review!$C$7:$C$600,G$10)) -> 7.596746 | H29: =IF(IF($E$5="Local prices",COUNTIFS(Offers!$B$7:$B$3000,$B29,Offers!$C$7:$C$3000,H$10,Offers!$AH$7:$AH$3000,"yes"),COUNTIFS(Offers!$B$7:$B$3000,$B29,Offers!$C$7:$C$3000,H$10,Offers!$AI$7:$AI$3000,"yes"))=0,"—",SUMIFS(Review!$O$7:$O$600,Review!$B$7:$B$600,$B29,Review!$C$7:$C$600,H$10)) -> — | J29: Record decisions, priorities and comments in Review. Add offer-specific comments in Offers.
B30: GN 1/3 PC container, 100 mm | C30: =IF(IF($E$5="Local prices",COUNTIFS(Offers!$B$7:$B$3000,$B30,Offers!$C$7:$C$3000,C$10,Offers!$AH$7:$AH$3000,"yes"),COUNTIFS(Offers!$B$7:$B$3000,$B30,Offers!$C$7:$C$3000,C$10,Offers!$AI$7:$AI$3000,"yes"))=0,"—",SUMIFS(Review!$O$7:$O$600,Review!$B$7:$B$600,$B30,Review!$C$7:$C$600,C$10)) -> — | D30: =IF(IF($E$5="Local prices",COUNTIFS(Offers!$B$7:$B$3000,$B30,Offers!$C$7:$C$3000,D$10,Offers!$AH$7:$AH$3000,"yes"),COUNTIFS(Offers!$B$7:$B$3000,$B30,Offers!$C$7:$C$3000,D$10,Offers!$AI$7:$AI$3000,"yes"))=0,"—",SUMIFS(Review!$O$7:$O$600,Review!$B$7:$B$600,$B30,Review!$C$7:$C$600,D$10)) -> — | E30: =IF(IF($E$5="Local prices",COUNTIFS(Offers!$B$7:$B$3000,$B30,Offers!$C$7:$C$3000,E$10,Offers!$AH$7:$AH$3000,"yes"),COUNTIFS(Offers!$B$7:$B$3000,$B30,Offers!$C$7:$C$3000,E$10,Offers!$AI$7:$AI$3000,"yes"))=0,"—",SUMIFS(Review!$O$7:$O$600,Review!$B$7:$B$600,$B30,Review!$C$7:$C$600,E$10)) -> 7.295 | F30: =IF(IF($E$5="Local prices",COUNTIFS(Offers!$B$7:$B$3000,$B30,Offers!$C$7:$C$3000,F$10,Offers!$AH$7:$AH$3000,"yes"),COUNTIFS(Offers!$B$7:$B$3000,$B30,Offers!$C$7:$C$3000,F$10,Offers!$AI$7:$AI$3000,"yes"))=0,"—",SUMIFS(Review!$O$7:$O$600,Review!$B$7:$B$600,$B30,Review!$C$7:$C$600,F$10)) -> 5.52 | G30: =IF(IF($E$5="Local prices",COUNTIFS(Offers!$B$7:$B$3000,$B30,Offers!$C$7:$C$3000,G$10,Offers!$AH$7:$AH$3000,"yes"),COUNTIFS(Offers!$B$7:$B$3000,$B30,Offers!$C$7:$C$3000,G$10,Offers!$AI$7:$AI$3000,"yes"))=0,"—",SUMIFS(Review!$O$7:$O$600,Review!$B$7:$B$600,$B30,Review!$C$7:$C$600,G$10)) -> 5.479942 | H30: =IF(IF($E$5="Local prices",COUNTIFS(Offers!$B$7:$B$3000,$B30,Offers!$C$7:$C$3000,H$10,Offers!$AH$7:$AH$3000,"yes"),COUNTIFS(Offers!$B$7:$B$3000,$B30,Offers!$C$7:$C$3000,H$10,Offers!$AI$7:$AI$3000,"yes"))=0,"—",SUMIFS(Review!$O$7:$O$600,Review!$B$7:$B$600,$B30,Review!$C$7:$C$600,H$10)) -> —
B31: GN 1/2 PP container, 150 mm | C31: =IF(IF($E$5="Local prices",COUNTIFS(Offers!$B$7:$B$3000,$B31,Offers!$C$7:$C$3000,C$10,Offers!$AH$7:$AH$3000,"yes"),COUNTIFS(Offers!$B$7:$B$3000,$B31,Offers!$C$7:$C$3000,C$10,Offers!$AI$7:$AI$3000,"yes"))=0,"—",SUMIFS(Review!$O$7:$O$600,Review!$B$7:$B$600,$B31,Review!$C$7:$C$600,C$10)) -> — | D31: =IF(IF($E$5="Local prices",COUNTIFS(Offers!$B$7:$B$3000,$B31,Offers!$C$7:$C$3000,D$10,Offers!$AH$7:$AH$3000,"yes"),COUNTIFS(Offers!$B$7:$B$3000,$B31,Offers!$C$7:$C$3000,D$10,Offers!$AI$7:$AI$3000,"yes"))=0,"—",SUMIFS(Review!$O$7:$O$600,Review!$B$7:$B$600,$B31,Review!$C$7:$C$600,D$10)) -> — | E31: =IF(IF($E$5="Local prices",COUNTIFS(Offers!$B$7:$B$3000,$B31,Offers!$C$7:$C$3000,E$10,Offers!$AH$7:$AH$3000,"yes"),COUNTIFS(Offers!$B$7:$B$3000,$B31,Offers!$C$7:$C$3000,E$10,Offers!$AI$7:$AI$3000,"yes"))=0,"—",SUMIFS(Review!$O$7:$O$600,Review!$B$7:$B$600,$B31,Review!$C$7:$C$600,E$10)) -> 6.99 | F31: =IF(IF($E$5="Local prices",COUNTIFS(Offers!$B$7:$B$3000,$B31,Offers!$C$7:$C$3000,F$10,Offers!$AH$7:$AH$3000,"yes"),COUNTIFS(Offers!$B$7:$B$3000,$B31,Offers!$C$7:$C$3000,F$10,Offers!$AI$7:$AI$3000,"yes"))=0,"—",SUMIFS(Review!$O$7:$O$600,Review!$B$7:$B$600,$B31,Review!$C$7:$C$600,F$10)) -> 9.94 | G31: =IF(IF($E$5="Local prices",COUNTIFS(Offers!$B$7:$B$3000,$B31,Offers!$C$7:$C$3000,G$10,Offers!$AH$7:$AH$3000,"yes"),COUNTIFS(Offers!$B$7:$B$3000,$B31,Offers!$C$7:$C$3000,G$10,Offers!$AI$7:$AI$3000,"yes"))=0,"—",SUMIFS(Review!$O$7:$O$600,Review!$B$7:$B$600,$B31,Review!$C$7:$C$600,G$10)) -> 6.0333 | H31: =IF(IF($E$5="Local prices",COUNTIFS(Offers!$B$7:$B$3000,$B31,Offers!$C$7:$C$3000,H$10,Offers!$AH$7:$AH$3000,"yes"),COUNTIFS(Offers!$B$7:$B$3000,$B31,Offers!$C$7:$C$3000,H$10,Offers!$AI$7:$AI$3000,"yes"))=0,"—",SUMIFS(Review!$O$7:$O$600,Review!$B$7:$B$600,$B31,Review!$C$7:$C$600,H$10)) -> —
B32: GN 1/1 PC lid | C32: =IF(IF($E$5="Local prices",COUNTIFS(Offers!$B$7:$B$3000,$B32,Offers!$C$7:$C$3000,C$10,Offers!$AH$7:$AH$3000,"yes"),COUNTIFS(Offers!$B$7:$B$3000,$B32,Offers!$C$7:$C$3000,C$10,Offers!$AI$7:$AI$3000,"yes"))=0,"—",SUMIFS(Review!$O$7:$O$600,Review!$B$7:$B$600,$B32,Review!$C$7:$C$600,C$10)) -> — | D32: =IF(IF($E$5="Local prices",COUNTIFS(Offers!$B$7:$B$3000,$B32,Offers!$C$7:$C$3000,D$10,Offers!$AH$7:$AH$3000,"yes"),COUNTIFS(Offers!$B$7:$B$3000,$B32,Offers!$C$7:$C$3000,D$10,Offers!$AI$7:$AI$3000,"yes"))=0,"—",SUMIFS(Review!$O$7:$O$600,Review!$B$7:$B$600,$B32,Review!$C$7:$C$600,D$10)) -> — | E32: =IF(IF($E$5="Local prices",COUNTIFS(Offers!$B$7:$B$3000,$B32,Offers!$C$7:$C$3000,E$10,Offers!$AH$7:$AH$3000,"yes"),COUNTIFS(Offers!$B$7:$B$3000,$B32,Offers!$C$7:$C$3000,E$10,Offers!$AI$7:$AI$3000,"yes"))=0,"—",SUMIFS(Review!$O$7:$O$600,Review!$B$7:$B$600,$B32,Review!$C$7:$C$600,E$10)) -> 10.39 | F32: =IF(IF($E$5="Local prices",COUNTIFS(Offers!$B$7:$B$3000,$B32,Offers!$C$7:$C$3000,F$10,Offers!$AH$7:$AH$3000,"yes"),COUNTIFS(Offers!$B$7:$B$3000,$B32,Offers!$C$7:$C$3000,F$10,Offers!$AI$7:$AI$3000,"yes"))=0,"—",SUMIFS(Review!$O$7:$O$600,Review!$B$7:$B$600,$B32,Review!$C$7:$C$600,F$10)) -> 9.245 | G32: =IF(IF($E$5="Local prices",COUNTIFS(Offers!$B$7:$B$3000,$B32,Offers!$C$7:$C$3000,G$10,Offers!$AH$7:$AH$3000,"yes"),COUNTIFS(Offers!$B$7:$B$3000,$B32,Offers!$C$7:$C$3000,G$10,Offers!$AI$7:$AI$3000,"yes"))=0,"—",SUMIFS(Review!$O$7:$O$600,Review!$B$7:$B$600,$B32,Review!$C$7:$C$600,G$10)) -> 10.826816 | H32: =IF(IF($E$5="Local prices",COUNTIFS(Offers!$B$7:$B$3000,$B32,Offers!$C$7:$C$3000,H$10,Offers!$AH$7:$AH$3000,"yes"),COUNTIFS(Offers!$B$7:$B$3000,$B32,Offers!$C$7:$C$3000,H$10,Offers!$AI$7:$AI$3000,"yes"))=0,"—",SUMIFS(Review!$O$7:$O$600,Review!$B$7:$B$600,$B32,Review!$C$7:$C$600,H$10)) -> — | J32: Match scope
B33: GN 1/6 PP container, 100 mm | C33: =IF(IF($E$5="Local prices",COUNTIFS(Offers!$B$7:$B$3000,$B33,Offers!$C$7:$C$3000,C$10,Offers!$AH$7:$AH$3000,"yes"),COUNTIFS(Offers!$B$7:$B$3000,$B33,Offers!$C$7:$C$3000,C$10,Offers!$AI$7:$AI$3000,"yes"))=0,"—",SUMIFS(Review!$O$7:$O$600,Review!$B$7:$B$600,$B33,Review!$C$7:$C$600,C$10)) -> — | D33: =IF(IF($E$5="Local prices",COUNTIFS(Offers!$B$7:$B$3000,$B33,Offers!$C$7:$C$3000,D$10,Offers!$AH$7:$AH$3000,"yes"),COUNTIFS(Offers!$B$7:$B$3000,$B33,Offers!$C$7:$C$3000,D$10,Offers!$AI$7:$AI$3000,"yes"))=0,"—",SUMIFS(Review!$O$7:$O$600,Review!$B$7:$B$600,$B33,Review!$C$7:$C$600,D$10)) -> — | E33: =IF(IF($E$5="Local prices",COUNTIFS(Offers!$B$7:$B$3000,$B33,Offers!$C$7:$C$3000,E$10,Offers!$AH$7:$AH$3000,"yes"),COUNTIFS(Offers!$B$7:$B$3000,$B33,Offers!$C$7:$C$3000,E$10,Offers!$AI$7:$AI$3000,"yes"))=0,"—",SUMIFS(Review!$O$7:$O$600,Review!$B$7:$B$600,$B33,Review!$C$7:$C$600,E$10)) -> 3.44 | F33: =IF(IF($E$5="Local prices",COUNTIFS(Offers!$B$7:$B$3000,$B33,Offers!$C$7:$C$3000,F$10,Offers!$AH$7:$AH$3000,"yes"),COUNTIFS(Offers!$B$7:$B$3000,$B33,Offers!$C$7:$C$3000,F$10,Offers!$AI$7:$AI$3000,"yes"))=0,"—",SUMIFS(Review!$O$7:$O$600,Review!$B$7:$B$600,$B33,Review!$C$7:$C$600,F$10)) -> 2.315 | G33: =IF(IF($E$5="Local prices",COUNTIFS(Offers!$B$7:$B$3000,$B33,Offers!$C$7:$C$3000,G$10,Offers!$AH$7:$AH$3000,"yes"),COUNTIFS(Offers!$B$7:$B$3000,$B33,Offers!$C$7:$C$3000,G$10,Offers!$AI$7:$AI$3000,"yes"))=0,"—",SUMIFS(Review!$O$7:$O$600,Review!$B$7:$B$600,$B33,Review!$C$7:$C$600,G$10)) -> 3.125868 | H33: =IF(IF($E$5="Local prices",COUNTIFS(Offers!$B$7:$B$3000,$B33,Offers!$C$7:$C$3000,H$10,Offers!$AH$7:$AH$3000,"yes"),COUNTIFS(Offers!$B$7:$B$3000,$B33,Offers!$C$7:$C$3000,H$10,Offers!$AI$7:$AI$3000,"yes"))=0,"—",SUMIFS(Review!$O$7:$O$600,Review!$B$7:$B$600,$B33,Review!$C$7:$C$600,H$10)) -> — | J33: All mapped includes near matches and incomplete specifications. Check their notes before deciding.
B34: GN 1/9 PP container, 100 mm | C34: =IF(IF($E$5="Local prices",COUNTIFS(Offers!$B$7:$B$3000,$B34,Offers!$C$7:$C$3000,C$10,Offers!$AH$7:$AH$3000,"yes"),COUNTIFS(Offers!$B$7:$B$3000,$B34,Offers!$C$7:$C$3000,C$10,Offers!$AI$7:$AI$3000,"yes"))=0,"—",SUMIFS(Review!$O$7:$O$600,Review!$B$7:$B$600,$B34,Review!$C$7:$C$600,C$10)) -> — | D34: =IF(IF($E$5="Local prices",COUNTIFS(Offers!$B$7:$B$3000,$B34,Offers!$C$7:$C$3000,D$10,Offers!$AH$7:$AH$3000,"yes"),COUNTIFS(Offers!$B$7:$B$3000,$B34,Offers!$C$7:$C$3000,D$10,Offers!$AI$7:$AI$3000,"yes"))=0,"—",SUMIFS(Review!$O$7:$O$600,Review!$B$7:$B$600,$B34,Review!$C$7:$C$600,D$10)) -> — | E34: =IF(IF($E$5="Local prices",COUNTIFS(Offers!$B$7:$B$3000,$B34,Offers!$C$7:$C$3000,E$10,Offers!$AH$7:$AH$3000,"yes"),COUNTIFS(Offers!$B$7:$B$3000,$B34,Offers!$C$7:$C$3000,E$10,Offers!$AI$7:$AI$3000,"yes"))=0,"—",SUMIFS(Review!$O$7:$O$600,Review!$B$7:$B$600,$B34,Review!$C$7:$C$600,E$10)) -> 3.5 | F34: =IF(IF($E$5="Local prices",COUNTIFS(Offers!$B$7:$B$3000,$B34,Offers!$C$7:$C$3000,F$10,Offers!$AH$7:$AH$3000,"yes"),COUNTIFS(Offers!$B$7:$B$3000,$B34,Offers!$C$7:$C$3000,F$10,Offers!$AI$7:$AI$3000,"yes"))=0,"—",SUMIFS(Review!$O$7:$O$600,Review!$B$7:$B$600,$B34,Review!$C$7:$C$600,F$10)) -> 2.79 | G34: =IF(IF($E$5="Local prices",COUNTIFS(Offers!$B$7:$B$3000,$B34,Offers!$C$7:$C$3000,G$10,Offers!$AH$7:$AH$3000,"yes"),COUNTIFS(Offers!$B$7:$B$3000,$B34,Offers!$C$7:$C$3000,G$10,Offers!$AI$7:$AI$3000,"yes"))=0,"—",SUMIFS(Review!$O$7:$O$600,Review!$B$7:$B$600,$B34,Review!$C$7:$C$600,G$10)) -> 2.825135 | H34: =IF(IF($E$5="Local prices",COUNTIFS(Offers!$B$7:$B$3000,$B34,Offers!$C$7:$C$3000,H$10,Offers!$AH$7:$AH$3000,"yes"),COUNTIFS(Offers!$B$7:$B$3000,$B34,Offers!$C$7:$C$3000,H$10,Offers!$AI$7:$AI$3000,"yes"))=0,"—",SUMIFS(Review!$O$7:$O$600,Review!$B$7:$B$600,$B34,Review!$C$7:$C$600,H$10)) -> —
B35: Squeeze bottle 250 ml, PP, single tip | C35: =IF(IF($E$5="Local prices",COUNTIFS(Offers!$B$7:$B$3000,$B35,Offers!$C$7:$C$3000,C$10,Offers!$AH$7:$AH$3000,"yes"),COUNTIFS(Offers!$B$7:$B$3000,$B35,Offers!$C$7:$C$3000,C$10,Offers!$AI$7:$AI$3000,"yes"))=0,"—",SUMIFS(Review!$O$7:$O$600,Review!$B$7:$B$600,$B35,Review!$C$7:$C$600,C$10)) -> — | D35: =IF(IF($E$5="Local prices",COUNTIFS(Offers!$B$7:$B$3000,$B35,Offers!$C$7:$C$3000,D$10,Offers!$AH$7:$AH$3000,"yes"),COUNTIFS(Offers!$B$7:$B$3000,$B35,Offers!$C$7:$C$3000,D$10,Offers!$AI$7:$AI$3000,"yes"))=0,"—",SUMIFS(Review!$O$7:$O$600,Review!$B$7:$B$600,$B35,Review!$C$7:$C$600,D$10)) -> — | E35: =IF(IF($E$5="Local prices",COUNTIFS(Offers!$B$7:$B$3000,$B35,Offers!$C$7:$C$3000,E$10,Offers!$AH$7:$AH$3000,"yes"),COUNTIFS(Offers!$B$7:$B$3000,$B35,Offers!$C$7:$C$3000,E$10,Offers!$AI$7:$AI$3000,"yes"))=0,"—",SUMIFS(Review!$O$7:$O$600,Review!$B$7:$B$600,$B35,Review!$C$7:$C$600,E$10)) -> 1.175 | F35: =IF(IF($E$5="Local prices",COUNTIFS(Offers!$B$7:$B$3000,$B35,Offers!$C$7:$C$3000,F$10,Offers!$AH$7:$AH$3000,"yes"),COUNTIFS(Offers!$B$7:$B$3000,$B35,Offers!$C$7:$C$3000,F$10,Offers!$AI$7:$AI$3000,"yes"))=0,"—",SUMIFS(Review!$O$7:$O$600,Review!$B$7:$B$600,$B35,Review!$C$7:$C$600,F$10)) -> 1.08 | G35: =IF(IF($E$5="Local prices",COUNTIFS(Offers!$B$7:$B$3000,$B35,Offers!$C$7:$C$3000,G$10,Offers!$AH$7:$AH$3000,"yes"),COUNTIFS(Offers!$B$7:$B$3000,$B35,Offers!$C$7:$C$3000,G$10,Offers!$AI$7:$AI$3000,"yes"))=0,"—",SUMIFS(Review!$O$7:$O$600,Review!$B$7:$B$600,$B35,Review!$C$7:$C$600,G$10)) -> 1.7397095 | H35: =IF(IF($E$5="Local prices",COUNTIFS(Offers!$B$7:$B$3000,$B35,Offers!$C$7:$C$3000,H$10,Offers!$AH$7:$AH$3000,"yes"),COUNTIFS(Offers!$B$7:$B$3000,$B35,Offers!$C$7:$C$3000,H$10,Offers!$AI$7:$AI$3000,"yes"))=0,"—",SUMIFS(Review!$O$7:$O$600,Review!$B$7:$B$600,$B35,Review!$C$7:$C$600,H$10)) -> —
B36: Squeeze bottle 750 ml, PP, single tip | C36: =IF(IF($E$5="Local prices",COUNTIFS(Offers!$B$7:$B$3000,$B36,Offers!$C$7:$C$3000,C$10,Offers!$AH$7:$AH$3000,"yes"),COUNTIFS(Offers!$B$7:$B$3000,$B36,Offers!$C$7:$C$3000,C$10,Offers!$AI$7:$AI$3000,"yes"))=0,"—",SUMIFS(Review!$O$7:$O$600,Review!$B$7:$B$600,$B36,Review!$C$7:$C$600,C$10)) -> — | D36: =IF(IF($E$5="Local prices",COUNTIFS(Offers!$B$7:$B$3000,$B36,Offers!$C$7:$C$3000,D$10,Offers!$AH$7:$AH$3000,"yes"),COUNTIFS(Offers!$B$7:$B$3000,$B36,Offers!$C$7:$C$3000,D$10,Offers!$AI$7:$AI$3000,"yes"))=0,"—",SUMIFS(Review!$O$7:$O$600,Review!$B$7:$B$600,$B36,Review!$C$7:$C$600,D$10)) -> — | E36: =IF(IF($E$5="Local prices",COUNTIFS(Offers!$B$7:$B$3000,$B36,Offers!$C$7:$C$3000,E$10,Offers!$AH$7:$AH$3000,"yes"),COUNTIFS(Offers!$B$7:$B$3000,$B36,Offers!$C$7:$C$3000,E$10,Offers!$AI$7:$AI$3000,"yes"))=0,"—",SUMIFS(Review!$O$7:$O$600,Review!$B$7:$B$600,$B36,Review!$C$7:$C$600,E$10)) -> 1.73 | F36: =IF(IF($E$5="Local prices",COUNTIFS(Offers!$B$7:$B$3000,$B36,Offers!$C$7:$C$3000,F$10,Offers!$AH$7:$AH$3000,"yes"),COUNTIFS(Offers!$B$7:$B$3000,$B36,Offers!$C$7:$C$3000,F$10,Offers!$AI$7:$AI$3000,"yes"))=0,"—",SUMIFS(Review!$O$7:$O$600,Review!$B$7:$B$600,$B36,Review!$C$7:$C$600,F$10)) -> 1.08 | G36: =IF(IF($E$5="Local prices",COUNTIFS(Offers!$B$7:$B$3000,$B36,Offers!$C$7:$C$3000,G$10,Offers!$AH$7:$AH$3000,"yes"),COUNTIFS(Offers!$B$7:$B$3000,$B36,Offers!$C$7:$C$3000,G$10,Offers!$AI$7:$AI$3000,"yes"))=0,"—",SUMIFS(Review!$O$7:$O$600,Review!$B$7:$B$600,$B36,Review!$C$7:$C$600,G$10)) -> 1.555871 | H36: =IF(IF($E$5="Local prices",COUNTIFS(Offers!$B$7:$B$3000,$B36,Offers!$C$7:$C$3000,H$10,Offers!$AH$7:$AH$3000,"yes"),COUNTIFS(Offers!$B$7:$B$3000,$B36,Offers!$C$7:$C$3000,H$10,Offers!$AI$7:$AI$3000,"yes"))=0,"—",SUMIFS(Review!$O$7:$O$600,Review!$B$7:$B$600,$B36,Review!$C$7:$C$600,H$10)) -> — | J36: Additional variants
B37: Red PE cutting board 400 × 300 × 20 mm | C37: =IF(IF($E$5="Local prices",COUNTIFS(Offers!$B$7:$B$3000,$B37,Offers!$C$7:$C$3000,C$10,Offers!$AH$7:$AH$3000,"yes"),COUNTIFS(Offers!$B$7:$B$3000,$B37,Offers!$C$7:$C$3000,C$10,Offers!$AI$7:$AI$3000,"yes"))=0,"—",SUMIFS(Review!$O$7:$O$600,Review!$B$7:$B$600,$B37,Review!$C$7:$C$600,C$10)) -> — | D37: =IF(IF($E$5="Local prices",COUNTIFS(Offers!$B$7:$B$3000,$B37,Offers!$C$7:$C$3000,D$10,Offers!$AH$7:$AH$3000,"yes"),COUNTIFS(Offers!$B$7:$B$3000,$B37,Offers!$C$7:$C$3000,D$10,Offers!$AI$7:$AI$3000,"yes"))=0,"—",SUMIFS(Review!$O$7:$O$600,Review!$B$7:$B$600,$B37,Review!$C$7:$C$600,D$10)) -> — | E37: =IF(IF($E$5="Local prices",COUNTIFS(Offers!$B$7:$B$3000,$B37,Offers!$C$7:$C$3000,E$10,Offers!$AH$7:$AH$3000,"yes"),COUNTIFS(Offers!$B$7:$B$3000,$B37,Offers!$C$7:$C$3000,E$10,Offers!$AI$7:$AI$3000,"yes"))=0,"—",SUMIFS(Review!$O$7:$O$600,Review!$B$7:$B$600,$B37,Review!$C$7:$C$600,E$10)) -> 20.96 | F37: =IF(IF($E$5="Local prices",COUNTIFS(Offers!$B$7:$B$3000,$B37,Offers!$C$7:$C$3000,F$10,Offers!$AH$7:$AH$3000,"yes"),COUNTIFS(Offers!$B$7:$B$3000,$B37,Offers!$C$7:$C$3000,F$10,Offers!$AI$7:$AI$3000,"yes"))=0,"—",SUMIFS(Review!$O$7:$O$600,Review!$B$7:$B$600,$B37,Review!$C$7:$C$600,F$10)) -> 6.58 | G37: =IF(IF($E$5="Local prices",COUNTIFS(Offers!$B$7:$B$3000,$B37,Offers!$C$7:$C$3000,G$10,Offers!$AH$7:$AH$3000,"yes"),COUNTIFS(Offers!$B$7:$B$3000,$B37,Offers!$C$7:$C$3000,G$10,Offers!$AI$7:$AI$3000,"yes"))=0,"—",SUMIFS(Review!$O$7:$O$600,Review!$B$7:$B$600,$B37,Review!$C$7:$C$600,G$10)) -> 36.612515 | H37: =IF(IF($E$5="Local prices",COUNTIFS(Offers!$B$7:$B$3000,$B37,Offers!$C$7:$C$3000,H$10,Offers!$AH$7:$AH$3000,"yes"),COUNTIFS(Offers!$B$7:$B$3000,$B37,Offers!$C$7:$C$3000,H$10,Offers!$AI$7:$AI$3000,"yes"))=0,"—",SUMIFS(Review!$O$7:$O$600,Review!$B$7:$B$600,$B37,Review!$C$7:$C$600,H$10)) -> — | J37: Additional variants have research for Austria and Czechia (basket additions) or for AT/DE/CZ/SK/RO (GN expansion of 2 Oct 2026). A dash in the other markets means no offer has been recorded.
B38: PP dough box 600 × 400 × 75 mm, no lid | C38: =IF(IF($E$5="Local prices",COUNTIFS(Offers!$B$7:$B$3000,$B38,Offers!$C$7:$C$3000,C$10,Offers!$AH$7:$AH$3000,"yes"),COUNTIFS(Offers!$B$7:$B$3000,$B38,Offers!$C$7:$C$3000,C$10,Offers!$AI$7:$AI$3000,"yes"))=0,"—",SUMIFS(Review!$O$7:$O$600,Review!$B$7:$B$600,$B38,Review!$C$7:$C$600,C$10)) -> — | D38: =IF(IF($E$5="Local prices",COUNTIFS(Offers!$B$7:$B$3000,$B38,Offers!$C$7:$C$3000,D$10,Offers!$AH$7:$AH$3000,"yes"),COUNTIFS(Offers!$B$7:$B$3000,$B38,Offers!$C$7:$C$3000,D$10,Offers!$AI$7:$AI$3000,"yes"))=0,"—",SUMIFS(Review!$O$7:$O$600,Review!$B$7:$B$600,$B38,Review!$C$7:$C$600,D$10)) -> — | E38: =IF(IF($E$5="Local prices",COUNTIFS(Offers!$B$7:$B$3000,$B38,Offers!$C$7:$C$3000,E$10,Offers!$AH$7:$AH$3000,"yes"),COUNTIFS(Offers!$B$7:$B$3000,$B38,Offers!$C$7:$C$3000,E$10,Offers!$AI$7:$AI$3000,"yes"))=0,"—",SUMIFS(Review!$O$7:$O$600,Review!$B$7:$B$600,$B38,Review!$C$7:$C$600,E$10)) -> 21.46 | F38: =IF(IF($E$5="Local prices",COUNTIFS(Offers!$B$7:$B$3000,$B38,Offers!$C$7:$C$3000,F$10,Offers!$AH$7:$AH$3000,"yes"),COUNTIFS(Offers!$B$7:$B$3000,$B38,Offers!$C$7:$C$3000,F$10,Offers!$AI$7:$AI$3000,"yes"))=0,"—",SUMIFS(Review!$O$7:$O$600,Review!$B$7:$B$600,$B38,Review!$C$7:$C$600,F$10)) -> 9.4 | G38: =IF(IF($E$5="Local prices",COUNTIFS(Offers!$B$7:$B$3000,$B38,Offers!$C$7:$C$3000,G$10,Offers!$AH$7:$AH$3000,"yes"),COUNTIFS(Offers!$B$7:$B$3000,$B38,Offers!$C$7:$C$3000,G$10,Offers!$AI$7:$AI$3000,"yes"))=0,"—",SUMIFS(Review!$O$7:$O$600,Review!$B$7:$B$600,$B38,Review!$C$7:$C$600,G$10)) -> 10.557609 | H38: =IF(IF($E$5="Local prices",COUNTIFS(Offers!$B$7:$B$3000,$B38,Offers!$C$7:$C$3000,H$10,Offers!$AH$7:$AH$3000,"yes"),COUNTIFS(Offers!$B$7:$B$3000,$B38,Offers!$C$7:$C$3000,H$10,Offers!$AI$7:$AI$3000,"yes"))=0,"—",SUMIFS(Review!$O$7:$O$600,Review!$B$7:$B$600,$B38,Review!$C$7:$C$600,H$10)) -> —
B39: GN 1/1 PC container, 100 mm | C39: =IF(IF($E$5="Local prices",COUNTIFS(Offers!$B$7:$B$3000,$B39,Offers!$C$7:$C$3000,C$10,Offers!$AH$7:$AH$3000,"yes"),COUNTIFS(Offers!$B$7:$B$3000,$B39,Offers!$C$7:$C$3000,C$10,Offers!$AI$7:$AI$3000,"yes"))=0,"—",SUMIFS(Review!$O$7:$O$600,Review!$B$7:$B$600,$B39,Review!$C$7:$C$600,C$10)) -> — | D39: =IF(IF($E$5="Local prices",COUNTIFS(Offers!$B$7:$B$3000,$B39,Offers!$C$7:$C$3000,D$10,Offers!$AH$7:$AH$3000,"yes"),COUNTIFS(Offers!$B$7:$B$3000,$B39,Offers!$C$7:$C$3000,D$10,Offers!$AI$7:$AI$3000,"yes"))=0,"—",SUMIFS(Review!$O$7:$O$600,Review!$B$7:$B$600,$B39,Review!$C$7:$C$600,D$10)) -> — | E39: =IF(IF($E$5="Local prices",COUNTIFS(Offers!$B$7:$B$3000,$B39,Offers!$C$7:$C$3000,E$10,Offers!$AH$7:$AH$3000,"yes"),COUNTIFS(Offers!$B$7:$B$3000,$B39,Offers!$C$7:$C$3000,E$10,Offers!$AI$7:$AI$3000,"yes"))=0,"—",SUMIFS(Review!$O$7:$O$600,Review!$B$7:$B$600,$B39,Review!$C$7:$C$600,E$10)) -> 17.545 | F39: =IF(IF($E$5="Local prices",COUNTIFS(Offers!$B$7:$B$3000,$B39,Offers!$C$7:$C$3000,F$10,Offers!$AH$7:$AH$3000,"yes"),COUNTIFS(Offers!$B$7:$B$3000,$B39,Offers!$C$7:$C$3000,F$10,Offers!$AI$7:$AI$3000,"yes"))=0,"—",SUMIFS(Review!$O$7:$O$600,Review!$B$7:$B$600,$B39,Review!$C$7:$C$600,F$10)) -> 13.62 | G39: =IF(IF($E$5="Local prices",COUNTIFS(Offers!$B$7:$B$3000,$B39,Offers!$C$7:$C$3000,G$10,Offers!$AH$7:$AH$3000,"yes"),COUNTIFS(Offers!$B$7:$B$3000,$B39,Offers!$C$7:$C$3000,G$10,Offers!$AI$7:$AI$3000,"yes"))=0,"—",SUMIFS(Review!$O$7:$O$600,Review!$B$7:$B$600,$B39,Review!$C$7:$C$600,G$10)) -> 11.83281 | H39: =IF(IF($E$5="Local prices",COUNTIFS(Offers!$B$7:$B$3000,$B39,Offers!$C$7:$C$3000,H$10,Offers!$AH$7:$AH$3000,"yes"),COUNTIFS(Offers!$B$7:$B$3000,$B39,Offers!$C$7:$C$3000,H$10,Offers!$AI$7:$AI$3000,"yes"))=0,"—",SUMIFS(Review!$O$7:$O$600,Review!$B$7:$B$600,$B39,Review!$C$7:$C$600,H$10)) -> —
B40: GN 1/6 PC container, 100 mm | C40: =IF(IF($E$5="Local prices",COUNTIFS(Offers!$B$7:$B$3000,$B40,Offers!$C$7:$C$3000,C$10,Offers!$AH$7:$AH$3000,"yes"),COUNTIFS(Offers!$B$7:$B$3000,$B40,Offers!$C$7:$C$3000,C$10,Offers!$AI$7:$AI$3000,"yes"))=0,"—",SUMIFS(Review!$O$7:$O$600,Review!$B$7:$B$600,$B40,Review!$C$7:$C$600,C$10)) -> — | D40: =IF(IF($E$5="Local prices",COUNTIFS(Offers!$B$7:$B$3000,$B40,Offers!$C$7:$C$3000,D$10,Offers!$AH$7:$AH$3000,"yes"),COUNTIFS(Offers!$B$7:$B$3000,$B40,Offers!$C$7:$C$3000,D$10,Offers!$AI$7:$AI$3000,"yes"))=0,"—",SUMIFS(Review!$O$7:$O$600,Review!$B$7:$B$600,$B40,Review!$C$7:$C$600,D$10)) -> — | E40: =IF(IF($E$5="Local prices",COUNTIFS(Offers!$B$7:$B$3000,$B40,Offers!$C$7:$C$3000,E$10,Offers!$AH$7:$AH$3000,"yes"),COUNTIFS(Offers!$B$7:$B$3000,$B40,Offers!$C$7:$C$3000,E$10,Offers!$AI$7:$AI$3000,"yes"))=0,"—",SUMIFS(Review!$O$7:$O$600,Review!$B$7:$B$600,$B40,Review!$C$7:$C$600,E$10)) -> 4.13 | F40: =IF(IF($E$5="Local prices",COUNTIFS(Offers!$B$7:$B$3000,$B40,Offers!$C$7:$C$3000,F$10,Offers!$AH$7:$AH$3000,"yes"),COUNTIFS(Offers!$B$7:$B$3000,$B40,Offers!$C$7:$C$3000,F$10,Offers!$AI$7:$AI$3000,"yes"))=0,"—",SUMIFS(Review!$O$7:$O$600,Review!$B$7:$B$600,$B40,Review!$C$7:$C$600,F$10)) -> 3.75 | G40: =IF(IF($E$5="Local prices",COUNTIFS(Offers!$B$7:$B$3000,$B40,Offers!$C$7:$C$3000,G$10,Offers!$AH$7:$AH$3000,"yes"),COUNTIFS(Offers!$B$7:$B$3000,$B40,Offers!$C$7:$C$3000,G$10,Offers!$AI$7:$AI$3000,"yes"))=0,"—",SUMIFS(Review!$O$7:$O$600,Review!$B$7:$B$600,$B40,Review!$C$7:$C$600,G$10)) -> 3.9164965 | H40: =IF(IF($E$5="Local prices",COUNTIFS(Offers!$B$7:$B$3000,$B40,Offers!$C$7:$C$3000,H$10,Offers!$AH$7:$AH$3000,"yes"),COUNTIFS(Offers!$B$7:$B$3000,$B40,Offers!$C$7:$C$3000,H$10,Offers!$AI$7:$AI$3000,"yes"))=0,"—",SUMIFS(Review!$O$7:$O$600,Review!$B$7:$B$600,$B40,Review!$C$7:$C$600,H$10)) -> —
