Workbook

Sheet Compare
B2: YES Gastro market comparison
B3: Original benchmark basket plus Austria and Czechia additions. Net prices per piece.
B5: Statistic | C5: Median | D5: View | E5: Net per piece EUR | G5: Match | H5: EXACT + CLOSE | J5: Product detail
J6: GN 1/1 PC container, 65 mm
B7: =IF(E5="Local prices","Local net prices per piece. Currency differs by country.","EUR net prices per piece. Erste Bank mid-rates published 30 Sep 2026 at 18:00 CEST.")
B8: A dash means no qualifying price. Green marks the lowest available EUR price for each product.
J9: Net price per piece in EUR
B10: Product | C10: Hungary | D10: Romania | E10: Austria | F10: Germany | G10: Czech | H10: Slovakia
C11: =IF($E$5="Local prices","HUF net/pc","EUR net/pc") | D11: =IF($E$5="Local prices","RON net/pc","EUR net/pc") | E11: =IF($E$5="Local prices","EUR net/pc","EUR net/pc") | F11: =IF($E$5="Local prices","EUR net/pc","EUR net/pc") | G11: =IF($E$5="Local prices","CZK net/pc","EUR net/pc") | H11: =IF($E$5="Local prices","EUR net/pc","EUR net/pc") | J11: Market | K11: Minimum | L11: Median | M11: Maximum
B12: GN 1/1 PC container, 65 mm | C12: =IF(IF($E$5="Local prices",COUNTIFS('Offers'!$B$7:$B$608,$B12,'Offers'!$C$7:$C$608,C$10,'Offers'!$AH$7:$AH$608,"yes"),COUNTIFS('Offers'!$B$7:$B$608,$B12,'Offers'!$C$7:$C$608,C$10,'Offers'!$AI$7:$AI$608,"yes"))=0,"—",SUMIFS('Review'!$O$7:$O$210,'Review'!$B$7:$B$210,$B12,'Review'!$C$7:$C$210,C$10)) | D12: =IF(IF($E$5="Local prices",COUNTIFS('Offers'!$B$7:$B$608,$B12,'Offers'!$C$7:$C$608,D$10,'Offers'!$AH$7:$AH$608,"yes"),COUNTIFS('Offers'!$B$7:$B$608,$B12,'Offers'!$C$7:$C$608,D$10,'Offers'!$AI$7:$AI$608,"yes"))=0,"—",SUMIFS('Review'!$O$7:$O$210,'Review'!$B$7:$B$210,$B12,'Review'!$C$7:$C$210,D$10)) | E12: =IF(IF($E$5="Local prices",COUNTIFS('Offers'!$B$7:$B$608,$B12,'Offers'!$C$7:$C$608,E$10,'Offers'!$AH$7:$AH$608,"yes"),COUNTIFS('Offers'!$B$7:$B$608,$B12,'Offers'!$C$7:$C$608,E$10,'Offers'!$AI$7:$AI$608,"yes"))=0,"—",SUMIFS('Review'!$O$7:$O$210,'Review'!$B$7:$B$210,$B12,'Review'!$C$7:$C$210,E$10)) | F12: =IF(IF($E$5="Local prices",COUNTIFS('Offers'!$B$7:$B$608,$B12,'Offers'!$C$7:$C$608,F$10,'Offers'!$AH$7:$AH$608,"yes"),COUNTIFS('Offers'!$B$7:$B$608,$B12,'Offers'!$C$7:$C$608,F$10,'Offers'!$AI$7:$AI$608,"yes"))=0,"—",SUMIFS('Review'!$O$7:$O$210,'Review'!$B$7:$B$210,$B12,'Review'!$C$7:$C$210,F$10)) | G12: =IF(IF($E$5="Local prices",COUNTIFS('Offers'!$B$7:$B$608,$B12,'Offers'!$C$7:$C$608,G$10,'Offers'!$AH$7:$AH$608,"yes"),COUNTIFS('Offers'!$B$7:$B$608,$B12,'Offers'!$C$7:$C$608,G$10,'Offers'!$AI$7:$AI$608,"yes"))=0,"—",SUMIFS('Review'!$O$7:$O$210,'Review'!$B$7:$B$210,$B12,'Review'!$C$7:$C$210,G$10)) | H12: =IF(IF($E$5="Local prices",COUNTIFS('Offers'!$B$7:$B$608,$B12,'Offers'!$C$7:$C$608,H$10,'Offers'!$AH$7:$AH$608,"yes"),COUNTIFS('Offers'!$B$7:$B$608,$B12,'Offers'!$C$7:$C$608,H$10,'Offers'!$AI$7:$AI$608,"yes"))=0,"—",SUMIFS('Review'!$O$7:$O$210,'Review'!$B$7:$B$210,$B12,'Review'!$C$7:$C$210,H$10)) | J12: Hungary | K12: =IF(COUNTIFS('Offers'!$B$7:$B$608,$J$6,'Offers'!$C$7:$C$608,$J12,'Offers'!$AI$7:$AI$608,"yes")=0,"—",SUMIFS('Review'!$I$7:$I$210,'Review'!$B$7:$B$210,$J$6,'Review'!$C$7:$C$210,$J12)) | L12: =IF(COUNTIFS('Offers'!$B$7:$B$608,$J$6,'Offers'!$C$7:$C$608,$J12,'Offers'!$AI$7:$AI$608,"yes")=0,"—",SUMIFS('Review'!$J$7:$J$210,'Review'!$B$7:$B$210,$J$6,'Review'!$C$7:$C$210,$J12)) | M12: =IF(COUNTIFS('Offers'!$B$7:$B$608,$J$6,'Offers'!$C$7:$C$608,$J12,'Offers'!$AI$7:$AI$608,"yes")=0,"—",SUMIFS('Review'!$K$7:$K$210,'Review'!$B$7:$B$210,$J$6,'Review'!$C$7:$C$210,$J12))
B13: GN 1/2 PC container, 150 mm | C13: =IF(IF($E$5="Local prices",COUNTIFS('Offers'!$B$7:$B$608,$B13,'Offers'!$C$7:$C$608,C$10,'Offers'!$AH$7:$AH$608,"yes"),COUNTIFS('Offers'!$B$7:$B$608,$B13,'Offers'!$C$7:$C$608,C$10,'Offers'!$AI$7:$AI$608,"yes"))=0,"—",SUMIFS('Review'!$O$7:$O$210,'Review'!$B$7:$B$210,$B13,'Review'!$C$7:$C$210,C$10)) | D13: =IF(IF($E$5="Local prices",COUNTIFS('Offers'!$B$7:$B$608,$B13,'Offers'!$C$7:$C$608,D$10,'Offers'!$AH$7:$AH$608,"yes"),COUNTIFS('Offers'!$B$7:$B$608,$B13,'Offers'!$C$7:$C$608,D$10,'Offers'!$AI$7:$AI$608,"yes"))=0,"—",SUMIFS('Review'!$O$7:$O$210,'Review'!$B$7:$B$210,$B13,'Review'!$C$7:$C$210,D$10)) | E13: =IF(IF($E$5="Local prices",COUNTIFS('Offers'!$B$7:$B$608,$B13,'Offers'!$C$7:$C$608,E$10,'Offers'!$AH$7:$AH$608,"yes"),COUNTIFS('Offers'!$B$7:$B$608,$B13,'Offers'!$C$7:$C$608,E$10,'Offers'!$AI$7:$AI$608,"yes"))=0,"—",SUMIFS('Review'!$O$7:$O$210,'Review'!$B$7:$B$210,$B13,'Review'!$C$7:$C$210,E$10)) | F13: =IF(IF($E$5="Local prices",COUNTIFS('Offers'!$B$7:$B$608,$B13,'Offers'!$C$7:$C$608,F$10,'Offers'!$AH$7:$AH$608,"yes"),COUNTIFS('Offers'!$B$7:$B$608,$B13,'Offers'!$C$7:$C$608,F$10,'Offers'!$AI$7:$AI$608,"yes"))=0,"—",SUMIFS('Review'!$O$7:$O$210,'Review'!$B$7:$B$210,$B13,'Review'!$C$7:$C$210,F$10)) | G13: =IF(IF($E$5="Local prices",COUNTIFS('Offers'!$B$7:$B$608,$B13,'Offers'!$C$7:$C$608,G$10,'Offers'!$AH$7:$AH$608,"yes"),COUNTIFS('Offers'!$B$7:$B$608,$B13,'Offers'!$C$7:$C$608,G$10,'Offers'!$AI$7:$AI$608,"yes"))=0,"—",SUMIFS('Review'!$O$7:$O$210,'Review'!$B$7:$B$210,$B13,'Review'!$C$7:$C$210,G$10)) | H13: =IF(IF($E$5="Local prices",COUNTIFS('Offers'!$B$7:$B$608,$B13,'Offers'!$C$7:$C$608,H$10,'Offers'!$AH$7:$AH$608,"yes"),COUNTIFS('Offers'!$B$7:$B$608,$B13,'Offers'!$C$7:$C$608,H$10,'Offers'!$AI$7:$AI$608,"yes"))=0,"—",SUMIFS('Review'!$O$7:$O$210,'Review'!$B$7:$B$210,$B13,'Review'!$C$7:$C$210,H$10)) | J13: Romania | K13: =IF(COUNTIFS('Offers'!$B$7:$B$608,$J$6,'Offers'!$C$7:$C$608,$J13,'Offers'!$AI$7:$AI$608,"yes")=0,"—",SUMIFS('Review'!$I$7:$I$210,'Review'!$B$7:$B$210,$J$6,'Review'!$C$7:$C$210,$J13)) | L13: =IF(COUNTIFS('Offers'!$B$7:$B$608,$J$6,'Offers'!$C$7:$C$608,$J13,'Offers'!$AI$7:$AI$608,"yes")=0,"—",SUMIFS('Review'!$J$7:$J$210,'Review'!$B$7:$B$210,$J$6,'Review'!$C$7:$C$210,$J13)) | M13: =IF(COUNTIFS('Offers'!$B$7:$B$608,$J$6,'Offers'!$C$7:$C$608,$J13,'Offers'!$AI$7:$AI$608,"yes")=0,"—",SUMIFS('Review'!$K$7:$K$210,'Review'!$B$7:$B$210,$J$6,'Review'!$C$7:$C$210,$J13))
B14: GN 1/3 PP container, 100 mm | C14: =IF(IF($E$5="Local prices",COUNTIFS('Offers'!$B$7:$B$608,$B14,'Offers'!$C$7:$C$608,C$10,'Offers'!$AH$7:$AH$608,"yes"),COUNTIFS('Offers'!$B$7:$B$608,$B14,'Offers'!$C$7:$C$608,C$10,'Offers'!$AI$7:$AI$608,"yes"))=0,"—",SUMIFS('Review'!$O$7:$O$210,'Review'!$B$7:$B$210,$B14,'Review'!$C$7:$C$210,C$10)) | D14: =IF(IF($E$5="Local prices",COUNTIFS('Offers'!$B$7:$B$608,$B14,'Offers'!$C$7:$C$608,D$10,'Offers'!$AH$7:$AH$608,"yes"),COUNTIFS('Offers'!$B$7:$B$608,$B14,'Offers'!$C$7:$C$608,D$10,'Offers'!$AI$7:$AI$608,"yes"))=0,"—",SUMIFS('Review'!$O$7:$O$210,'Review'!$B$7:$B$210,$B14,'Review'!$C$7:$C$210,D$10)) | E14: =IF(IF($E$5="Local prices",COUNTIFS('Offers'!$B$7:$B$608,$B14,'Offers'!$C$7:$C$608,E$10,'Offers'!$AH$7:$AH$608,"yes"),COUNTIFS('Offers'!$B$7:$B$608,$B14,'Offers'!$C$7:$C$608,E$10,'Offers'!$AI$7:$AI$608,"yes"))=0,"—",SUMIFS('Review'!$O$7:$O$210,'Review'!$B$7:$B$210,$B14,'Review'!$C$7:$C$210,E$10)) | F14: =IF(IF($E$5="Local prices",COUNTIFS('Offers'!$B$7:$B$608,$B14,'Offers'!$C$7:$C$608,F$10,'Offers'!$AH$7:$AH$608,"yes"),COUNTIFS('Offers'!$B$7:$B$608,$B14,'Offers'!$C$7:$C$608,F$10,'Offers'!$AI$7:$AI$608,"yes"))=0,"—",SUMIFS('Review'!$O$7:$O$210,'Review'!$B$7:$B$210,$B14,'Review'!$C$7:$C$210,F$10)) | G14: =IF(IF($E$5="Local prices",COUNTIFS('Offers'!$B$7:$B$608,$B14,'Offers'!$C$7:$C$608,G$10,'Offers'!$AH$7:$AH$608,"yes"),COUNTIFS('Offers'!$B$7:$B$608,$B14,'Offers'!$C$7:$C$608,G$10,'Offers'!$AI$7:$AI$608,"yes"))=0,"—",SUMIFS('Review'!$O$7:$O$210,'Review'!$B$7:$B$210,$B14,'Review'!$C$7:$C$210,G$10)) | H14: =IF(IF($E$5="Local prices",COUNTIFS('Offers'!$B$7:$B$608,$B14,'Offers'!$C$7:$C$608,H$10,'Offers'!$AH$7:$AH$608,"yes"),COUNTIFS('Offers'!$B$7:$B$608,$B14,'Offers'!$C$7:$C$608,H$10,'Offers'!$AI$7:$AI$608,"yes"))=0,"—",SUMIFS('Review'!$O$7:$O$210,'Review'!$B$7:$B$210,$B14,'Review'!$C$7:$C$210,H$10)) | J14: Austria | K14: =IF(COUNTIFS('Offers'!$B$7:$B$608,$J$6,'Offers'!$C$7:$C$608,$J14,'Offers'!$AI$7:$AI$608,"yes")=0,"—",SUMIFS('Review'!$I$7:$I$210,'Review'!$B$7:$B$210,$J$6,'Review'!$C$7:$C$210,$J14)) | L14: =IF(COUNTIFS('Offers'!$B$7:$B$608,$J$6,'Offers'!$C$7:$C$608,$J14,'Offers'!$AI$7:$AI$608,"yes")=0,"—",SUMIFS('Review'!$J$7:$J$210,'Review'!$B$7:$B$210,$J$6,'Review'!$C$7:$C$210,$J14)) | M14: =IF(COUNTIFS('Offers'!$B$7:$B$608,$J$6,'Offers'!$C$7:$C$608,$J14,'Offers'!$AI$7:$AI$608,"yes")=0,"—",SUMIFS('Review'!$K$7:$K$210,'Review'!$B$7:$B$210,$J$6,'Review'!$C$7:$C$210,$J14))
B15: GN 1/1 PP lid | C15: =IF(IF($E$5="Local prices",COUNTIFS('Offers'!$B$7:$B$608,$B15,'Offers'!$C$7:$C$608,C$10,'Offers'!$AH$7:$AH$608,"yes"),COUNTIFS('Offers'!$B$7:$B$608,$B15,'Offers'!$C$7:$C$608,C$10,'Offers'!$AI$7:$AI$608,"yes"))=0,"—",SUMIFS('Review'!$O$7:$O$210,'Review'!$B$7:$B$210,$B15,'Review'!$C$7:$C$210,C$10)) | D15: =IF(IF($E$5="Local prices",COUNTIFS('Offers'!$B$7:$B$608,$B15,'Offers'!$C$7:$C$608,D$10,'Offers'!$AH$7:$AH$608,"yes"),COUNTIFS('Offers'!$B$7:$B$608,$B15,'Offers'!$C$7:$C$608,D$10,'Offers'!$AI$7:$AI$608,"yes"))=0,"—",SUMIFS('Review'!$O$7:$O$210,'Review'!$B$7:$B$210,$B15,'Review'!$C$7:$C$210,D$10)) | E15: =IF(IF($E$5="Local prices",COUNTIFS('Offers'!$B$7:$B$608,$B15,'Offers'!$C$7:$C$608,E$10,'Offers'!$AH$7:$AH$608,"yes"),COUNTIFS('Offers'!$B$7:$B$608,$B15,'Offers'!$C$7:$C$608,E$10,'Offers'!$AI$7:$AI$608,"yes"))=0,"—",SUMIFS('Review'!$O$7:$O$210,'Review'!$B$7:$B$210,$B15,'Review'!$C$7:$C$210,E$10)) | F15: =IF(IF($E$5="Local prices",COUNTIFS('Offers'!$B$7:$B$608,$B15,'Offers'!$C$7:$C$608,F$10,'Offers'!$AH$7:$AH$608,"yes"),COUNTIFS('Offers'!$B$7:$B$608,$B15,'Offers'!$C$7:$C$608,F$10,'Offers'!$AI$7:$AI$608,"yes"))=0,"—",SUMIFS('Review'!$O$7:$O$210,'Review'!$B$7:$B$210,$B15,'Review'!$C$7:$C$210,F$10)) | G15: =IF(IF($E$5="Local prices",COUNTIFS('Offers'!$B$7:$B$608,$B15,'Offers'!$C$7:$C$608,G$10,'Offers'!$AH$7:$AH$608,"yes"),COUNTIFS('Offers'!$B$7:$B$608,$B15,'Offers'!$C$7:$C$608,G$10,'Offers'!$AI$7:$AI$608,"yes"))=0,"—",SUMIFS('Review'!$O$7:$O$210,'Review'!$B$7:$B$210,$B15,'Review'!$C$7:$C$210,G$10)) | H15: =IF(IF($E$5="Local prices",COUNTIFS('Offers'!$B$7:$B$608,$B15,'Offers'!$C$7:$C$608,H$10,'Offers'!$AH$7:$AH$608,"yes"),COUNTIFS('Offers'!$B$7:$B$608,$B15,'Offers'!$C$7:$C$608,H$10,'Offers'!$AI$7:$AI$608,"yes"))=0,"—",SUMIFS('Review'!$O$7:$O$210,'Review'!$B$7:$B$210,$B15,'Review'!$C$7:$C$210,H$10)) | J15: Germany | K15: =IF(COUNTIFS('Offers'!$B$7:$B$608,$J$6,'Offers'!$C$7:$C$608,$J15,'Offers'!$AI$7:$AI$608,"yes")=0,"—",SUMIFS('Review'!$I$7:$I$210,'Review'!$B$7:$B$210,$J$6,'Review'!$C$7:$C$210,$J15)) | L15: =IF(COUNTIFS('Offers'!$B$7:$B$608,$J$6,'Offers'!$C$7:$C$608,$J15,'Offers'!$AI$7:$AI$608,"yes")=0,"—",SUMIFS('Review'!$J$7:$J$210,'Review'!$B$7:$B$210,$J$6,'Review'!$C$7:$C$210,$J15)) | M15: =IF(COUNTIFS('Offers'!$B$7:$B$608,$J$6,'Offers'!$C$7:$C$608,$J15,'Offers'!$AI$7:$AI$608,"yes")=0,"—",SUMIFS('Review'!$K$7:$K$210,'Review'!$B$7:$B$210,$J$6,'Review'!$C$7:$C$210,$J15))
B16: Squeeze bottle 500 ml, PP, single tip | C16: =IF(IF($E$5="Local prices",COUNTIFS('Offers'!$B$7:$B$608,$B16,'Offers'!$C$7:$C$608,C$10,'Offers'!$AH$7:$AH$608,"yes"),COUNTIFS('Offers'!$B$7:$B$608,$B16,'Offers'!$C$7:$C$608,C$10,'Offers'!$AI$7:$AI$608,"yes"))=0,"—",SUMIFS('Review'!$O$7:$O$210,'Review'!$B$7:$B$210,$B16,'Review'!$C$7:$C$210,C$10)) | D16: =IF(IF($E$5="Local prices",COUNTIFS('Offers'!$B$7:$B$608,$B16,'Offers'!$C$7:$C$608,D$10,'Offers'!$AH$7:$AH$608,"yes"),COUNTIFS('Offers'!$B$7:$B$608,$B16,'Offers'!$C$7:$C$608,D$10,'Offers'!$AI$7:$AI$608,"yes"))=0,"—",SUMIFS('Review'!$O$7:$O$210,'Review'!$B$7:$B$210,$B16,'Review'!$C$7:$C$210,D$10)) | E16: =IF(IF($E$5="Local prices",COUNTIFS('Offers'!$B$7:$B$608,$B16,'Offers'!$C$7:$C$608,E$10,'Offers'!$AH$7:$AH$608,"yes"),COUNTIFS('Offers'!$B$7:$B$608,$B16,'Offers'!$C$7:$C$608,E$10,'Offers'!$AI$7:$AI$608,"yes"))=0,"—",SUMIFS('Review'!$O$7:$O$210,'Review'!$B$7:$B$210,$B16,'Review'!$C$7:$C$210,E$10)) | F16: =IF(IF($E$5="Local prices",COUNTIFS('Offers'!$B$7:$B$608,$B16,'Offers'!$C$7:$C$608,F$10,'Offers'!$AH$7:$AH$608,"yes"),COUNTIFS('Offers'!$B$7:$B$608,$B16,'Offers'!$C$7:$C$608,F$10,'Offers'!$AI$7:$AI$608,"yes"))=0,"—",SUMIFS('Review'!$O$7:$O$210,'Review'!$B$7:$B$210,$B16,'Review'!$C$7:$C$210,F$10)) | G16: =IF(IF($E$5="Local prices",COUNTIFS('Offers'!$B$7:$B$608,$B16,'Offers'!$C$7:$C$608,G$10,'Offers'!$AH$7:$AH$608,"yes"),COUNTIFS('Offers'!$B$7:$B$608,$B16,'Offers'!$C$7:$C$608,G$10,'Offers'!$AI$7:$AI$608,"yes"))=0,"—",SUMIFS('Review'!$O$7:$O$210,'Review'!$B$7:$B$210,$B16,'Review'!$C$7:$C$210,G$10)) | H16: =IF(IF($E$5="Local prices",COUNTIFS('Offers'!$B$7:$B$608,$B16,'Offers'!$C$7:$C$608,H$10,'Offers'!$AH$7:$AH$608,"yes"),COUNTIFS('Offers'!$B$7:$B$608,$B16,'Offers'!$C$7:$C$608,H$10,'Offers'!$AI$7:$AI$608,"yes"))=0,"—",SUMIFS('Review'!$O$7:$O$210,'Review'!$B$7:$B$210,$B16,'Review'!$C$7:$C$210,H$10)) | J16: Czech | K16: =IF(COUNTIFS('Offers'!$B$7:$B$608,$J$6,'Offers'!$C$7:$C$608,$J16,'Offers'!$AI$7:$AI$608,"yes")=0,"—",SUMIFS('Review'!$I$7:$I$210,'Review'!$B$7:$B$210,$J$6,'Review'!$C$7:$C$210,$J16)) | L16: =IF(COUNTIFS('Offers'!$B$7:$B$608,$J$6,'Offers'!$C$7:$C$608,$J16,'Offers'!$AI$7:$AI$608,"yes")=0,"—",SUMIFS('Review'!$J$7:$J$210,'Review'!$B$7:$B$210,$J$6,'Review'!$C$7:$C$210,$J16)) | M16: =IF(COUNTIFS('Offers'!$B$7:$B$608,$J$6,'Offers'!$C$7:$C$608,$J16,'Offers'!$AI$7:$AI$608,"yes")=0,"—",SUMIFS('Review'!$K$7:$K$210,'Review'!$B$7:$B$210,$J$6,'Review'!$C$7:$C$210,$J16))
B17: Squeeze bottle 1,000 ml, PP, single tip | C17: =IF(IF($E$5="Local prices",COUNTIFS('Offers'!$B$7:$B$608,$B17,'Offers'!$C$7:$C$608,C$10,'Offers'!$AH$7:$AH$608,"yes"),COUNTIFS('Offers'!$B$7:$B$608,$B17,'Offers'!$C$7:$C$608,C$10,'Offers'!$AI$7:$AI$608,"yes"))=0,"—",SUMIFS('Review'!$O$7:$O$210,'Review'!$B$7:$B$210,$B17,'Review'!$C$7:$C$210,C$10)) | D17: =IF(IF($E$5="Local prices",COUNTIFS('Offers'!$B$7:$B$608,$B17,'Offers'!$C$7:$C$608,D$10,'Offers'!$AH$7:$AH$608,"yes"),COUNTIFS('Offers'!$B$7:$B$608,$B17,'Offers'!$C$7:$C$608,D$10,'Offers'!$AI$7:$AI$608,"yes"))=0,"—",SUMIFS('Review'!$O$7:$O$210,'Review'!$B$7:$B$210,$B17,'Review'!$C$7:$C$210,D$10)) | E17: =IF(IF($E$5="Local prices",COUNTIFS('Offers'!$B$7:$B$608,$B17,'Offers'!$C$7:$C$608,E$10,'Offers'!$AH$7:$AH$608,"yes"),COUNTIFS('Offers'!$B$7:$B$608,$B17,'Offers'!$C$7:$C$608,E$10,'Offers'!$AI$7:$AI$608,"yes"))=0,"—",SUMIFS('Review'!$O$7:$O$210,'Review'!$B$7:$B$210,$B17,'Review'!$C$7:$C$210,E$10)) | F17: =IF(IF($E$5="Local prices",COUNTIFS('Offers'!$B$7:$B$608,$B17,'Offers'!$C$7:$C$608,F$10,'Offers'!$AH$7:$AH$608,"yes"),COUNTIFS('Offers'!$B$7:$B$608,$B17,'Offers'!$C$7:$C$608,F$10,'Offers'!$AI$7:$AI$608,"yes"))=0,"—",SUMIFS('Review'!$O$7:$O$210,'Review'!$B$7:$B$210,$B17,'Review'!$C$7:$C$210,F$10)) | G17: =IF(IF($E$5="Local prices",COUNTIFS('Offers'!$B$7:$B$608,$B17,'Offers'!$C$7:$C$608,G$10,'Offers'!$AH$7:$AH$608,"yes"),COUNTIFS('Offers'!$B$7:$B$608,$B17,'Offers'!$C$7:$C$608,G$10,'Offers'!$AI$7:$AI$608,"yes"))=0,"—",SUMIFS('Review'!$O$7:$O$210,'Review'!$B$7:$B$210,$B17,'Review'!$C$7:$C$210,G$10)) | H17: =IF(IF($E$5="Local prices",COUNTIFS('Offers'!$B$7:$B$608,$B17,'Offers'!$C$7:$C$608,H$10,'Offers'!$AH$7:$AH$608,"yes"),COUNTIFS('Offers'!$B$7:$B$608,$B17,'Offers'!$C$7:$C$608,H$10,'Offers'!$AI$7:$AI$608,"yes"))=0,"—",SUMIFS('Review'!$O$7:$O$210,'Review'!$B$7:$B$210,$B17,'Review'!$C$7:$C$210,H$10)) | J17: Slovakia | K17: =IF(COUNTIFS('Offers'!$B$7:$B$608,$J$6,'Offers'!$C$7:$C$608,$J17,'Offers'!$AI$7:$AI$608,"yes")=0,"—",SUMIFS('Review'!$I$7:$I$210,'Review'!$B$7:$B$210,$J$6,'Review'!$C$7:$C$210,$J17)) | L17: =IF(COUNTIFS('Offers'!$B$7:$B$608,$J$6,'Offers'!$C$7:$C$608,$J17,'Offers'!$AI$7:$AI$608,"yes")=0,"—",SUMIFS('Review'!$J$7:$J$210,'Review'!$B$7:$B$210,$J$6,'Review'!$C$7:$C$210,$J17)) | M17: =IF(COUNTIFS('Offers'!$B$7:$B$608,$J$6,'Offers'!$C$7:$C$608,$J17,'Offers'!$AI$7:$AI$608,"yes")=0,"—",SUMIFS('Review'!$K$7:$K$210,'Review'!$B$7:$B$210,$J$6,'Review'!$C$7:$C$210,$J17))
B18: Squeeze bottle 500 ml, triple tip | C18: =IF(IF($E$5="Local prices",COUNTIFS('Offers'!$B$7:$B$608,$B18,'Offers'!$C$7:$C$608,C$10,'Offers'!$AH$7:$AH$608,"yes"),COUNTIFS('Offers'!$B$7:$B$608,$B18,'Offers'!$C$7:$C$608,C$10,'Offers'!$AI$7:$AI$608,"yes"))=0,"—",SUMIFS('Review'!$O$7:$O$210,'Review'!$B$7:$B$210,$B18,'Review'!$C$7:$C$210,C$10)) | D18: =IF(IF($E$5="Local prices",COUNTIFS('Offers'!$B$7:$B$608,$B18,'Offers'!$C$7:$C$608,D$10,'Offers'!$AH$7:$AH$608,"yes"),COUNTIFS('Offers'!$B$7:$B$608,$B18,'Offers'!$C$7:$C$608,D$10,'Offers'!$AI$7:$AI$608,"yes"))=0,"—",SUMIFS('Review'!$O$7:$O$210,'Review'!$B$7:$B$210,$B18,'Review'!$C$7:$C$210,D$10)) | E18: =IF(IF($E$5="Local prices",COUNTIFS('Offers'!$B$7:$B$608,$B18,'Offers'!$C$7:$C$608,E$10,'Offers'!$AH$7:$AH$608,"yes"),COUNTIFS('Offers'!$B$7:$B$608,$B18,'Offers'!$C$7:$C$608,E$10,'Offers'!$AI$7:$AI$608,"yes"))=0,"—",SUMIFS('Review'!$O$7:$O$210,'Review'!$B$7:$B$210,$B18,'Review'!$C$7:$C$210,E$10)) | F18: =IF(IF($E$5="Local prices",COUNTIFS('Offers'!$B$7:$B$608,$B18,'Offers'!$C$7:$C$608,F$10,'Offers'!$AH$7:$AH$608,"yes"),COUNTIFS('Offers'!$B$7:$B$608,$B18,'Offers'!$C$7:$C$608,F$10,'Offers'!$AI$7:$AI$608,"yes"))=0,"—",SUMIFS('Review'!$O$7:$O$210,'Review'!$B$7:$B$210,$B18,'Review'!$C$7:$C$210,F$10)) | G18: =IF(IF($E$5="Local prices",COUNTIFS('Offers'!$B$7:$B$608,$B18,'Offers'!$C$7:$C$608,G$10,'Offers'!$AH$7:$AH$608,"yes"),COUNTIFS('Offers'!$B$7:$B$608,$B18,'Offers'!$C$7:$C$608,G$10,'Offers'!$AI$7:$AI$608,"yes"))=0,"—",SUMIFS('Review'!$O$7:$O$210,'Review'!$B$7:$B$210,$B18,'Review'!$C$7:$C$210,G$10)) | H18: =IF(IF($E$5="Local prices",COUNTIFS('Offers'!$B$7:$B$608,$B18,'Offers'!$C$7:$C$608,H$10,'Offers'!$AH$7:$AH$608,"yes"),COUNTIFS('Offers'!$B$7:$B$608,$B18,'Offers'!$C$7:$C$608,H$10,'Offers'!$AI$7:$AI$608,"yes"))=0,"—",SUMIFS('Review'!$O$7:$O$210,'Review'!$B$7:$B$210,$B18,'Review'!$C$7:$C$210,H$10))
B19: Sauce pump dispenser with stand | C19: =IF(IF($E$5="Local prices",COUNTIFS('Offers'!$B$7:$B$608,$B19,'Offers'!$C$7:$C$608,C$10,'Offers'!$AH$7:$AH$608,"yes"),COUNTIFS('Offers'!$B$7:$B$608,$B19,'Offers'!$C$7:$C$608,C$10,'Offers'!$AI$7:$AI$608,"yes"))=0,"—",SUMIFS('Review'!$O$7:$O$210,'Review'!$B$7:$B$210,$B19,'Review'!$C$7:$C$210,C$10)) | D19: =IF(IF($E$5="Local prices",COUNTIFS('Offers'!$B$7:$B$608,$B19,'Offers'!$C$7:$C$608,D$10,'Offers'!$AH$7:$AH$608,"yes"),COUNTIFS('Offers'!$B$7:$B$608,$B19,'Offers'!$C$7:$C$608,D$10,'Offers'!$AI$7:$AI$608,"yes"))=0,"—",SUMIFS('Review'!$O$7:$O$210,'Review'!$B$7:$B$210,$B19,'Review'!$C$7:$C$210,D$10)) | E19: =IF(IF($E$5="Local prices",COUNTIFS('Offers'!$B$7:$B$608,$B19,'Offers'!$C$7:$C$608,E$10,'Offers'!$AH$7:$AH$608,"yes"),COUNTIFS('Offers'!$B$7:$B$608,$B19,'Offers'!$C$7:$C$608,E$10,'Offers'!$AI$7:$AI$608,"yes"))=0,"—",SUMIFS('Review'!$O$7:$O$210,'Review'!$B$7:$B$210,$B19,'Review'!$C$7:$C$210,E$10)) | F19: =IF(IF($E$5="Local prices",COUNTIFS('Offers'!$B$7:$B$608,$B19,'Offers'!$C$7:$C$608,F$10,'Offers'!$AH$7:$AH$608,"yes"),COUNTIFS('Offers'!$B$7:$B$608,$B19,'Offers'!$C$7:$C$608,F$10,'Offers'!$AI$7:$AI$608,"yes"))=0,"—",SUMIFS('Review'!$O$7:$O$210,'Review'!$B$7:$B$210,$B19,'Review'!$C$7:$C$210,F$10)) | G19: =IF(IF($E$5="Local prices",COUNTIFS('Offers'!$B$7:$B$608,$B19,'Offers'!$C$7:$C$608,G$10,'Offers'!$AH$7:$AH$608,"yes"),COUNTIFS('Offers'!$B$7:$B$608,$B19,'Offers'!$C$7:$C$608,G$10,'Offers'!$AI$7:$AI$608,"yes"))=0,"—",SUMIFS('Review'!$O$7:$O$210,'Review'!$B$7:$B$210,$B19,'Review'!$C$7:$C$210,G$10)) | H19: =IF(IF($E$5="Local prices",COUNTIFS('Offers'!$B$7:$B$608,$B19,'Offers'!$C$7:$C$608,H$10,'Offers'!$AH$7:$AH$608,"yes"),COUNTIFS('Offers'!$B$7:$B$608,$B19,'Offers'!$C$7:$C$608,H$10,'Offers'!$AI$7:$AI$608,"yes"))=0,"—",SUMIFS('Review'!$O$7:$O$210,'Review'!$B$7:$B$210,$B19,'Review'!$C$7:$C$210,H$10))
B20: PE cutting board 530 × 325 × 20 mm | C20: =IF(IF($E$5="Local prices",COUNTIFS('Offers'!$B$7:$B$608,$B20,'Offers'!$C$7:$C$608,C$10,'Offers'!$AH$7:$AH$608,"yes"),COUNTIFS('Offers'!$B$7:$B$608,$B20,'Offers'!$C$7:$C$608,C$10,'Offers'!$AI$7:$AI$608,"yes"))=0,"—",SUMIFS('Review'!$O$7:$O$210,'Review'!$B$7:$B$210,$B20,'Review'!$C$7:$C$210,C$10)) | D20: =IF(IF($E$5="Local prices",COUNTIFS('Offers'!$B$7:$B$608,$B20,'Offers'!$C$7:$C$608,D$10,'Offers'!$AH$7:$AH$608,"yes"),COUNTIFS('Offers'!$B$7:$B$608,$B20,'Offers'!$C$7:$C$608,D$10,'Offers'!$AI$7:$AI$608,"yes"))=0,"—",SUMIFS('Review'!$O$7:$O$210,'Review'!$B$7:$B$210,$B20,'Review'!$C$7:$C$210,D$10)) | E20: =IF(IF($E$5="Local prices",COUNTIFS('Offers'!$B$7:$B$608,$B20,'Offers'!$C$7:$C$608,E$10,'Offers'!$AH$7:$AH$608,"yes"),COUNTIFS('Offers'!$B$7:$B$608,$B20,'Offers'!$C$7:$C$608,E$10,'Offers'!$AI$7:$AI$608,"yes"))=0,"—",SUMIFS('Review'!$O$7:$O$210,'Review'!$B$7:$B$210,$B20,'Review'!$C$7:$C$210,E$10)) | F20: =IF(IF($E$5="Local prices",COUNTIFS('Offers'!$B$7:$B$608,$B20,'Offers'!$C$7:$C$608,F$10,'Offers'!$AH$7:$AH$608,"yes"),COUNTIFS('Offers'!$B$7:$B$608,$B20,'Offers'!$C$7:$C$608,F$10,'Offers'!$AI$7:$AI$608,"yes"))=0,"—",SUMIFS('Review'!$O$7:$O$210,'Review'!$B$7:$B$210,$B20,'Review'!$C$7:$C$210,F$10)) | G20: =IF(IF($E$5="Local prices",COUNTIFS('Offers'!$B$7:$B$608,$B20,'Offers'!$C$7:$C$608,G$10,'Offers'!$AH$7:$AH$608,"yes"),COUNTIFS('Offers'!$B$7:$B$608,$B20,'Offers'!$C$7:$C$608,G$10,'Offers'!$AI$7:$AI$608,"yes"))=0,"—",SUMIFS('Review'!$O$7:$O$210,'Review'!$B$7:$B$210,$B20,'Review'!$C$7:$C$210,G$10)) | H20: =IF(IF($E$5="Local prices",COUNTIFS('Offers'!$B$7:$B$608,$B20,'Offers'!$C$7:$C$608,H$10,'Offers'!$AH$7:$AH$608,"yes"),COUNTIFS('Offers'!$B$7:$B$608,$B20,'Offers'!$C$7:$C$608,H$10,'Offers'!$AI$7:$AI$608,"yes"))=0,"—",SUMIFS('Review'!$O$7:$O$210,'Review'!$B$7:$B$210,$B20,'Review'!$C$7:$C$210,H$10)) | J20: Price basis
B21: PE cutting board 600 × 400 × 20 mm | C21: =IF(IF($E$5="Local prices",COUNTIFS('Offers'!$B$7:$B$608,$B21,'Offers'!$C$7:$C$608,C$10,'Offers'!$AH$7:$AH$608,"yes"),COUNTIFS('Offers'!$B$7:$B$608,$B21,'Offers'!$C$7:$C$608,C$10,'Offers'!$AI$7:$AI$608,"yes"))=0,"—",SUMIFS('Review'!$O$7:$O$210,'Review'!$B$7:$B$210,$B21,'Review'!$C$7:$C$210,C$10)) | D21: =IF(IF($E$5="Local prices",COUNTIFS('Offers'!$B$7:$B$608,$B21,'Offers'!$C$7:$C$608,D$10,'Offers'!$AH$7:$AH$608,"yes"),COUNTIFS('Offers'!$B$7:$B$608,$B21,'Offers'!$C$7:$C$608,D$10,'Offers'!$AI$7:$AI$608,"yes"))=0,"—",SUMIFS('Review'!$O$7:$O$210,'Review'!$B$7:$B$210,$B21,'Review'!$C$7:$C$210,D$10)) | E21: =IF(IF($E$5="Local prices",COUNTIFS('Offers'!$B$7:$B$608,$B21,'Offers'!$C$7:$C$608,E$10,'Offers'!$AH$7:$AH$608,"yes"),COUNTIFS('Offers'!$B$7:$B$608,$B21,'Offers'!$C$7:$C$608,E$10,'Offers'!$AI$7:$AI$608,"yes"))=0,"—",SUMIFS('Review'!$O$7:$O$210,'Review'!$B$7:$B$210,$B21,'Review'!$C$7:$C$210,E$10)) | F21: =IF(IF($E$5="Local prices",COUNTIFS('Offers'!$B$7:$B$608,$B21,'Offers'!$C$7:$C$608,F$10,'Offers'!$AH$7:$AH$608,"yes"),COUNTIFS('Offers'!$B$7:$B$608,$B21,'Offers'!$C$7:$C$608,F$10,'Offers'!$AI$7:$AI$608,"yes"))=0,"—",SUMIFS('Review'!$O$7:$O$210,'Review'!$B$7:$B$210,$B21,'Review'!$C$7:$C$210,F$10)) | G21: =IF(IF($E$5="Local prices",COUNTIFS('Offers'!$B$7:$B$608,$B21,'Offers'!$C$7:$C$608,G$10,'Offers'!$AH$7:$AH$608,"yes"),COUNTIFS('Offers'!$B$7:$B$608,$B21,'Offers'!$C$7:$C$608,G$10,'Offers'!$AI$7:$AI$608,"yes"))=0,"—",SUMIFS('Review'!$O$7:$O$210,'Review'!$B$7:$B$210,$B21,'Review'!$C$7:$C$210,G$10)) | H21: =IF(IF($E$5="Local prices",COUNTIFS('Offers'!$B$7:$B$608,$B21,'Offers'!$C$7:$C$608,H$10,'Offers'!$AH$7:$AH$608,"yes"),COUNTIFS('Offers'!$B$7:$B$608,$B21,'Offers'!$C$7:$C$608,H$10,'Offers'!$AI$7:$AI$608,"yes"))=0,"—",SUMIFS('Review'!$O$7:$O$210,'Review'!$B$7:$B$210,$B21,'Review'!$C$7:$C$210,H$10)) | J21: Hungary and Romania prices are net per piece, as confirmed by you.
B22: PE cutting board 300 × 200 × 10 mm | C22: =IF(IF($E$5="Local prices",COUNTIFS('Offers'!$B$7:$B$608,$B22,'Offers'!$C$7:$C$608,C$10,'Offers'!$AH$7:$AH$608,"yes"),COUNTIFS('Offers'!$B$7:$B$608,$B22,'Offers'!$C$7:$C$608,C$10,'Offers'!$AI$7:$AI$608,"yes"))=0,"—",SUMIFS('Review'!$O$7:$O$210,'Review'!$B$7:$B$210,$B22,'Review'!$C$7:$C$210,C$10)) | D22: =IF(IF($E$5="Local prices",COUNTIFS('Offers'!$B$7:$B$608,$B22,'Offers'!$C$7:$C$608,D$10,'Offers'!$AH$7:$AH$608,"yes"),COUNTIFS('Offers'!$B$7:$B$608,$B22,'Offers'!$C$7:$C$608,D$10,'Offers'!$AI$7:$AI$608,"yes"))=0,"—",SUMIFS('Review'!$O$7:$O$210,'Review'!$B$7:$B$210,$B22,'Review'!$C$7:$C$210,D$10)) | E22: =IF(IF($E$5="Local prices",COUNTIFS('Offers'!$B$7:$B$608,$B22,'Offers'!$C$7:$C$608,E$10,'Offers'!$AH$7:$AH$608,"yes"),COUNTIFS('Offers'!$B$7:$B$608,$B22,'Offers'!$C$7:$C$608,E$10,'Offers'!$AI$7:$AI$608,"yes"))=0,"—",SUMIFS('Review'!$O$7:$O$210,'Review'!$B$7:$B$210,$B22,'Review'!$C$7:$C$210,E$10)) | F22: =IF(IF($E$5="Local prices",COUNTIFS('Offers'!$B$7:$B$608,$B22,'Offers'!$C$7:$C$608,F$10,'Offers'!$AH$7:$AH$608,"yes"),COUNTIFS('Offers'!$B$7:$B$608,$B22,'Offers'!$C$7:$C$608,F$10,'Offers'!$AI$7:$AI$608,"yes"))=0,"—",SUMIFS('Review'!$O$7:$O$210,'Review'!$B$7:$B$210,$B22,'Review'!$C$7:$C$210,F$10)) | G22: =IF(IF($E$5="Local prices",COUNTIFS('Offers'!$B$7:$B$608,$B22,'Offers'!$C$7:$C$608,G$10,'Offers'!$AH$7:$AH$608,"yes"),COUNTIFS('Offers'!$B$7:$B$608,$B22,'Offers'!$C$7:$C$608,G$10,'Offers'!$AI$7:$AI$608,"yes"))=0,"—",SUMIFS('Review'!$O$7:$O$210,'Review'!$B$7:$B$210,$B22,'Review'!$C$7:$C$210,G$10)) | H22: =IF(IF($E$5="Local prices",COUNTIFS('Offers'!$B$7:$B$608,$B22,'Offers'!$C$7:$C$608,H$10,'Offers'!$AH$7:$AH$608,"yes"),COUNTIFS('Offers'!$B$7:$B$608,$B22,'Offers'!$C$7:$C$608,H$10,'Offers'!$AI$7:$AI$608,"yes"))=0,"—",SUMIFS('Review'!$O$7:$O$210,'Review'!$B$7:$B$210,$B22,'Review'!$C$7:$C$210,H$10))
B23: PP dough box 600 × 400 × 100 mm | C23: =IF(IF($E$5="Local prices",COUNTIFS('Offers'!$B$7:$B$608,$B23,'Offers'!$C$7:$C$608,C$10,'Offers'!$AH$7:$AH$608,"yes"),COUNTIFS('Offers'!$B$7:$B$608,$B23,'Offers'!$C$7:$C$608,C$10,'Offers'!$AI$7:$AI$608,"yes"))=0,"—",SUMIFS('Review'!$O$7:$O$210,'Review'!$B$7:$B$210,$B23,'Review'!$C$7:$C$210,C$10)) | D23: =IF(IF($E$5="Local prices",COUNTIFS('Offers'!$B$7:$B$608,$B23,'Offers'!$C$7:$C$608,D$10,'Offers'!$AH$7:$AH$608,"yes"),COUNTIFS('Offers'!$B$7:$B$608,$B23,'Offers'!$C$7:$C$608,D$10,'Offers'!$AI$7:$AI$608,"yes"))=0,"—",SUMIFS('Review'!$O$7:$O$210,'Review'!$B$7:$B$210,$B23,'Review'!$C$7:$C$210,D$10)) | E23: =IF(IF($E$5="Local prices",COUNTIFS('Offers'!$B$7:$B$608,$B23,'Offers'!$C$7:$C$608,E$10,'Offers'!$AH$7:$AH$608,"yes"),COUNTIFS('Offers'!$B$7:$B$608,$B23,'Offers'!$C$7:$C$608,E$10,'Offers'!$AI$7:$AI$608,"yes"))=0,"—",SUMIFS('Review'!$O$7:$O$210,'Review'!$B$7:$B$210,$B23,'Review'!$C$7:$C$210,E$10)) | F23: =IF(IF($E$5="Local prices",COUNTIFS('Offers'!$B$7:$B$608,$B23,'Offers'!$C$7:$C$608,F$10,'Offers'!$AH$7:$AH$608,"yes"),COUNTIFS('Offers'!$B$7:$B$608,$B23,'Offers'!$C$7:$C$608,F$10,'Offers'!$AI$7:$AI$608,"yes"))=0,"—",SUMIFS('Review'!$O$7:$O$210,'Review'!$B$7:$B$210,$B23,'Review'!$C$7:$C$210,F$10)) | G23: =IF(IF($E$5="Local prices",COUNTIFS('Offers'!$B$7:$B$608,$B23,'Offers'!$C$7:$C$608,G$10,'Offers'!$AH$7:$AH$608,"yes"),COUNTIFS('Offers'!$B$7:$B$608,$B23,'Offers'!$C$7:$C$608,G$10,'Offers'!$AI$7:$AI$608,"yes"))=0,"—",SUMIFS('Review'!$O$7:$O$210,'Review'!$B$7:$B$210,$B23,'Review'!$C$7:$C$210,G$10)) | H23: =IF(IF($E$5="Local prices",COUNTIFS('Offers'!$B$7:$B$608,$B23,'Offers'!$C$7:$C$608,H$10,'Offers'!$AH$7:$AH$608,"yes"),COUNTIFS('Offers'!$B$7:$B$608,$B23,'Offers'!$C$7:$C$608,H$10,'Offers'!$AI$7:$AI$608,"yes"))=0,"—",SUMIFS('Review'!$O$7:$O$210,'Review'!$B$7:$B$210,$B23,'Review'!$C$7:$C$210,H$10))
B24: Lid for 600 × 400 mm dough box | C24: =IF(IF($E$5="Local prices",COUNTIFS('Offers'!$B$7:$B$608,$B24,'Offers'!$C$7:$C$608,C$10,'Offers'!$AH$7:$AH$608,"yes"),COUNTIFS('Offers'!$B$7:$B$608,$B24,'Offers'!$C$7:$C$608,C$10,'Offers'!$AI$7:$AI$608,"yes"))=0,"—",SUMIFS('Review'!$O$7:$O$210,'Review'!$B$7:$B$210,$B24,'Review'!$C$7:$C$210,C$10)) | D24: =IF(IF($E$5="Local prices",COUNTIFS('Offers'!$B$7:$B$608,$B24,'Offers'!$C$7:$C$608,D$10,'Offers'!$AH$7:$AH$608,"yes"),COUNTIFS('Offers'!$B$7:$B$608,$B24,'Offers'!$C$7:$C$608,D$10,'Offers'!$AI$7:$AI$608,"yes"))=0,"—",SUMIFS('Review'!$O$7:$O$210,'Review'!$B$7:$B$210,$B24,'Review'!$C$7:$C$210,D$10)) | E24: =IF(IF($E$5="Local prices",COUNTIFS('Offers'!$B$7:$B$608,$B24,'Offers'!$C$7:$C$608,E$10,'Offers'!$AH$7:$AH$608,"yes"),COUNTIFS('Offers'!$B$7:$B$608,$B24,'Offers'!$C$7:$C$608,E$10,'Offers'!$AI$7:$AI$608,"yes"))=0,"—",SUMIFS('Review'!$O$7:$O$210,'Review'!$B$7:$B$210,$B24,'Review'!$C$7:$C$210,E$10)) | F24: =IF(IF($E$5="Local prices",COUNTIFS('Offers'!$B$7:$B$608,$B24,'Offers'!$C$7:$C$608,F$10,'Offers'!$AH$7:$AH$608,"yes"),COUNTIFS('Offers'!$B$7:$B$608,$B24,'Offers'!$C$7:$C$608,F$10,'Offers'!$AI$7:$AI$608,"yes"))=0,"—",SUMIFS('Review'!$O$7:$O$210,'Review'!$B$7:$B$210,$B24,'Review'!$C$7:$C$210,F$10)) | G24: =IF(IF($E$5="Local prices",COUNTIFS('Offers'!$B$7:$B$608,$B24,'Offers'!$C$7:$C$608,G$10,'Offers'!$AH$7:$AH$608,"yes"),COUNTIFS('Offers'!$B$7:$B$608,$B24,'Offers'!$C$7:$C$608,G$10,'Offers'!$AI$7:$AI$608,"yes"))=0,"—",SUMIFS('Review'!$O$7:$O$210,'Review'!$B$7:$B$210,$B24,'Review'!$C$7:$C$210,G$10)) | H24: =IF(IF($E$5="Local prices",COUNTIFS('Offers'!$B$7:$B$608,$B24,'Offers'!$C$7:$C$608,H$10,'Offers'!$AH$7:$AH$608,"yes"),COUNTIFS('Offers'!$B$7:$B$608,$B24,'Offers'!$C$7:$C$608,H$10,'Offers'!$AI$7:$AI$608,"yes"))=0,"—",SUMIFS('Review'!$O$7:$O$210,'Review'!$B$7:$B$210,$B24,'Review'!$C$7:$C$210,H$10)) | J24: Current FX
B25: PE dough box 600 × 400 × 75 mm | C25: =IF(IF($E$5="Local prices",COUNTIFS('Offers'!$B$7:$B$608,$B25,'Offers'!$C$7:$C$608,C$10,'Offers'!$AH$7:$AH$608,"yes"),COUNTIFS('Offers'!$B$7:$B$608,$B25,'Offers'!$C$7:$C$608,C$10,'Offers'!$AI$7:$AI$608,"yes"))=0,"—",SUMIFS('Review'!$O$7:$O$210,'Review'!$B$7:$B$210,$B25,'Review'!$C$7:$C$210,C$10)) | D25: =IF(IF($E$5="Local prices",COUNTIFS('Offers'!$B$7:$B$608,$B25,'Offers'!$C$7:$C$608,D$10,'Offers'!$AH$7:$AH$608,"yes"),COUNTIFS('Offers'!$B$7:$B$608,$B25,'Offers'!$C$7:$C$608,D$10,'Offers'!$AI$7:$AI$608,"yes"))=0,"—",SUMIFS('Review'!$O$7:$O$210,'Review'!$B$7:$B$210,$B25,'Review'!$C$7:$C$210,D$10)) | E25: =IF(IF($E$5="Local prices",COUNTIFS('Offers'!$B$7:$B$608,$B25,'Offers'!$C$7:$C$608,E$10,'Offers'!$AH$7:$AH$608,"yes"),COUNTIFS('Offers'!$B$7:$B$608,$B25,'Offers'!$C$7:$C$608,E$10,'Offers'!$AI$7:$AI$608,"yes"))=0,"—",SUMIFS('Review'!$O$7:$O$210,'Review'!$B$7:$B$210,$B25,'Review'!$C$7:$C$210,E$10)) | F25: =IF(IF($E$5="Local prices",COUNTIFS('Offers'!$B$7:$B$608,$B25,'Offers'!$C$7:$C$608,F$10,'Offers'!$AH$7:$AH$608,"yes"),COUNTIFS('Offers'!$B$7:$B$608,$B25,'Offers'!$C$7:$C$608,F$10,'Offers'!$AI$7:$AI$608,"yes"))=0,"—",SUMIFS('Review'!$O$7:$O$210,'Review'!$B$7:$B$210,$B25,'Review'!$C$7:$C$210,F$10)) | G25: =IF(IF($E$5="Local prices",COUNTIFS('Offers'!$B$7:$B$608,$B25,'Offers'!$C$7:$C$608,G$10,'Offers'!$AH$7:$AH$608,"yes"),COUNTIFS('Offers'!$B$7:$B$608,$B25,'Offers'!$C$7:$C$608,G$10,'Offers'!$AI$7:$AI$608,"yes"))=0,"—",SUMIFS('Review'!$O$7:$O$210,'Review'!$B$7:$B$210,$B25,'Review'!$C$7:$C$210,G$10)) | H25: =IF(IF($E$5="Local prices",COUNTIFS('Offers'!$B$7:$B$608,$B25,'Offers'!$C$7:$C$608,H$10,'Offers'!$AH$7:$AH$608,"yes"),COUNTIFS('Offers'!$B$7:$B$608,$B25,'Offers'!$C$7:$C$608,H$10,'Offers'!$AI$7:$AI$608,"yes"))=0,"—",SUMIFS('Review'!$O$7:$O$210,'Review'!$B$7:$B$210,$B25,'Review'!$C$7:$C$210,H$10)) | J25: Erste rates are applied to analytical conversions. Historical prices and research dates remain unchanged.
B26: Front-load GN 1/1 thermobox, 80–90 L | C26: =IF(IF($E$5="Local prices",COUNTIFS('Offers'!$B$7:$B$608,$B26,'Offers'!$C$7:$C$608,C$10,'Offers'!$AH$7:$AH$608,"yes"),COUNTIFS('Offers'!$B$7:$B$608,$B26,'Offers'!$C$7:$C$608,C$10,'Offers'!$AI$7:$AI$608,"yes"))=0,"—",SUMIFS('Review'!$O$7:$O$210,'Review'!$B$7:$B$210,$B26,'Review'!$C$7:$C$210,C$10)) | D26: =IF(IF($E$5="Local prices",COUNTIFS('Offers'!$B$7:$B$608,$B26,'Offers'!$C$7:$C$608,D$10,'Offers'!$AH$7:$AH$608,"yes"),COUNTIFS('Offers'!$B$7:$B$608,$B26,'Offers'!$C$7:$C$608,D$10,'Offers'!$AI$7:$AI$608,"yes"))=0,"—",SUMIFS('Review'!$O$7:$O$210,'Review'!$B$7:$B$210,$B26,'Review'!$C$7:$C$210,D$10)) | E26: =IF(IF($E$5="Local prices",COUNTIFS('Offers'!$B$7:$B$608,$B26,'Offers'!$C$7:$C$608,E$10,'Offers'!$AH$7:$AH$608,"yes"),COUNTIFS('Offers'!$B$7:$B$608,$B26,'Offers'!$C$7:$C$608,E$10,'Offers'!$AI$7:$AI$608,"yes"))=0,"—",SUMIFS('Review'!$O$7:$O$210,'Review'!$B$7:$B$210,$B26,'Review'!$C$7:$C$210,E$10)) | F26: =IF(IF($E$5="Local prices",COUNTIFS('Offers'!$B$7:$B$608,$B26,'Offers'!$C$7:$C$608,F$10,'Offers'!$AH$7:$AH$608,"yes"),COUNTIFS('Offers'!$B$7:$B$608,$B26,'Offers'!$C$7:$C$608,F$10,'Offers'!$AI$7:$AI$608,"yes"))=0,"—",SUMIFS('Review'!$O$7:$O$210,'Review'!$B$7:$B$210,$B26,'Review'!$C$7:$C$210,F$10)) | G26: =IF(IF($E$5="Local prices",COUNTIFS('Offers'!$B$7:$B$608,$B26,'Offers'!$C$7:$C$608,G$10,'Offers'!$AH$7:$AH$608,"yes"),COUNTIFS('Offers'!$B$7:$B$608,$B26,'Offers'!$C$7:$C$608,G$10,'Offers'!$AI$7:$AI$608,"yes"))=0,"—",SUMIFS('Review'!$O$7:$O$210,'Review'!$B$7:$B$210,$B26,'Review'!$C$7:$C$210,G$10)) | H26: =IF(IF($E$5="Local prices",COUNTIFS('Offers'!$B$7:$B$608,$B26,'Offers'!$C$7:$C$608,H$10,'Offers'!$AH$7:$AH$608,"yes"),COUNTIFS('Offers'!$B$7:$B$608,$B26,'Offers'!$C$7:$C$608,H$10,'Offers'!$AI$7:$AI$608,"yes"))=0,"—",SUMIFS('Review'!$O$7:$O$210,'Review'!$B$7:$B$210,$B26,'Review'!$C$7:$C$210,H$10))
B27: Service tray approx. 370 × 530 mm | C27: =IF(IF($E$5="Local prices",COUNTIFS('Offers'!$B$7:$B$608,$B27,'Offers'!$C$7:$C$608,C$10,'Offers'!$AH$7:$AH$608,"yes"),COUNTIFS('Offers'!$B$7:$B$608,$B27,'Offers'!$C$7:$C$608,C$10,'Offers'!$AI$7:$AI$608,"yes"))=0,"—",SUMIFS('Review'!$O$7:$O$210,'Review'!$B$7:$B$210,$B27,'Review'!$C$7:$C$210,C$10)) | D27: =IF(IF($E$5="Local prices",COUNTIFS('Offers'!$B$7:$B$608,$B27,'Offers'!$C$7:$C$608,D$10,'Offers'!$AH$7:$AH$608,"yes"),COUNTIFS('Offers'!$B$7:$B$608,$B27,'Offers'!$C$7:$C$608,D$10,'Offers'!$AI$7:$AI$608,"yes"))=0,"—",SUMIFS('Review'!$O$7:$O$210,'Review'!$B$7:$B$210,$B27,'Review'!$C$7:$C$210,D$10)) | E27: =IF(IF($E$5="Local prices",COUNTIFS('Offers'!$B$7:$B$608,$B27,'Offers'!$C$7:$C$608,E$10,'Offers'!$AH$7:$AH$608,"yes"),COUNTIFS('Offers'!$B$7:$B$608,$B27,'Offers'!$C$7:$C$608,E$10,'Offers'!$AI$7:$AI$608,"yes"))=0,"—",SUMIFS('Review'!$O$7:$O$210,'Review'!$B$7:$B$210,$B27,'Review'!$C$7:$C$210,E$10)) | F27: =IF(IF($E$5="Local prices",COUNTIFS('Offers'!$B$7:$B$608,$B27,'Offers'!$C$7:$C$608,F$10,'Offers'!$AH$7:$AH$608,"yes"),COUNTIFS('Offers'!$B$7:$B$608,$B27,'Offers'!$C$7:$C$608,F$10,'Offers'!$AI$7:$AI$608,"yes"))=0,"—",SUMIFS('Review'!$O$7:$O$210,'Review'!$B$7:$B$210,$B27,'Review'!$C$7:$C$210,F$10)) | G27: =IF(IF($E$5="Local prices",COUNTIFS('Offers'!$B$7:$B$608,$B27,'Offers'!$C$7:$C$608,G$10,'Offers'!$AH$7:$AH$608,"yes"),COUNTIFS('Offers'!$B$7:$B$608,$B27,'Offers'!$C$7:$C$608,G$10,'Offers'!$AI$7:$AI$608,"yes"))=0,"—",SUMIFS('Review'!$O$7:$O$210,'Review'!$B$7:$B$210,$B27,'Review'!$C$7:$C$210,G$10)) | H27: =IF(IF($E$5="Local prices",COUNTIFS('Offers'!$B$7:$B$608,$B27,'Offers'!$C$7:$C$608,H$10,'Offers'!$AH$7:$AH$608,"yes"),COUNTIFS('Offers'!$B$7:$B$608,$B27,'Offers'!$C$7:$C$608,H$10,'Offers'!$AI$7:$AI$608,"yes"))=0,"—",SUMIFS('Review'!$O$7:$O$210,'Review'!$B$7:$B$210,$B27,'Review'!$C$7:$C$210,H$10))
B28: Thermo tray + lid, 5–6 compartments | C28: =IF(IF($E$5="Local prices",COUNTIFS('Offers'!$B$7:$B$608,$B28,'Offers'!$C$7:$C$608,C$10,'Offers'!$AH$7:$AH$608,"yes"),COUNTIFS('Offers'!$B$7:$B$608,$B28,'Offers'!$C$7:$C$608,C$10,'Offers'!$AI$7:$AI$608,"yes"))=0,"—",SUMIFS('Review'!$O$7:$O$210,'Review'!$B$7:$B$210,$B28,'Review'!$C$7:$C$210,C$10)) | D28: =IF(IF($E$5="Local prices",COUNTIFS('Offers'!$B$7:$B$608,$B28,'Offers'!$C$7:$C$608,D$10,'Offers'!$AH$7:$AH$608,"yes"),COUNTIFS('Offers'!$B$7:$B$608,$B28,'Offers'!$C$7:$C$608,D$10,'Offers'!$AI$7:$AI$608,"yes"))=0,"—",SUMIFS('Review'!$O$7:$O$210,'Review'!$B$7:$B$210,$B28,'Review'!$C$7:$C$210,D$10)) | E28: =IF(IF($E$5="Local prices",COUNTIFS('Offers'!$B$7:$B$608,$B28,'Offers'!$C$7:$C$608,E$10,'Offers'!$AH$7:$AH$608,"yes"),COUNTIFS('Offers'!$B$7:$B$608,$B28,'Offers'!$C$7:$C$608,E$10,'Offers'!$AI$7:$AI$608,"yes"))=0,"—",SUMIFS('Review'!$O$7:$O$210,'Review'!$B$7:$B$210,$B28,'Review'!$C$7:$C$210,E$10)) | F28: =IF(IF($E$5="Local prices",COUNTIFS('Offers'!$B$7:$B$608,$B28,'Offers'!$C$7:$C$608,F$10,'Offers'!$AH$7:$AH$608,"yes"),COUNTIFS('Offers'!$B$7:$B$608,$B28,'Offers'!$C$7:$C$608,F$10,'Offers'!$AI$7:$AI$608,"yes"))=0,"—",SUMIFS('Review'!$O$7:$O$210,'Review'!$B$7:$B$210,$B28,'Review'!$C$7:$C$210,F$10)) | G28: =IF(IF($E$5="Local prices",COUNTIFS('Offers'!$B$7:$B$608,$B28,'Offers'!$C$7:$C$608,G$10,'Offers'!$AH$7:$AH$608,"yes"),COUNTIFS('Offers'!$B$7:$B$608,$B28,'Offers'!$C$7:$C$608,G$10,'Offers'!$AI$7:$AI$608,"yes"))=0,"—",SUMIFS('Review'!$O$7:$O$210,'Review'!$B$7:$B$210,$B28,'Review'!$C$7:$C$210,G$10)) | H28: =IF(IF($E$5="Local prices",COUNTIFS('Offers'!$B$7:$B$608,$B28,'Offers'!$C$7:$C$608,H$10,'Offers'!$AH$7:$AH$608,"yes"),COUNTIFS('Offers'!$B$7:$B$608,$B28,'Offers'!$C$7:$C$608,H$10,'Offers'!$AI$7:$AI$608,"yes"))=0,"—",SUMIFS('Review'!$O$7:$O$210,'Review'!$B$7:$B$210,$B28,'Review'!$C$7:$C$210,H$10)) | J28: Your review
B29: GN 1/1 PP container, 65 mm | C29: =IF(IF($E$5="Local prices",COUNTIFS('Offers'!$B$7:$B$608,$B29,'Offers'!$C$7:$C$608,C$10,'Offers'!$AH$7:$AH$608,"yes"),COUNTIFS('Offers'!$B$7:$B$608,$B29,'Offers'!$C$7:$C$608,C$10,'Offers'!$AI$7:$AI$608,"yes"))=0,"—",SUMIFS('Review'!$O$7:$O$210,'Review'!$B$7:$B$210,$B29,'Review'!$C$7:$C$210,C$10)) | D29: =IF(IF($E$5="Local prices",COUNTIFS('Offers'!$B$7:$B$608,$B29,'Offers'!$C$7:$C$608,D$10,'Offers'!$AH$7:$AH$608,"yes"),COUNTIFS('Offers'!$B$7:$B$608,$B29,'Offers'!$C$7:$C$608,D$10,'Offers'!$AI$7:$AI$608,"yes"))=0,"—",SUMIFS('Review'!$O$7:$O$210,'Review'!$B$7:$B$210,$B29,'Review'!$C$7:$C$210,D$10)) | E29: =IF(IF($E$5="Local prices",COUNTIFS('Offers'!$B$7:$B$608,$B29,'Offers'!$C$7:$C$608,E$10,'Offers'!$AH$7:$AH$608,"yes"),COUNTIFS('Offers'!$B$7:$B$608,$B29,'Offers'!$C$7:$C$608,E$10,'Offers'!$AI$7:$AI$608,"yes"))=0,"—",SUMIFS('Review'!$O$7:$O$210,'Review'!$B$7:$B$210,$B29,'Review'!$C$7:$C$210,E$10)) | F29: =IF(IF($E$5="Local prices",COUNTIFS('Offers'!$B$7:$B$608,$B29,'Offers'!$C$7:$C$608,F$10,'Offers'!$AH$7:$AH$608,"yes"),COUNTIFS('Offers'!$B$7:$B$608,$B29,'Offers'!$C$7:$C$608,F$10,'Offers'!$AI$7:$AI$608,"yes"))=0,"—",SUMIFS('Review'!$O$7:$O$210,'Review'!$B$7:$B$210,$B29,'Review'!$C$7:$C$210,F$10)) | G29: =IF(IF($E$5="Local prices",COUNTIFS('Offers'!$B$7:$B$608,$B29,'Offers'!$C$7:$C$608,G$10,'Offers'!$AH$7:$AH$608,"yes"),COUNTIFS('Offers'!$B$7:$B$608,$B29,'Offers'!$C$7:$C$608,G$10,'Offers'!$AI$7:$AI$608,"yes"))=0,"—",SUMIFS('Review'!$O$7:$O$210,'Review'!$B$7:$B$210,$B29,'Review'!$C$7:$C$210,G$10)) | H29: =IF(IF($E$5="Local prices",COUNTIFS('Offers'!$B$7:$B$608,$B29,'Offers'!$C$7:$C$608,H$10,'Offers'!$AH$7:$AH$608,"yes"),COUNTIFS('Offers'!$B$7:$B$608,$B29,'Offers'!$C$7:$C$608,H$10,'Offers'!$AI$7:$AI$608,"yes"))=0,"—",SUMIFS('Review'!$O$7:$O$210,'Review'!$B$7:$B$210,$B29,'Review'!$C$7:$C$210,H$10)) | J29: Record decisions, priorities and comments in Review. Add offer-specific comments in Offers.
B30: GN 1/3 PC container, 100 mm | C30: =IF(IF($E$5="Local prices",COUNTIFS('Offers'!$B$7:$B$608,$B30,'Offers'!$C$7:$C$608,C$10,'Offers'!$AH$7:$AH$608,"yes"),COUNTIFS('Offers'!$B$7:$B$608,$B30,'Offers'!$C$7:$C$608,C$10,'Offers'!$AI$7:$AI$608,"yes"))=0,"—",SUMIFS('Review'!$O$7:$O$210,'Review'!$B$7:$B$210,$B30,'Review'!$C$7:$C$210,C$10)) | D30: =IF(IF($E$5="Local prices",COUNTIFS('Offers'!$B$7:$B$608,$B30,'Offers'!$C$7:$C$608,D$10,'Offers'!$AH$7:$AH$608,"yes"),COUNTIFS('Offers'!$B$7:$B$608,$B30,'Offers'!$C$7:$C$608,D$10,'Offers'!$AI$7:$AI$608,"yes"))=0,"—",SUMIFS('Review'!$O$7:$O$210,'Review'!$B$7:$B$210,$B30,'Review'!$C$7:$C$210,D$10)) | E30: =IF(IF($E$5="Local prices",COUNTIFS('Offers'!$B$7:$B$608,$B30,'Offers'!$C$7:$C$608,E$10,'Offers'!$AH$7:$AH$608,"yes"),COUNTIFS('Offers'!$B$7:$B$608,$B30,'Offers'!$C$7:$C$608,E$10,'Offers'!$AI$7:$AI$608,"yes"))=0,"—",SUMIFS('Review'!$O$7:$O$210,'Review'!$B$7:$B$210,$B30,'Review'!$C$7:$C$210,E$10)) | F30: =IF(IF($E$5="Local prices",COUNTIFS('Offers'!$B$7:$B$608,$B30,'Offers'!$C$7:$C$608,F$10,'Offers'!$AH$7:$AH$608,"yes"),COUNTIFS('Offers'!$B$7:$B$608,$B30,'Offers'!$C$7:$C$608,F$10,'Offers'!$AI$7:$AI$608,"yes"))=0,"—",SUMIFS('Review'!$O$7:$O$210,'Review'!$B$7:$B$210,$B30,'Review'!$C$7:$C$210,F$10)) | G30: =IF(IF($E$5="Local prices",COUNTIFS('Offers'!$B$7:$B$608,$B30,'Offers'!$C$7:$C$608,G$10,'Offers'!$AH$7:$AH$608,"yes"),COUNTIFS('Offers'!$B$7:$B$608,$B30,'Offers'!$C$7:$C$608,G$10,'Offers'!$AI$7:$AI$608,"yes"))=0,"—",SUMIFS('Review'!$O$7:$O$210,'Review'!$B$7:$B$210,$B30,'Review'!$C$7:$C$210,G$10)) | H30: =IF(IF($E$5="Local prices",COUNTIFS('Offers'!$B$7:$B$608,$B30,'Offers'!$C$7:$C$608,H$10,'Offers'!$AH$7:$AH$608,"yes"),COUNTIFS('Offers'!$B$7:$B$608,$B30,'Offers'!$C$7:$C$608,H$10,'Offers'!$AI$7:$AI$608,"yes"))=0,"—",SUMIFS('Review'!$O$7:$O$210,'Review'!$B$7:$B$210,$B30,'Review'!$C$7:$C$210,H$10))
B31: GN 1/2 PP container, 150 mm | C31: =IF(IF($E$5="Local prices",COUNTIFS('Offers'!$B$7:$B$608,$B31,'Offers'!$C$7:$C$608,C$10,'Offers'!$AH$7:$AH$608,"yes"),COUNTIFS('Offers'!$B$7:$B$608,$B31,'Offers'!$C$7:$C$608,C$10,'Offers'!$AI$7:$AI$608,"yes"))=0,"—",SUMIFS('Review'!$O$7:$O$210,'Review'!$B$7:$B$210,$B31,'Review'!$C$7:$C$210,C$10)) | D31: =IF(IF($E$5="Local prices",COUNTIFS('Offers'!$B$7:$B$608,$B31,'Offers'!$C$7:$C$608,D$10,'Offers'!$AH$7:$AH$608,"yes"),COUNTIFS('Offers'!$B$7:$B$608,$B31,'Offers'!$C$7:$C$608,D$10,'Offers'!$AI$7:$AI$608,"yes"))=0,"—",SUMIFS('Review'!$O$7:$O$210,'Review'!$B$7:$B$210,$B31,'Review'!$C$7:$C$210,D$10)) | E31: =IF(IF($E$5="Local prices",COUNTIFS('Offers'!$B$7:$B$608,$B31,'Offers'!$C$7:$C$608,E$10,'Offers'!$AH$7:$AH$608,"yes"),COUNTIFS('Offers'!$B$7:$B$608,$B31,'Offers'!$C$7:$C$608,E$10,'Offers'!$AI$7:$AI$608,"yes"))=0,"—",SUMIFS('Review'!$O$7:$O$210,'Review'!$B$7:$B$210,$B31,'Review'!$C$7:$C$210,E$10)) | F31: =IF(IF($E$5="Local prices",COUNTIFS('Offers'!$B$7:$B$608,$B31,'Offers'!$C$7:$C$608,F$10,'Offers'!$AH$7:$AH$608,"yes"),COUNTIFS('Offers'!$B$7:$B$608,$B31,'Offers'!$C$7:$C$608,F$10,'Offers'!$AI$7:$AI$608,"yes"))=0,"—",SUMIFS('Review'!$O$7:$O$210,'Review'!$B$7:$B$210,$B31,'Review'!$C$7:$C$210,F$10)) | G31: =IF(IF($E$5="Local prices",COUNTIFS('Offers'!$B$7:$B$608,$B31,'Offers'!$C$7:$C$608,G$10,'Offers'!$AH$7:$AH$608,"yes"),COUNTIFS('Offers'!$B$7:$B$608,$B31,'Offers'!$C$7:$C$608,G$10,'Offers'!$AI$7:$AI$608,"yes"))=0,"—",SUMIFS('Review'!$O$7:$O$210,'Review'!$B$7:$B$210,$B31,'Review'!$C$7:$C$210,G$10)) | H31: =IF(IF($E$5="Local prices",COUNTIFS('Offers'!$B$7:$B$608,$B31,'Offers'!$C$7:$C$608,H$10,'Offers'!$AH$7:$AH$608,"yes"),COUNTIFS('Offers'!$B$7:$B$608,$B31,'Offers'!$C$7:$C$608,H$10,'Offers'!$AI$7:$AI$608,"yes"))=0,"—",SUMIFS('Review'!$O$7:$O$210,'Review'!$B$7:$B$210,$B31,'Review'!$C$7:$C$210,H$10))
B32: GN 1/1 PC lid | C32: =IF(IF($E$5="Local prices",COUNTIFS('Offers'!$B$7:$B$608,$B32,'Offers'!$C$7:$C$608,C$10,'Offers'!$AH$7:$AH$608,"yes"),COUNTIFS('Offers'!$B$7:$B$608,$B32,'Offers'!$C$7:$C$608,C$10,'Offers'!$AI$7:$AI$608,"yes"))=0,"—",SUMIFS('Review'!$O$7:$O$210,'Review'!$B$7:$B$210,$B32,'Review'!$C$7:$C$210,C$10)) | D32: =IF(IF($E$5="Local prices",COUNTIFS('Offers'!$B$7:$B$608,$B32,'Offers'!$C$7:$C$608,D$10,'Offers'!$AH$7:$AH$608,"yes"),COUNTIFS('Offers'!$B$7:$B$608,$B32,'Offers'!$C$7:$C$608,D$10,'Offers'!$AI$7:$AI$608,"yes"))=0,"—",SUMIFS('Review'!$O$7:$O$210,'Review'!$B$7:$B$210,$B32,'Review'!$C$7:$C$210,D$10)) | E32: =IF(IF($E$5="Local prices",COUNTIFS('Offers'!$B$7:$B$608,$B32,'Offers'!$C$7:$C$608,E$10,'Offers'!$AH$7:$AH$608,"yes"),COUNTIFS('Offers'!$B$7:$B$608,$B32,'Offers'!$C$7:$C$608,E$10,'Offers'!$AI$7:$AI$608,"yes"))=0,"—",SUMIFS('Review'!$O$7:$O$210,'Review'!$B$7:$B$210,$B32,'Review'!$C$7:$C$210,E$10)) | F32: =IF(IF($E$5="Local prices",COUNTIFS('Offers'!$B$7:$B$608,$B32,'Offers'!$C$7:$C$608,F$10,'Offers'!$AH$7:$AH$608,"yes"),COUNTIFS('Offers'!$B$7:$B$608,$B32,'Offers'!$C$7:$C$608,F$10,'Offers'!$AI$7:$AI$608,"yes"))=0,"—",SUMIFS('Review'!$O$7:$O$210,'Review'!$B$7:$B$210,$B32,'Review'!$C$7:$C$210,F$10)) | G32: =IF(IF($E$5="Local prices",COUNTIFS('Offers'!$B$7:$B$608,$B32,'Offers'!$C$7:$C$608,G$10,'Offers'!$AH$7:$AH$608,"yes"),COUNTIFS('Offers'!$B$7:$B$608,$B32,'Offers'!$C$7:$C$608,G$10,'Offers'!$AI$7:$AI$608,"yes"))=0,"—",SUMIFS('Review'!$O$7:$O$210,'Review'!$B$7:$B$210,$B32,'Review'!$C$7:$C$210,G$10)) | H32: =IF(IF($E$5="Local prices",COUNTIFS('Offers'!$B$7:$B$608,$B32,'Offers'!$C$7:$C$608,H$10,'Offers'!$AH$7:$AH$608,"yes"),COUNTIFS('Offers'!$B$7:$B$608,$B32,'Offers'!$C$7:$C$608,H$10,'Offers'!$AI$7:$AI$608,"yes"))=0,"—",SUMIFS('Review'!$O$7:$O$210,'Review'!$B$7:$B$210,$B32,'Review'!$C$7:$C$210,H$10)) | J32: Match scope
B33: GN 1/6 PP container, 100 mm | C33: =IF(IF($E$5="Local prices",COUNTIFS('Offers'!$B$7:$B$608,$B33,'Offers'!$C$7:$C$608,C$10,'Offers'!$AH$7:$AH$608,"yes"),COUNTIFS('Offers'!$B$7:$B$608,$B33,'Offers'!$C$7:$C$608,C$10,'Offers'!$AI$7:$AI$608,"yes"))=0,"—",SUMIFS('Review'!$O$7:$O$210,'Review'!$B$7:$B$210,$B33,'Review'!$C$7:$C$210,C$10)) | D33: =IF(IF($E$5="Local prices",COUNTIFS('Offers'!$B$7:$B$608,$B33,'Offers'!$C$7:$C$608,D$10,'Offers'!$AH$7:$AH$608,"yes"),COUNTIFS('Offers'!$B$7:$B$608,$B33,'Offers'!$C$7:$C$608,D$10,'Offers'!$AI$7:$AI$608,"yes"))=0,"—",SUMIFS('Review'!$O$7:$O$210,'Review'!$B$7:$B$210,$B33,'Review'!$C$7:$C$210,D$10)) | E33: =IF(IF($E$5="Local prices",COUNTIFS('Offers'!$B$7:$B$608,$B33,'Offers'!$C$7:$C$608,E$10,'Offers'!$AH$7:$AH$608,"yes"),COUNTIFS('Offers'!$B$7:$B$608,$B33,'Offers'!$C$7:$C$608,E$10,'Offers'!$AI$7:$AI$608,"yes"))=0,"—",SUMIFS('Review'!$O$7:$O$210,'Review'!$B$7:$B$210,$B33,'Review'!$C$7:$C$210,E$10)) | F33: =IF(IF($E$5="Local prices",COUNTIFS('Offers'!$B$7:$B$608,$B33,'Offers'!$C$7:$C$608,F$10,'Offers'!$AH$7:$AH$608,"yes"),COUNTIFS('Offers'!$B$7:$B$608,$B33,'Offers'!$C$7:$C$608,F$10,'Offers'!$AI$7:$AI$608,"yes"))=0,"—",SUMIFS('Review'!$O$7:$O$210,'Review'!$B$7:$B$210,$B33,'Review'!$C$7:$C$210,F$10)) | G33: =IF(IF($E$5="Local prices",COUNTIFS('Offers'!$B$7:$B$608,$B33,'Offers'!$C$7:$C$608,G$10,'Offers'!$AH$7:$AH$608,"yes"),COUNTIFS('Offers'!$B$7:$B$608,$B33,'Offers'!$C$7:$C$608,G$10,'Offers'!$AI$7:$AI$608,"yes"))=0,"—",SUMIFS('Review'!$O$7:$O$210,'Review'!$B$7:$B$210,$B33,'Review'!$C$7:$C$210,G$10)) | H33: =IF(IF($E$5="Local prices",COUNTIFS('Offers'!$B$7:$B$608,$B33,'Offers'!$C$7:$C$608,H$10,'Offers'!$AH$7:$AH$608,"yes"),COUNTIFS('Offers'!$B$7:$B$608,$B33,'Offers'!$C$7:$C$608,H$10,'Offers'!$AI$7:$AI$608,"yes"))=0,"—",SUMIFS('Review'!$O$7:$O$210,'Review'!$B$7:$B$210,$B33,'Review'!$C$7:$C$210,H$10)) | J33: All mapped includes near matches and incomplete specifications. Check their notes before deciding.
B34: GN 1/9 PP container, 100 mm | C34: =IF(IF($E$5="Local prices",COUNTIFS('Offers'!$B$7:$B$608,$B34,'Offers'!$C$7:$C$608,C$10,'Offers'!$AH$7:$AH$608,"yes"),COUNTIFS('Offers'!$B$7:$B$608,$B34,'Offers'!$C$7:$C$608,C$10,'Offers'!$AI$7:$AI$608,"yes"))=0,"—",SUMIFS('Review'!$O$7:$O$210,'Review'!$B$7:$B$210,$B34,'Review'!$C$7:$C$210,C$10)) | D34: =IF(IF($E$5="Local prices",COUNTIFS('Offers'!$B$7:$B$608,$B34,'Offers'!$C$7:$C$608,D$10,'Offers'!$AH$7:$AH$608,"yes"),COUNTIFS('Offers'!$B$7:$B$608,$B34,'Offers'!$C$7:$C$608,D$10,'Offers'!$AI$7:$AI$608,"yes"))=0,"—",SUMIFS('Review'!$O$7:$O$210,'Review'!$B$7:$B$210,$B34,'Review'!$C$7:$C$210,D$10)) | E34: =IF(IF($E$5="Local prices",COUNTIFS('Offers'!$B$7:$B$608,$B34,'Offers'!$C$7:$C$608,E$10,'Offers'!$AH$7:$AH$608,"yes"),COUNTIFS('Offers'!$B$7:$B$608,$B34,'Offers'!$C$7:$C$608,E$10,'Offers'!$AI$7:$AI$608,"yes"))=0,"—",SUMIFS('Review'!$O$7:$O$210,'Review'!$B$7:$B$210,$B34,'Review'!$C$7:$C$210,E$10)) | F34: =IF(IF($E$5="Local prices",COUNTIFS('Offers'!$B$7:$B$608,$B34,'Offers'!$C$7:$C$608,F$10,'Offers'!$AH$7:$AH$608,"yes"),COUNTIFS('Offers'!$B$7:$B$608,$B34,'Offers'!$C$7:$C$608,F$10,'Offers'!$AI$7:$AI$608,"yes"))=0,"—",SUMIFS('Review'!$O$7:$O$210,'Review'!$B$7:$B$210,$B34,'Review'!$C$7:$C$210,F$10)) | G34: =IF(IF($E$5="Local prices",COUNTIFS('Offers'!$B$7:$B$608,$B34,'Offers'!$C$7:$C$608,G$10,'Offers'!$AH$7:$AH$608,"yes"),COUNTIFS('Offers'!$B$7:$B$608,$B34,'Offers'!$C$7:$C$608,G$10,'Offers'!$AI$7:$AI$608,"yes"))=0,"—",SUMIFS('Review'!$O$7:$O$210,'Review'!$B$7:$B$210,$B34,'Review'!$C$7:$C$210,G$10)) | H34: =IF(IF($E$5="Local prices",COUNTIFS('Offers'!$B$7:$B$608,$B34,'Offers'!$C$7:$C$608,H$10,'Offers'!$AH$7:$AH$608,"yes"),COUNTIFS('Offers'!$B$7:$B$608,$B34,'Offers'!$C$7:$C$608,H$10,'Offers'!$AI$7:$AI$608,"yes"))=0,"—",SUMIFS('Review'!$O$7:$O$210,'Review'!$B$7:$B$210,$B34,'Review'!$C$7:$C$210,H$10))
B35: Squeeze bottle 250 ml, PP, single tip | C35: =IF(IF($E$5="Local prices",COUNTIFS('Offers'!$B$7:$B$608,$B35,'Offers'!$C$7:$C$608,C$10,'Offers'!$AH$7:$AH$608,"yes"),COUNTIFS('Offers'!$B$7:$B$608,$B35,'Offers'!$C$7:$C$608,C$10,'Offers'!$AI$7:$AI$608,"yes"))=0,"—",SUMIFS('Review'!$O$7:$O$210,'Review'!$B$7:$B$210,$B35,'Review'!$C$7:$C$210,C$10)) | D35: =IF(IF($E$5="Local prices",COUNTIFS('Offers'!$B$7:$B$608,$B35,'Offers'!$C$7:$C$608,D$10,'Offers'!$AH$7:$AH$608,"yes"),COUNTIFS('Offers'!$B$7:$B$608,$B35,'Offers'!$C$7:$C$608,D$10,'Offers'!$AI$7:$AI$608,"yes"))=0,"—",SUMIFS('Review'!$O$7:$O$210,'Review'!$B$7:$B$210,$B35,'Review'!$C$7:$C$210,D$10)) | E35: =IF(IF($E$5="Local prices",COUNTIFS('Offers'!$B$7:$B$608,$B35,'Offers'!$C$7:$C$608,E$10,'Offers'!$AH$7:$AH$608,"yes"),COUNTIFS('Offers'!$B$7:$B$608,$B35,'Offers'!$C$7:$C$608,E$10,'Offers'!$AI$7:$AI$608,"yes"))=0,"—",SUMIFS('Review'!$O$7:$O$210,'Review'!$B$7:$B$210,$B35,'Review'!$C$7:$C$210,E$10)) | F35: =IF(IF($E$5="Local prices",COUNTIFS('Offers'!$B$7:$B$608,$B35,'Offers'!$C$7:$C$608,F$10,'Offers'!$AH$7:$AH$608,"yes"),COUNTIFS('Offers'!$B$7:$B$608,$B35,'Offers'!$C$7:$C$608,F$10,'Offers'!$AI$7:$AI$608,"yes"))=0,"—",SUMIFS('Review'!$O$7:$O$210,'Review'!$B$7:$B$210,$B35,'Review'!$C$7:$C$210,F$10)) | G35: =IF(IF($E$5="Local prices",COUNTIFS('Offers'!$B$7:$B$608,$B35,'Offers'!$C$7:$C$608,G$10,'Offers'!$AH$7:$AH$608,"yes"),COUNTIFS('Offers'!$B$7:$B$608,$B35,'Offers'!$C$7:$C$608,G$10,'Offers'!$AI$7:$AI$608,"yes"))=0,"—",SUMIFS('Review'!$O$7:$O$210,'Review'!$B$7:$B$210,$B35,'Review'!$C$7:$C$210,G$10)) | H35: =IF(IF($E$5="Local prices",COUNTIFS('Offers'!$B$7:$B$608,$B35,'Offers'!$C$7:$C$608,H$10,'Offers'!$AH$7:$AH$608,"yes"),COUNTIFS('Offers'!$B$7:$B$608,$B35,'Offers'!$C$7:$C$608,H$10,'Offers'!$AI$7:$AI$608,"yes"))=0,"—",SUMIFS('Review'!$O$7:$O$210,'Review'!$B$7:$B$210,$B35,'Review'!$C$7:$C$210,H$10))
B36: Squeeze bottle 750 ml, PP, single tip | C36: =IF(IF($E$5="Local prices",COUNTIFS('Offers'!$B$7:$B$608,$B36,'Offers'!$C$7:$C$608,C$10,'Offers'!$AH$7:$AH$608,"yes"),COUNTIFS('Offers'!$B$7:$B$608,$B36,'Offers'!$C$7:$C$608,C$10,'Offers'!$AI$7:$AI$608,"yes"))=0,"—",SUMIFS('Review'!$O$7:$O$210,'Review'!$B$7:$B$210,$B36,'Review'!$C$7:$C$210,C$10)) | D36: =IF(IF($E$5="Local prices",COUNTIFS('Offers'!$B$7:$B$608,$B36,'Offers'!$C$7:$C$608,D$10,'Offers'!$AH$7:$AH$608,"yes"),COUNTIFS('Offers'!$B$7:$B$608,$B36,'Offers'!$C$7:$C$608,D$10,'Offers'!$AI$7:$AI$608,"yes"))=0,"—",SUMIFS('Review'!$O$7:$O$210,'Review'!$B$7:$B$210,$B36,'Review'!$C$7:$C$210,D$10)) | E36: =IF(IF($E$5="Local prices",COUNTIFS('Offers'!$B$7:$B$608,$B36,'Offers'!$C$7:$C$608,E$10,'Offers'!$AH$7:$AH$608,"yes"),COUNTIFS('Offers'!$B$7:$B$608,$B36,'Offers'!$C$7:$C$608,E$10,'Offers'!$AI$7:$AI$608,"yes"))=0,"—",SUMIFS('Review'!$O$7:$O$210,'Review'!$B$7:$B$210,$B36,'Review'!$C$7:$C$210,E$10)) | F36: =IF(IF($E$5="Local prices",COUNTIFS('Offers'!$B$7:$B$608,$B36,'Offers'!$C$7:$C$608,F$10,'Offers'!$AH$7:$AH$608,"yes"),COUNTIFS('Offers'!$B$7:$B$608,$B36,'Offers'!$C$7:$C$608,F$10,'Offers'!$AI$7:$AI$608,"yes"))=0,"—",SUMIFS('Review'!$O$7:$O$210,'Review'!$B$7:$B$210,$B36,'Review'!$C$7:$C$210,F$10)) | G36: =IF(IF($E$5="Local prices",COUNTIFS('Offers'!$B$7:$B$608,$B36,'Offers'!$C$7:$C$608,G$10,'Offers'!$AH$7:$AH$608,"yes"),COUNTIFS('Offers'!$B$7:$B$608,$B36,'Offers'!$C$7:$C$608,G$10,'Offers'!$AI$7:$AI$608,"yes"))=0,"—",SUMIFS('Review'!$O$7:$O$210,'Review'!$B$7:$B$210,$B36,'Review'!$C$7:$C$210,G$10)) | H36: =IF(IF($E$5="Local prices",COUNTIFS('Offers'!$B$7:$B$608,$B36,'Offers'!$C$7:$C$608,H$10,'Offers'!$AH$7:$AH$608,"yes"),COUNTIFS('Offers'!$B$7:$B$608,$B36,'Offers'!$C$7:$C$608,H$10,'Offers'!$AI$7:$AI$608,"yes"))=0,"—",SUMIFS('Review'!$O$7:$O$210,'Review'!$B$7:$B$210,$B36,'Review'!$C$7:$C$210,H$10)) | J36: Additional variants
B37: Red PE cutting board 400 × 300 × 20 mm | C37: =IF(IF($E$5="Local prices",COUNTIFS('Offers'!$B$7:$B$608,$B37,'Offers'!$C$7:$C$608,C$10,'Offers'!$AH$7:$AH$608,"yes"),COUNTIFS('Offers'!$B$7:$B$608,$B37,'Offers'!$C$7:$C$608,C$10,'Offers'!$AI$7:$AI$608,"yes"))=0,"—",SUMIFS('Review'!$O$7:$O$210,'Review'!$B$7:$B$210,$B37,'Review'!$C$7:$C$210,C$10)) | D37: =IF(IF($E$5="Local prices",COUNTIFS('Offers'!$B$7:$B$608,$B37,'Offers'!$C$7:$C$608,D$10,'Offers'!$AH$7:$AH$608,"yes"),COUNTIFS('Offers'!$B$7:$B$608,$B37,'Offers'!$C$7:$C$608,D$10,'Offers'!$AI$7:$AI$608,"yes"))=0,"—",SUMIFS('Review'!$O$7:$O$210,'Review'!$B$7:$B$210,$B37,'Review'!$C$7:$C$210,D$10)) | E37: =IF(IF($E$5="Local prices",COUNTIFS('Offers'!$B$7:$B$608,$B37,'Offers'!$C$7:$C$608,E$10,'Offers'!$AH$7:$AH$608,"yes"),COUNTIFS('Offers'!$B$7:$B$608,$B37,'Offers'!$C$7:$C$608,E$10,'Offers'!$AI$7:$AI$608,"yes"))=0,"—",SUMIFS('Review'!$O$7:$O$210,'Review'!$B$7:$B$210,$B37,'Review'!$C$7:$C$210,E$10)) | F37: =IF(IF($E$5="Local prices",COUNTIFS('Offers'!$B$7:$B$608,$B37,'Offers'!$C$7:$C$608,F$10,'Offers'!$AH$7:$AH$608,"yes"),COUNTIFS('Offers'!$B$7:$B$608,$B37,'Offers'!$C$7:$C$608,F$10,'Offers'!$AI$7:$AI$608,"yes"))=0,"—",SUMIFS('Review'!$O$7:$O$210,'Review'!$B$7:$B$210,$B37,'Review'!$C$7:$C$210,F$10)) | G37: =IF(IF($E$5="Local prices",COUNTIFS('Offers'!$B$7:$B$608,$B37,'Offers'!$C$7:$C$608,G$10,'Offers'!$AH$7:$AH$608,"yes"),COUNTIFS('Offers'!$B$7:$B$608,$B37,'Offers'!$C$7:$C$608,G$10,'Offers'!$AI$7:$AI$608,"yes"))=0,"—",SUMIFS('Review'!$O$7:$O$210,'Review'!$B$7:$B$210,$B37,'Review'!$C$7:$C$210,G$10)) | H37: =IF(IF($E$5="Local prices",COUNTIFS('Offers'!$B$7:$B$608,$B37,'Offers'!$C$7:$C$608,H$10,'Offers'!$AH$7:$AH$608,"yes"),COUNTIFS('Offers'!$B$7:$B$608,$B37,'Offers'!$C$7:$C$608,H$10,'Offers'!$AI$7:$AI$608,"yes"))=0,"—",SUMIFS('Review'!$O$7:$O$210,'Review'!$B$7:$B$210,$B37,'Review'!$C$7:$C$210,H$10)) | J37: New variants have research for Austria and Czechia. A dash in the other markets means no offer has been imported.
B38: PP dough box 600 × 400 × 75 mm, no lid | C38: =IF(IF($E$5="Local prices",COUNTIFS('Offers'!$B$7:$B$608,$B38,'Offers'!$C$7:$C$608,C$10,'Offers'!$AH$7:$AH$608,"yes"),COUNTIFS('Offers'!$B$7:$B$608,$B38,'Offers'!$C$7:$C$608,C$10,'Offers'!$AI$7:$AI$608,"yes"))=0,"—",SUMIFS('Review'!$O$7:$O$210,'Review'!$B$7:$B$210,$B38,'Review'!$C$7:$C$210,C$10)) | D38: =IF(IF($E$5="Local prices",COUNTIFS('Offers'!$B$7:$B$608,$B38,'Offers'!$C$7:$C$608,D$10,'Offers'!$AH$7:$AH$608,"yes"),COUNTIFS('Offers'!$B$7:$B$608,$B38,'Offers'!$C$7:$C$608,D$10,'Offers'!$AI$7:$AI$608,"yes"))=0,"—",SUMIFS('Review'!$O$7:$O$210,'Review'!$B$7:$B$210,$B38,'Review'!$C$7:$C$210,D$10)) | E38: =IF(IF($E$5="Local prices",COUNTIFS('Offers'!$B$7:$B$608,$B38,'Offers'!$C$7:$C$608,E$10,'Offers'!$AH$7:$AH$608,"yes"),COUNTIFS('Offers'!$B$7:$B$608,$B38,'Offers'!$C$7:$C$608,E$10,'Offers'!$AI$7:$AI$608,"yes"))=0,"—",SUMIFS('Review'!$O$7:$O$210,'Review'!$B$7:$B$210,$B38,'Review'!$C$7:$C$210,E$10)) | F38: =IF(IF($E$5="Local prices",COUNTIFS('Offers'!$B$7:$B$608,$B38,'Offers'!$C$7:$C$608,F$10,'Offers'!$AH$7:$AH$608,"yes"),COUNTIFS('Offers'!$B$7:$B$608,$B38,'Offers'!$C$7:$C$608,F$10,'Offers'!$AI$7:$AI$608,"yes"))=0,"—",SUMIFS('Review'!$O$7:$O$210,'Review'!$B$7:$B$210,$B38,'Review'!$C$7:$C$210,F$10)) | G38: =IF(IF($E$5="Local prices",COUNTIFS('Offers'!$B$7:$B$608,$B38,'Offers'!$C$7:$C$608,G$10,'Offers'!$AH$7:$AH$608,"yes"),COUNTIFS('Offers'!$B$7:$B$608,$B38,'Offers'!$C$7:$C$608,G$10,'Offers'!$AI$7:$AI$608,"yes"))=0,"—",SUMIFS('Review'!$O$7:$O$210,'Review'!$B$7:$B$210,$B38,'Review'!$C$7:$C$210,G$10)) | H38: =IF(IF($E$5="Local prices",COUNTIFS('Offers'!$B$7:$B$608,$B38,'Offers'!$C$7:$C$608,H$10,'Offers'!$AH$7:$AH$608,"yes"),COUNTIFS('Offers'!$B$7:$B$608,$B38,'Offers'!$C$7:$C$608,H$10,'Offers'!$AI$7:$AI$608,"yes"))=0,"—",SUMIFS('Review'!$O$7:$O$210,'Review'!$B$7:$B$210,$B38,'Review'!$C$7:$C$210,H$10))
B39: GN 1/1 PC container, 100 mm | C39: =IF(IF($E$5="Local prices",COUNTIFS('Offers'!$B$7:$B$608,$B39,'Offers'!$C$7:$C$608,C$10,'Offers'!$AH$7:$AH$608,"yes"),COUNTIFS('Offers'!$B$7:$B$608,$B39,'Offers'!$C$7:$C$608,C$10,'Offers'!$AI$7:$AI$608,"yes"))=0,"—",SUMIFS('Review'!$O$7:$O$210,'Review'!$B$7:$B$210,$B39,'Review'!$C$7:$C$210,C$10)) | D39: =IF(IF($E$5="Local prices",COUNTIFS('Offers'!$B$7:$B$608,$B39,'Offers'!$C$7:$C$608,D$10,'Offers'!$AH$7:$AH$608,"yes"),COUNTIFS('Offers'!$B$7:$B$608,$B39,'Offers'!$C$7:$C$608,D$10,'Offers'!$AI$7:$AI$608,"yes"))=0,"—",SUMIFS('Review'!$O$7:$O$210,'Review'!$B$7:$B$210,$B39,'Review'!$C$7:$C$210,D$10)) | E39: =IF(IF($E$5="Local prices",COUNTIFS('Offers'!$B$7:$B$608,$B39,'Offers'!$C$7:$C$608,E$10,'Offers'!$AH$7:$AH$608,"yes"),COUNTIFS('Offers'!$B$7:$B$608,$B39,'Offers'!$C$7:$C$608,E$10,'Offers'!$AI$7:$AI$608,"yes"))=0,"—",SUMIFS('Review'!$O$7:$O$210,'Review'!$B$7:$B$210,$B39,'Review'!$C$7:$C$210,E$10)) | F39: =IF(IF($E$5="Local prices",COUNTIFS('Offers'!$B$7:$B$608,$B39,'Offers'!$C$7:$C$608,F$10,'Offers'!$AH$7:$AH$608,"yes"),COUNTIFS('Offers'!$B$7:$B$608,$B39,'Offers'!$C$7:$C$608,F$10,'Offers'!$AI$7:$AI$608,"yes"))=0,"—",SUMIFS('Review'!$O$7:$O$210,'Review'!$B$7:$B$210,$B39,'Review'!$C$7:$C$210,F$10)) | G39: =IF(IF($E$5="Local prices",COUNTIFS('Offers'!$B$7:$B$608,$B39,'Offers'!$C$7:$C$608,G$10,'Offers'!$AH$7:$AH$608,"yes"),COUNTIFS('Offers'!$B$7:$B$608,$B39,'Offers'!$C$7:$C$608,G$10,'Offers'!$AI$7:$AI$608,"yes"))=0,"—",SUMIFS('Review'!$O$7:$O$210,'Review'!$B$7:$B$210,$B39,'Review'!$C$7:$C$210,G$10)) | H39: =IF(IF($E$5="Local prices",COUNTIFS('Offers'!$B$7:$B$608,$B39,'Offers'!$C$7:$C$608,H$10,'Offers'!$AH$7:$AH$608,"yes"),COUNTIFS('Offers'!$B$7:$B$608,$B39,'Offers'!$C$7:$C$608,H$10,'Offers'!$AI$7:$AI$608,"yes"))=0,"—",SUMIFS('Review'!$O$7:$O$210,'Review'!$B$7:$B$210,$B39,'Review'!$C$7:$C$210,H$10))
B40: GN 1/6 PC container, 100 mm | C40: =IF(IF($E$5="Local prices",COUNTIFS('Offers'!$B$7:$B$608,$B40,'Offers'!$C$7:$C$608,C$10,'Offers'!$AH$7:$AH$608,"yes"),COUNTIFS('Offers'!$B$7:$B$608,$B40,'Offers'!$C$7:$C$608,C$10,'Offers'!$AI$7:$AI$608,"yes"))=0,"—",SUMIFS('Review'!$O$7:$O$210,'Review'!$B$7:$B$210,$B40,'Review'!$C$7:$C$210,C$10)) | D40: =IF(IF($E$5="Local prices",COUNTIFS('Offers'!$B$7:$B$608,$B40,'Offers'!$C$7:$C$608,D$10,'Offers'!$AH$7:$AH$608,"yes"),COUNTIFS('Offers'!$B$7:$B$608,$B40,'Offers'!$C$7:$C$608,D$10,'Offers'!$AI$7:$AI$608,"yes"))=0,"—",SUMIFS('Review'!$O$7:$O$210,'Review'!$B$7:$B$210,$B40,'Review'!$C$7:$C$210,D$10)) | E40: =IF(IF($E$5="Local prices",COUNTIFS('Offers'!$B$7:$B$608,$B40,'Offers'!$C$7:$C$608,E$10,'Offers'!$AH$7:$AH$608,"yes"),COUNTIFS('Offers'!$B$7:$B$608,$B40,'Offers'!$C$7:$C$608,E$10,'Offers'!$AI$7:$AI$608,"yes"))=0,"—",SUMIFS('Review'!$O$7:$O$210,'Review'!$B$7:$B$210,$B40,'Review'!$C$7:$C$210,E$10)) | F40: =IF(IF($E$5="Local prices",COUNTIFS('Offers'!$B$7:$B$608,$B40,'Offers'!$C$7:$C$608,F$10,'Offers'!$AH$7:$AH$608,"yes"),COUNTIFS('Offers'!$B$7:$B$608,$B40,'Offers'!$C$7:$C$608,F$10,'Offers'!$AI$7:$AI$608,"yes"))=0,"—",SUMIFS('Review'!$O$7:$O$210,'Review'!$B$7:$B$210,$B40,'Review'!$C$7:$C$210,F$10)) | G40: =IF(IF($E$5="Local prices",COUNTIFS('Offers'!$B$7:$B$608,$B40,'Offers'!$C$7:$C$608,G$10,'Offers'!$AH$7:$AH$608,"yes"),COUNTIFS('Offers'!$B$7:$B$608,$B40,'Offers'!$C$7:$C$608,G$10,'Offers'!$AI$7:$AI$608,"yes"))=0,"—",SUMIFS('Review'!$O$7:$O$210,'Review'!$B$7:$B$210,$B40,'Review'!$C$7:$C$210,G$10)) | H40: =IF(IF($E$5="Local prices",COUNTIFS('Offers'!$B$7:$B$608,$B40,'Offers'!$C$7:$C$608,H$10,'Offers'!$AH$7:$AH$608,"yes"),COUNTIFS('Offers'!$B$7:$B$608,$B40,'Offers'!$C$7:$C$608,H$10,'Offers'!$AI$7:$AI$608,"yes"))=0,"—",SUMIFS('Review'!$O$7:$O$210,'Review'!$B$7:$B$210,$B40,'Review'!$C$7:$C$210,H$10))
